<?xml version="1.0" ?>
<sdf version="1.4">
  <world name="default">
    <scene>
      <ambient>1.0 1.0 1.0 1</ambient>
      <background>0 0 0 1.0</background>
      <shadows>true</shadows>
    </scene>
    <physics type="rtql8">
      <gravity>0 0 -10.0</gravity>
      <ode>
        <solver>
          <type>quick</type>
          <dt>0.001</dt>
          <iters>10</iters>
          <sor>1.3</sor>
        </solver>
        <constraints>
          <cfm>0.0</cfm>
          <erp>0.2</erp>
          <contact_max_correcting_vel>100.0</contact_max_correcting_vel>
          <contact_surface_layer>0.0</contact_surface_layer>
        </constraints>
      </ode>
    </physics>
    <!--include><uri>model://ground_plane</uri></include-->
    <!-- 25.3kg total mass -->
    <model name="double_pendulum_1">
      <pose>0 0 2 0 0 0</pose>
      <link name="link1">
	<pose>0 0 0 0 0 0</pose>
        <inertial>
          <inertia>
            <ixx>1</ixx>
            <ixy>0</ixy>
            <ixz>0</ixz>
            <iyy>1</iyy>
            <iyz>0</iyz>
            <izz>1</izz>
          </inertia>
          <mass>1.0</mass>
        </inertial>
        <visual name="visual">
          <pose>0 0 0 0 0 0</pose>
          <geometry>
            <box>
              <size>0.2 0.4 0.6</size>
            </box>
          </geometry>
          <material>
            <script>Gazebo/WoodPallet</script>
          </material>
        </visual>
	<collision name="1coll_link1">
          <pose>0 0 0 0 0 0</pose>
          <max_contacts>250</max_contacts>
          <geometry>
            <box>
              <size>0.2 0.4 0.6</size>
            </box>
          </geometry>
          <surface>
            <friction>
              <ode>
                <mu>0.5</mu>
                <mu2>0.2</mu2>
                <fdir1>1 0 0</fdir1>
                <slip1>0</slip1>
                <slip2>0</slip2>
              </ode>
            </friction>
            <bounce>
              <restitution_coefficient>0</restitution_coefficient>
              <threshold>1000000</threshold>
            </bounce>
            <contact>
              <ode>
                <soft_cfm>0.0</soft_cfm>
                <soft_erp>0.2</soft_erp>
                <kp>1000000000000000</kp>
                <kd>10000000000000</kd>
                <max_vel>100</max_vel>
                <min_depth>0</min_depth>
              </ode>
            </contact>
          </surface>
          <laser_retro>100</laser_retro>
        </collision>
      </link>
      <link name="link2">
	<pose>0 -1 0 0 0 0</pose>
        <inertial>
          <inertia>
            <ixx>1</ixx>
            <ixy>0</ixy>
            <ixz>0</ixz>
            <iyy>1</iyy>
            <iyz>0</iyz>
            <izz>1</izz>
          </inertia>
          <mass>1.0</mass>
        </inertial>
        <visual name="visual">
          <pose>0 0 0 0 0 0</pose>
          <geometry>
            <box>
              <size>0.2 0.4 0.6</size>
            </box>
          </geometry>
          <material>
            <script>Gazebo/WoodPallet</script>
          </material>
        </visual>
	<collision name="1coll_link2">
          <pose>0 0 0 0 0 0</pose>
          <max_contacts>250</max_contacts>
          <geometry>
            <box>
              <size>0.2 0.4 0.6</size>
            </box>
          </geometry>
          <surface>
            <friction>
              <ode>
                <mu>0.5</mu>
                <mu2>0.2</mu2>
                <fdir1>1 0 0</fdir1>
                <slip1>0</slip1>
                <slip2>0</slip2>
              </ode>
            </friction>
            <bounce>
              <restitution_coefficient>0</restitution_coefficient>
              <threshold>1000000</threshold>
            </bounce>
            <contact>
              <ode>
                <soft_cfm>0.0</soft_cfm>
                <soft_erp>0.2</soft_erp>
                <kp>1000000000000000</kp>
                <kd>10000000000000</kd>
                <max_vel>100</max_vel>
                <min_depth>0</min_depth>
              </ode>
            </contact>
          </surface>
          <laser_retro>100</laser_retro>
        </collision>
      </link>
      <joint name="joint01" type="revolute">
        <pose>0 0.5 0 0 0 0</pose>
        <parent>world</parent>
        <child>link1</child>
        <axis>
          <xyz>1.0 0.0 0.0</xyz>
        </axis>
      </joint>
      <joint name="joint12" type="revolute">
        <pose>0 0.5 0 0 0 0</pose>
        <parent>link1</parent>
        <child>link2</child>
        <axis>
          <xyz>1.0 0.0 0.0</xyz>
        </axis>
      </joint>
    </model>
    <model name="double_pendulum_2">
      <pose>0 4.9 2 0 0 0</pose>
      <link name="link1">
	<pose>0 0 0 0 0 0</pose>
        <inertial>
          <inertia>
            <ixx>1</ixx>
            <ixy>0</ixy>
            <ixz>0</ixz>
            <iyy>1</iyy>
            <iyz>0</iyz>
            <izz>1</izz>
          </inertia>
          <mass>1.0</mass>
        </inertial>
        <visual name="visual">
          <pose>0 0 0 0 0 0</pose>
          <geometry>
            <box>
              <size>0.2 0.4 0.6</size>
            </box>
          </geometry>
          <material>
            <script>Gazebo/WoodPallet</script>
          </material>
        </visual>
	<collision name="1coll_link2">
          <pose>0 0 0 0 0 0</pose>
          <max_contacts>250</max_contacts>
          <geometry>
            <box>
              <size>0.2 0.4 0.6</size>
            </box>
          </geometry>
          <surface>
            <friction>
              <ode>
                <mu>0.5</mu>
                <mu2>0.2</mu2>
                <fdir1>1 0 0</fdir1>
                <slip1>0</slip1>
                <slip2>0</slip2>
              </ode>
            </friction>
            <bounce>
              <restitution_coefficient>0</restitution_coefficient>
              <threshold>1000000</threshold>
            </bounce>
            <contact>
              <ode>
                <soft_cfm>0.0</soft_cfm>
                <soft_erp>0.2</soft_erp>
                <kp>1000000000000000</kp>
                <kd>10000000000000</kd>
                <max_vel>100</max_vel>
                <min_depth>0</min_depth>
              </ode>
            </contact>
          </surface>
          <laser_retro>100</laser_retro>
        </collision>
      </link>
      <link name="link2">
	<pose>0 1 0 0 0 0</pose>
        <inertial>
          <inertia>
            <ixx>1</ixx>
            <ixy>0</ixy>
            <ixz>0</ixz>
            <iyy>1</iyy>
            <iyz>0</iyz>
            <izz>1</izz>
          </inertia>
          <mass>1.0</mass>
        </inertial>
        <visual name="visual">
          <pose>0 0 0 0 0 0</pose>
          <geometry>
            <box>
              <size>0.2 0.4 0.6</size>
            </box>
          </geometry>
          <material>
            <script>Gazebo/WoodPallet</script>
          </material>
        </visual>
	<collision name="1coll_link2">
          <pose>0 0 0 0 0 0</pose>
          <max_contacts>250</max_contacts>
          <geometry>
            <box>
              <size>0.2 0.4 0.6</size>
            </box>
          </geometry>
          <surface>
            <friction>
              <ode>
                <mu>0.5</mu>
                <mu2>0.2</mu2>
                <fdir1>1 0 0</fdir1>
                <slip1>0</slip1>
                <slip2>0</slip2>
              </ode>
            </friction>
            <bounce>
              <restitution_coefficient>0</restitution_coefficient>
              <threshold>1000000</threshold>
            </bounce>
            <contact>
              <ode>
                <soft_cfm>0.0</soft_cfm>
                <soft_erp>0.2</soft_erp>
                <kp>1000000000000000</kp>
                <kd>10000000000000</kd>
                <max_vel>100</max_vel>
                <min_depth>0</min_depth>
              </ode>
            </contact>
          </surface>
          <laser_retro>100</laser_retro>
        </collision>
      </link>
      <joint name="joint01" type="revolute">
        <pose>0 -0.5 0 0 0 0</pose>
        <parent>world</parent>
        <child>link1</child>
        <axis>
          <xyz>1.0 0.0 0.0</xyz>
        </axis>
      </joint>
      <joint name="joint12" type="revolute">
        <pose>0 -0.5 0 0 0 0</pose>
        <parent>link1</parent>
        <child>link2</child>
        <axis>
          <xyz>1.0 0.0 0.0</xyz>
        </axis>
      </joint>
    </model>
    <light type="directional" name="sun">
      <pose>0 0 10 0 0 0</pose>
      <diffuse>.8 .8 .8 1</diffuse>
      <specular>.1 .1 .1 1</specular>
      <attenuation>
        <range>10</range>
        <linear>0.01</linear>
        <constant>0.8</constant>
        <quadratic>0.0</quadratic>
      </attenuation>
      <direction>0 .5 -.5</direction>
      <cast_shadows>true</cast_shadows>
    </light>
  </world>
</sdf>
