<?xml version="1.0" ?>
<sdf version="1.4">
    <world name="default">
        <include>
            <uri>model://sun</uri>
        </include>
        <include>
            <uri>model://ground_plane</uri>
        </include>
        <physics type="ode">
            <gravity>0 0 -10.0</gravity>
        </physics>
        <!--include><uri>model://ground_plane</uri></include-->
        <!-- 25.3kg total mass -->
        <model name="double_pendulum_with_base">
            <link name="base">
                <pose>0 0 0.5 0 0 0</pose>
                <inertial>
                    <mass>100</mass>
                </inertial>
                <visual name="vis_plate_on_ground">
                    <pose>0 0 0.01 0 0 0</pose>
                    <geometry>
                        <cylinder>
                            <radius>0.8</radius>
                            <length>0.02</length>
                        </cylinder>
                    </geometry>
                    <material>
                        <script>
                            <uri>file://media/materials/scripts/gazebo.material</uri>
                            <name>Gazebo/Grey</name>
                        </script>
                    </material>
                </visual>
                <collision name="col_plate_on_ground">
                    <pose>0 0 0.01 0 0 0</pose>
                    <geometry>
                        <cylinder>
                            <radius>0.8</radius>
                            <length>0.02</length>
                        </cylinder>
                    </geometry>
                </collision>
            </link>
            <!-- upper link, length 1, IC -90 degrees -->
            <link name="upper_link">
                <pose>0 0 2.1 -1.5708 0 0</pose>
                <self_collide>0</self_collide>
                <inertial>
                    <pose>0 0 0.5 0 0 0</pose>
                </inertial>
                <visual name="vis_cylinder">
                    <pose>0 0 0.5 0 0 0</pose>
                    <geometry>
                        <cylinder>
                            <radius>0.1</radius>
                            <length>0.9</length>
                        </cylinder>
                    </geometry>
                    <material>
                        <script>
                            <uri>file://media/materials/scripts/gazebo.material</uri>
                            <name>Gazebo/Grey</name>
                        </script>
                    </material>
                </visual>
                <collision name="col_cylinder">
                    <pose>0 0 0.5 0 0 0</pose>
                    <geometry>
                        <cylinder>
                            <radius>0.1</radius>
                            <length>0.9</length>
                        </cylinder>
                    </geometry>
                </collision>
            </link>
            <!-- lower link, length 1, IC ~-120 degrees more -->
            <link name="lower_link">
                <pose>0.25 1.0 2.1 -2 0 0</pose>
                <self_collide>0</self_collide>
                <inertial>
                    <pose>0 0 0.5 0 0 0</pose>
                </inertial>
                <visual name="vis_cylinder">
                    <pose>0 0 0.5 0 0 0</pose>
                    <geometry>
                        <cylinder>
                            <radius>0.1</radius>
                            <length>0.9</length>
                        </cylinder>
                    </geometry>
                    <material>
                        <script>
                            <uri>file://media/materials/scripts/gazebo.material</uri>
                            <name>Gazebo/Grey</name>
                        </script>
                    </material>
                </visual>
                <collision name="col_cylinder">
                    <pose>0 0 0.5 0 0 0</pose>
                    <geometry>
                        <cylinder>
                            <radius>0.1</radius>
                            <length>0.9</length>
                        </cylinder>
                    </geometry>
                </collision>
            </link>
            <joint name="joint01" type="revolute">
                <pose>0 0 0 0 0 0</pose>
                <axis>
                    <xyz>0 0 1</xyz>
                </axis>
                <parent>
                    <link_name>world</link_name>
                </parent>
                <child>
                    <link_name>base</link_name>
                </child>
            </joint>
            <!-- pin joint for upper link, at origin of upper link -->
            <joint name="upper_joint" type="revolute">
                <axis>
                    <xyz>1.0 0 0</xyz>
                </axis>
                <parent>
                    <link_name>base</link_name>
                </parent>
                <child>
                    <link_name>upper_link</link_name>
                </child>
            </joint>
            <!-- pin joint for lower link, at origin of child link -->
            <joint name="lower_joint" type="revolute">
                <axis>
                    <xyz>1.0 0 0</xyz>
                </axis>
                <parent>
                    <link_name>upper_link</link_name>
                </parent>
                <child>
                    <link_name>lower_link</link_name>
                </child>
            </joint>
        </model>
    </world>
</sdf>
