<?xml version="1.0" ?>
<sdf version="1.4">
  <world name="default">
    <include><uri>model://sun</uri></include>
    <physics type="ode">
      <gravity>0 0 -10.0</gravity>
      <ode>
        <solver>
          <type>quick</type>
          <dt>0.001</dt>
          <iters>10</iters>
          <sor>1.3</sor>
        </solver>
        <constraints>
          <cfm>0.0</cfm>
          <erp>0.2</erp>
          <contact_max_correcting_vel>100.0</contact_max_correcting_vel>
          <contact_surface_layer>0.0</contact_surface_layer>
        </constraints>
      </ode>
    </physics>
    <!--include><uri>model://ground_plane</uri></include-->
    <!-- 25.3kg total mass -->
    <model name="pendulum1">
      <pose>0 0 2 0 0 0</pose>
      <link name="link1">
        <pose>0 0 0 0 0 0</pose>
        <inertial>
          <inertia>
            <ixx>1</ixx>
            <ixy>0</ixy>
            <ixz>0</ixz>
            <iyy>1</iyy>
            <iyz>0</iyz>
            <izz>1</izz>
          </inertia>
          <mass>1.0</mass>
        </inertial>
        <visual name="visual1">
          <pose>0 0 0 0 0 0</pose>
          <geometry>
            <box>
              <size>0.2 0.4 0.6</size>
            </box>
          </geometry>
          <material>
            <script>Gazebo/WoodPallet</script>
          </material>
        </visual>
      </link>
      <joint name="joint01" type="revolute">
        <pose>0 -0.5 0 0 0 0</pose>
        <parent>world</parent>
        <child>link1</child>
        <axis>
          <xyz>1 0 0</xyz>
        </axis>
      </joint>
    </model>
    
    <model name="pendulum2">
      <pose>2 0 2 0 0 0</pose>
      <link name="link1">
        <pose>0 0 0 0 0 0</pose>
        <inertial>
          <inertia>
            <ixx>1</ixx>
            <ixy>0</ixy>
            <ixz>0</ixz>
            <iyy>1</iyy>
            <iyz>0</iyz>
            <izz>1</izz>
          </inertia>
          <mass>1.0</mass>
        </inertial>
        <visual name="visual1">
          <pose>0 0 0 0 0 0</pose>
          <geometry>
            <box>
              <size>0.2 0.4 0.6</size>
            </box>
          </geometry>
          <material>
            <script>Gazebo/WoodPallet</script>
          </material>
        </visual>
      </link>
      <joint name="joint01" type="revolute">
        <pose>0 -0.5 0 0 0 0</pose>
        <parent>world</parent>
        <child>link1</child>
        <axis>
          <xyz>1 0 0</xyz>
        </axis>
      </joint>
    </model>
    
    <model name="pendulum3">
      <pose>4 0 2 0 0 0</pose>
      <link name="link1">
        <pose>0 0 0 0 0 0</pose>
        <inertial>
          <inertia>
            <ixx>1</ixx>
            <ixy>0</ixy>
            <ixz>0</ixz>
            <iyy>1</iyy>
            <iyz>0</iyz>
            <izz>1</izz>
          </inertia>
          <mass>1.0</mass>
        </inertial>
        <visual name="visual1">
          <pose>0 0 0 0 0 0</pose>
          <geometry>
            <box>
              <size>0.2 0.4 0.6</size>
            </box>
          </geometry>
          <material>
            <script>Gazebo/WoodPallet</script>
          </material>
        </visual>
      </link>
      <joint name="joint01" type="revolute">
        <pose>0 -0.5 0 0 0 0</pose>
        <parent>world</parent>
        <child>link1</child>
        <axis>
          <xyz>1 0 0</xyz>
        </axis>
      </joint>
    </model>
    
    <model name="pendulum4">
      <pose>6 0 2 0 0 0</pose>
      <link name="link1">
        <pose>0 0 0 0 0 0</pose>
        <inertial>
          <inertia>
            <ixx>1</ixx>
            <ixy>0</ixy>
            <ixz>0</ixz>
            <iyy>1</iyy>
            <iyz>0</iyz>
            <izz>1</izz>
          </inertia>
          <mass>1.0</mass>
        </inertial>
        <visual name="visual1">
          <pose>0 0 0 0 0 0</pose>
          <geometry>
            <box>
              <size>0.2 0.4 0.6</size>
            </box>
          </geometry>
          <material>
            <script>Gazebo/WoodPallet</script>
          </material>
        </visual>
      </link>
      <joint name="joint01" type="revolute">
        <pose>0 -0.5 0 0 0 0</pose>
        <parent>world</parent>
        <child>link1</child>
        <axis>
          <xyz>1 0 0</xyz>
        </axis>
      </joint>
    </model>
    
    <model name="pendulum5">
      <pose>8 0 2 0 0 0</pose>
      <link name="link1">
        <pose>0 0 0 0 0 0</pose>
        <inertial>
          <inertia>
            <ixx>1</ixx>
            <ixy>0</ixy>
            <ixz>0</ixz>
            <iyy>1</iyy>
            <iyz>0</iyz>
            <izz>1</izz>
          </inertia>
          <mass>1.0</mass>
        </inertial>
        <visual name="visual1">
          <pose>0 0 0 0 0 0</pose>
          <geometry>
            <box>
              <size>0.2 0.4 0.6</size>
            </box>
          </geometry>
          <material>
            <script>Gazebo/WoodPallet</script>
          </material>
        </visual>
      </link>
      <joint name="joint01" type="revolute">
        <pose>0 -0.5 0 0 0 0</pose>
        <parent>world</parent>
        <child>link1</child>
        <axis>
          <xyz>1 0 0</xyz>
        </axis>
      </joint>
    </model>
    
    <model name="pendulum6">
      <pose>10 0 2 0 0 0</pose>
      <link name="link1">
        <pose>0 0 0 0 0 0</pose>
        <inertial>
          <inertia>
            <ixx>1</ixx>
            <ixy>0</ixy>
            <ixz>0</ixz>
            <iyy>1</iyy>
            <iyz>0</iyz>
            <izz>1</izz>
          </inertia>
          <mass>1.0</mass>
        </inertial>
        <visual name="visual1">
          <pose>0 0 0 0 0 0</pose>
          <geometry>
            <box>
              <size>0.2 0.4 0.6</size>
            </box>
          </geometry>
          <material>
            <script>Gazebo/WoodPallet</script>
          </material>
        </visual>
      </link>
      <joint name="joint01" type="revolute">
        <pose>0 -0.5 0 0 0 0</pose>
        <parent>world</parent>
        <child>link1</child>
        <axis>
          <xyz>1 0 0</xyz>
        </axis>
      </joint>
    </model>
    
    <model name="pendulum7">
      <pose>12 0 2 0 0 0</pose>
      <link name="link1">
        <pose>0 0 0 0 0 0</pose>
        <inertial>
          <inertia>
            <ixx>1</ixx>
            <ixy>0</ixy>
            <ixz>0</ixz>
            <iyy>1</iyy>
            <iyz>0</iyz>
            <izz>1</izz>
          </inertia>
          <mass>1.0</mass>
        </inertial>
        <visual name="visual1">
          <pose>0 0 0 0 0 0</pose>
          <geometry>
            <box>
              <size>0.2 0.4 0.6</size>
            </box>
          </geometry>
          <material>
            <script>Gazebo/WoodPallet</script>
          </material>
        </visual>
      </link>
      <joint name="joint01" type="revolute">
        <pose>0 -0.5 0 0 0 0</pose>
        <parent>world</parent>
        <child>link1</child>
        <axis>
          <xyz>1 0 0</xyz>
        </axis>
      </joint>
    </model>
    
    <model name="pendulum8">
      <pose>14 0 2 0 0 0</pose>
      <link name="link1">
        <pose>0 0 0 0 0 0</pose>
        <inertial>
          <inertia>
            <ixx>1</ixx>
            <ixy>0</ixy>
            <ixz>0</ixz>
            <iyy>1</iyy>
            <iyz>0</iyz>
            <izz>1</izz>
          </inertia>
          <mass>1.0</mass>
        </inertial>
        <visual name="visual1">
          <pose>0 0 0 0 0 0</pose>
          <geometry>
            <box>
              <size>0.2 0.4 0.6</size>
            </box>
          </geometry>
          <material>
            <script>Gazebo/WoodPallet</script>
          </material>
        </visual>
      </link>
      <joint name="joint01" type="revolute">
        <pose>0 -0.5 0 0 0 0</pose>
        <parent>world</parent>
        <child>link1</child>
        <axis>
          <xyz>1 0 0</xyz>
        </axis>
      </joint>
    </model>
    
    
  </world>
</sdf>
