<gazebo version='1.2'>
  <model name="pioneer2dx" static="0">
    <link name="chassis">
      <origin>0.0 0.0 0.16 0 0 0</origin>

      <inertial mass="5.0"/>

      <collision name="collision">
        <geometry>
          <box size="0.445 0.277 0.17"/>
        </geometry>
      </collision>
   
      <collision name="castor_collision">
        <origin>-0.200 0 -0.12 0 0 0</origin>
        <geometry>
          <sphere radius="0.04"/>
        </geometry>
        <surface>
          <friction>
            <ode mu="0" mu2="0" slip1="1.0" slip2="1.0"/>
          </friction>
        </surface>
      </collision>

      <visual name="visual">
        <origin>0 0 0.04 0 0 0</origin>
        <geometry>
          <mesh filename="pioneer2dx/chassis.dae"/>
        </geometry>
      </visual>

      <visual name="castor_visual">
        <origin>-0.200 0 -0.12 0 0 0</origin>
        <geometry>
          <sphere radius="0.04"/>
        </geometry>
        <material script="Gazebo/FlatBlack"/>
      </visual>

    </link>

    <link name="right_wheel">
      <origin>0.1 -.17 0.11 0 1.5707 1.5707</origin>

      <inertial mass="0.5">
        <inertia ixx='0.001' ixy='0.0' ixz='0.0'
                 iyy='0.001' iyz='0.0'
                 izz='0.001'/>
      </inertial>
  
      <collision name="collision">
        <geometry>
          <cylinder radius="0.11" length="0.05"/>
        </geometry>
        <surface>
          <friction>
            <ode mu="100000.0" mu2="100000.0" slip1="0.0" slip2="0.0"/>
          </friction>
        </surface>
      </collision>
   
      <visual name="visual">
        <geometry>
          <cylinder radius="0.11" length="0.05"/>
        </geometry>
        <material script="Gazebo/FlatBlack"/>
      </visual>
    </link>

    <link name="left_wheel">
      <origin>0.1 .17 0.11 0 1.5707 1.5707</origin>

       <inertial mass="0.5">
        <inertia ixx='0.001' ixy='0.0' ixz='0.0'
                 iyy='0.001' iyz='0.0'
                 izz='0.001'/>
      </inertial>
 
      <collision name="collision">
        <geometry>
          <cylinder radius="0.11" length="0.05"/>
        </geometry>
        <surface>
          <friction>
            <ode mu="100000.0" mu2="100000.0" slip1="0.0" slip2="0.0"/>
          </friction>
        </surface>
      </collision>

      <visual name="visual">
        <geometry>
          <cylinder radius="0.11" length="0.05"/>
        </geometry>
        <material script="Gazebo/FlatBlack"/>
      </visual>
    </link>

    <joint type="revolute" name="left_wheel_hinge">
      <origin>0 0 -0.03 0 0 0</origin>
      <child link="left_wheel"/>
      <parent link="chassis"/>
      <axis xyz="0 1 0"/>
    </joint>

    <joint type="revolute" name="right_wheel_hinge">
      <origin>0 0 0.03 0 0 0</origin>
      <child link="right_wheel"/>
      <parent link="chassis"/>
      <axis xyz="0 1 0"/>
    </joint>

    <plugin filename="libDiffDrivePlugin.so" name="diff_drive">
      <left_joint>left_wheel_hinge</left_joint>
      <right_joint>right_wheel_hinge</right_joint>
      <torque>5</torque>
    </plugin>
  </model>
</gazebo>
