<?xml version="1.0"?>
<gazebo version="1.2">
  <model name="pioneer2at">
    <static>0</static>

    <link name="chassis">
      <pose>0.0 0.0 0.16 0 0 0</pose>
      <inertial>
        <mass>5.0</mass>
      </inertial>

      <collision name="collision">
        <geometry>
          <box>
            <size>0.445 0.277 0.17</size>
          </box>
        </geometry>
      </collision>

      <visual name="visual">
        <pose>0 0 0.04 0 0 0</pose>
        <geometry>
          <mesh>
            <filename>pioneer2dx/chassis.dae</filename>
          </mesh>
        </geometry>
      </visual>
    </link>

    <link name="front_right_wheel">
      <pose>0.144 -.17 0.11 0 1.5707 1.5707</pose>
      <inertial>
        <mass>0.5</mass>
      </inertial>

      <collision name="collision">
        <geometry>
          <cylinder>
            <radius>0.111</radius>
            <length>0.05</length>
          </cylinder>
        </geometry>

        <surface>
          <friction>
            <ode>
              <slip1>0.0</slip1>
              <slip2>0.0</slip2>
            </ode>
          </friction>
        </surface>
      </collision>

      <visual name="visual">
        <geometry>
          <cylinder>
            <radius>0.111</radius>
            <length>0.05</length>
          </cylinder>
        </geometry>
        <material>
          <script>Gazebo/FlatBlack</script>
        </material>
      </visual>
    </link>

    <link name="front_left_wheel">
      <pose>0.144 .17 0.11 0 1.5707 1.5707</pose>

      <inertial>
        <mass>0.5</mass>
      </inertial>

      <collision name="collision">
        <geometry>
          <cylinder><radius>0.111</radius><length>0.05</length></cylinder>
        </geometry>
        <surface>
          <friction>
            <ode><slip1>0.0</slip1><slip2>0.0</slip2></ode>
          </friction>
        </surface>
      </collision>
      <visual name="visual">
        <geometry>
          <cylinder><radius>0.111</radius><length>0.05</length></cylinder>
        </geometry>
        <material><script>Gazebo/FlatBlack</script></material>
      </visual>
    </link>
    <link name="back_right_wheel">
      <pose>-0.144 -.17 0.11 0 1.5707 1.5707</pose>
      <inertial>
        <mass>0.5</mass>
      </inertial>

      <collision name="collision">
        <geometry>
          <cylinder><radius>0.111</radius><length>0.05</length></cylinder>
        </geometry>
        <surface>
          <friction>
            <ode><slip1>0.0</slip1><slip2>0.0</slip2></ode>
          </friction>
        </surface>
      </collision>
      <visual name="visual">
        <geometry>
          <cylinder><radius>0.111</radius><length>0.05</length></cylinder>
        </geometry>
        <material><script>Gazebo/FlatBlack</script></material>
      </visual>
    </link>
    <link name="back_left_wheel">
      <pose>-0.144 .17 0.11 0 1.5707 1.5707</pose>
      <inertial>
        <mass>0.5</mass>
      </inertial>

      <collision name="collision">
        <geometry>
          <cylinder><radius>0.111</radius><length>0.05</length></cylinder>
        </geometry>
        <surface>
          <friction>
            <ode><slip1>0.0</slip1><slip2>0.0</slip2></ode>
          </friction>
        </surface>
      </collision>
      <visual name="visual">
        <geometry>
          <cylinder><radius>0.111</radius><length>0.05</length></cylinder>
        </geometry>
        <material><script>Gazebo/FlatBlack</script></material>
      </visual>
    </link>

    <joint type="revolute" name="front_left_wheel_hinge">
      <pose>0 0 -0.03 0 0 0</pose>
      <child>front_left_wheel</child>
      <parent>chassis</parent>
      <axis><xyz>0 1 0</xyz></axis>
    </joint>
    <joint type="revolute" name="front_right_wheel_hinge">
      <pose>0 0 0.03 0 0 0</pose>
      <child>front_right_wheel</child>
      <parent>chassis</parent>
      <axis><xyz>0 1 0</xyz></axis>
    </joint>
    <joint type="revolute" name="back_left_wheel_hinge">
      <pose>0 0 -0.03 0 0 0</pose>
      <child>back_left_wheel</child>
      <parent>chassis</parent>
      <axis><xyz>0 1 0</xyz></axis>
    </joint>

    <joint type="revolute" name="back_right_wheel_hinge">
      <pose>0 0 0.03 0 0 0</pose>
      <child>back_right_wheel</child>
      <parent>chassis</parent>
      <axis><xyz>0 1 0</xyz></axis>
    </joint>
  </model>
</gazebo>
