<?xml version="1.0" ?>
<gazebo version="1.2">
    <model name="pioneer2at" static="0">
        <link name="chassis">
            <origin>0.0 0.0 0.16 0 0 0</origin>
            <inertial mass="5.0" />
            <collision name="collision">
                <geometry>
                    <box size="0.445 0.277 0.17" />
                </geometry>
            </collision>
            <visual name="visual">
                <origin>0 0 0.04 0 0 0</origin>
                <geometry>
                    <mesh filename="pioneer2dx/chassis.dae" />
                </geometry>
            </visual>
        </link>
        <link name="front_right_wheel">
            <origin>0.144 -.17 0.11 0 1.5707 1.5707</origin>
            <collision name="collision">
                <mass>0.5</mass>
                <geometry>
                    <cylinder radius="0.111" length="0.05" />
                </geometry>
                <surface>
                    <friction>
                        <ode mu="100000.0" mu2="100000.0" slip1="0.0" slip2="0.0" />
                    </friction>
                </surface>
            </collision>
            <visual name="visual">
                <geometry>
                    <cylinder radius="0.111" length="0.05" />
                </geometry>
                <material script="Gazebo/FlatBlack" />
            </visual>
        </link>
        <link name="front_left_wheel">
            <origin>0.144 .17 0.11 0 1.5707 1.5707</origin>
            <collision name="collision">
                <mass>0.5</mass>
                <geometry>
                    <cylinder radius="0.111" length="0.05" />
                </geometry>
                <surface>
                    <friction>
                        <ode mu="100000.0" mu2="100000.0" slip1="0.0" slip2="0.0" />
                    </friction>
                </surface>
            </collision>
            <visual name="visual">
                <geometry>
                    <cylinder radius="0.111" length="0.05" />
                </geometry>
                <material script="Gazebo/FlatBlack" />
            </visual>
        </link>
        <link name="back_right_wheel">
            <origin>-0.144 -.17 0.11 0 1.5707 1.5707</origin>
            <collision name="collision">
                <mass>0.5</mass>
                <geometry>
                    <cylinder radius="0.111" length="0.05" />
                </geometry>
                <surface>
                    <friction>
                        <ode mu="100000.0" mu2="100000.0" slip1="0.0" slip2="0.0" />
                    </friction>
                </surface>
            </collision>
            <visual name="visual">
                <geometry>
                    <cylinder radius="0.111" length="0.05" />
                </geometry>
                <material script="Gazebo/FlatBlack" />
            </visual>
        </link>
        <link name="back_left_wheel">
            <origin>-0.144 .17 0.11 0 1.5707 1.5707</origin>
            <collision name="collision">
                <mass>0.5</mass>
                <geometry>
                    <cylinder radius="0.111" length="0.05" />
                </geometry>
                <surface>
                    <friction>
                        <ode mu="100000.0" mu2="100000.0" slip1="0.0" slip2="0.0" />
                    </friction>
                </surface>
            </collision>
            <visual name="visual">
                <geometry>
                    <cylinder radius="0.111" length="0.05" />
                </geometry>
                <material script="Gazebo/FlatBlack" />
            </visual>
        </link>
        <joint type="revolute" name="front_left_wheel_hinge">
            <origin>0 0 -0.03 0 0 0</origin>
            <child link="front_left_wheel" />
            <parent link="chassis" />
            <axis xyz="0 1 0" />
        </joint>
        <joint type="revolute" name="front_right_wheel_hinge">
            <origin>0 0 0.03 0 0 0</origin>
            <child link="front_right_wheel" />
            <parent link="chassis" />
            <axis xyz="0 1 0" />
        </joint>
        <joint type="revolute" name="back_left_wheel_hinge">
            <origin>0 0 -0.03 0 0 0</origin>
            <child link="back_left_wheel" />
            <parent link="chassis" />
            <axis xyz="0 1 0" />
        </joint>
        <joint type="revolute" name="back_right_wheel_hinge">
            <origin>0 0 0.03 0 0 0</origin>
            <child link="back_right_wheel" />
            <parent link="chassis" />
            <axis xyz="0 1 0" />
        </joint>
        <!--
    <plugin filename="libDiffDrivePlugin.so" name="diff_drive">
      <left_joint>front_left_wheel_hinge</left_joint>
      <right_joint>front_right_wheel_hinge</right_joint>
      <torque>5</torque>
    </plugin>
    -->
    </model>
</gazebo>
