<gazebo version='1.0'>
  <model name="pioneer2dx" static="1">
    <link name="chassis">
      <origin pose="0.0 0.0 0.16 0 0 0"/>

      <collision name="collision">
        <mass>5.0</mass>
        <geometry>
          <box size="0.445 0.277 0.17"/>
        </geometry>
      </collision>
   
      <collision name="castor_collision">
        <origin pose="-0.200 0 -0.12 0 0 0"/>
        <mass>0.1</mass>
        <geometry>
          <sphere radius="0.04"/>
        </geometry>
        <surface>
          <friction>
            <ode mu="0" mu2="0" slip1="1.0" slip2="1.0"/>
          </friction>
        </surface>
      </collision>

       <visual name="my_visual2">
        <origin pose="0 0 0.04 0 0 0"/>
        <geometry>
          <mesh filename="pioneer2dx/chassis.dae"/>
        </geometry>
      </visual>

      <visual name="castor_visual">
        <origin pose="-0.200 0 -0.12 0 0 0"/>
        <geometry>
          <sphere radius="0.04"/>
        </geometry>
        <material script="Gazebo/FlatBlack"/>
      </visual>

    </link>

    <link name="right_wheel">
      <origin pose="0.1 -.17 0.11 0 1.5707 1.5707"/>
  
      <collision name="collision">
        <mass>0.5</mass>
        <geometry>
          <cylinder radius="0.11" length="0.05"/>
        </geometry>
        <surface>
          <friction>
            <ode mu="100000.0" mu2="100000.0" slip1="0.0" slip2="0.0"/>
          </friction>
        </surface>
      </collision>
   
      <visual name="visual">
        <geometry>
          <cylinder radius="0.11" length="0.05"/>
        </geometry>
        <material script="Gazebo/FlatBlack"/>
      </visual>
    </link>

    <link name="left_wheel">
      <origin pose="0.1 .17 0.11 0 1.5707 1.5707"/>
  
      <collision name="collision">
        <mass>0.5</mass>
        <geometry>
          <cylinder radius="0.11" length="0.05"/>
        </geometry>
        <surface>
          <friction>
            <ode mu="100000.0" mu2="100000.0" slip1="0.0" slip2="0.0"/>
          </friction>
        </surface>
      </collision>

      <visual name="visual">
        <geometry>
          <cylinder radius="0.11" length="0.05"/>
        </geometry>
        <material script="Gazebo/FlatBlack"/>
      </visual>
    </link>

    <joint type="revolute" name="left_wheel_hinge">
      <origin pose="0 0 -0.03 0 0 0"/>
      <child link="left_wheel"/>
      <parent link="chassis"/>
      <axis xyz="0 1 0"/>
    </joint>

    <joint type="revolute" name="right_wheel_hinge">
      <origin pose="0 0 0.03 0 0 0"/>
      <child link="right_wheel"/>
      <parent link="chassis"/>
      <axis xyz="0 1 0"/>
    </joint>

    <plugin filename="libDiffDrivePlugin.so" name="diff_drive">
      <left_joint>left_wheel_hinge</left_joint>
      <right_joint>right_wheel_hinge</right_joint>
      <torque>5</torque>
    </plugin>
  </model>
</gazebo>
