<gazebo version='1.2'>
  <model name='pr2' static='0'>
    <origin>0.000000 0.000000 0.000000 0.000000 -0.000000 0.000000</origin>
    <link name='base_footprint' gravity='1' self_collide='0' kinematic='0'>
      <origin>0.000000 0.000000 0.000000 0.000000 -0.000000 0.000000</origin>
      <inertial mass='118.001000'>
        <origin>-0.062421 0.000000 0.201365 0.000000 -0.000000 0.000000</origin>
        <inertia ixx='8.431730' ixy='-0.009720' ixz='1.901570' iyy='8.533050' iyz='-0.007380' izz='3.787470'/>
      </inertial>
      <collision name='base_footprint_geom' laser_retro='0.000000'>
        <origin>0.000000 0.000000 0.071000 0.000000 -0.000000 0.000000</origin>
        <geometry>
          <box size='0.001000 0.001000 0.001000'/>
        </geometry>
        <surface>
          <friction>
            <ode mu='0.000000' mu2='0.000000' fdir1='0.000000 0.000000 0.000000' slip1='0.000000' slip2='0.000000'/>
          </friction>
          <bounce restitution_coefficient='0.000000' threshold='100000.000000'/>
          <contact>
            <ode soft_cfm='0.000000' soft_erp='0.200000' kp='1000000000000.000000' kd='10000.000000' max_vel='100.000000' min_depth='0.000000'/>
          </contact>
        </surface>
      </collision>
      <visual name='base_footprint_geom_visual'>
        <origin>0.000000 0.000000 0.000000 0.000000 -0.000000 0.000000</origin>
        <geometry>
          <box size='0.010000 0.010000 0.010000'/>
        </geometry>
      </visual>
      <collision name='base_footprint_geom_base_bellow_link' laser_retro='0.000000'>
        <origin>-0.290000 0.000000 0.851000 0.000000 -0.000000 0.000000</origin>
        <geometry>
          <box size='0.050000 0.370000 0.300000'/>
        </geometry>
        <surface>
          <friction>
            <ode mu='0.000000' mu2='0.000000' fdir1='0.000000 0.000000 0.000000' slip1='0.000000' slip2='0.000000'/>
          </friction>
          <bounce restitution_coefficient='0.000000' threshold='100000.000000'/>
          <contact>
            <ode soft_cfm='0.000000' soft_erp='0.200000' kp='1000000000000.000000' kd='10000.000000' max_vel='100.000000' min_depth='0.000000'/>
          </contact>
        </surface>
      </collision>
      <visual name='base_footprint_geom_base_bellow_link_visual'>
        <origin>-0.290000 0.000000 0.851000 0.000000 -0.000000 0.000000</origin>
        <geometry>
          <box size='0.050000 0.370000 0.300000'/>
        </geometry>
      </visual>
      <collision name='base_footprint_geom_base_link' laser_retro='0.000000'>
        <origin>0.000000 0.000000 0.051000 0.000000 -0.000000 0.000000</origin>
        <geometry>
          <mesh filename='pr2/base_v0/base_L.stl' scale='1.000000 1.000000 1.000000'/>
        </geometry>
        <surface>
          <friction>
            <ode mu='0.000000' mu2='0.000000' fdir1='0.000000 0.000000 0.000000' slip1='0.000000' slip2='0.000000'/>
          </friction>
          <bounce restitution_coefficient='0.000000' threshold='100000.000000'/>
          <contact>
            <ode soft_cfm='0.000000' soft_erp='0.200000' kp='1000000000000.000000' kd='10000.000000' max_vel='100.000000' min_depth='0.000000'/>
          </contact>
        </surface>
      </collision>
      <visual name='base_footprint_geom_base_link_visual'>
        <origin>0.000000 0.000000 0.051000 0.000000 -0.000000 0.000000</origin>
        <geometry>
          <mesh filename='pr2/base_v0/base.dae' scale='1.000000 1.000000 1.000000'/>
        </geometry>
      </visual>
      <sensor name='base_contact_sensor' type='contact' always_on='0' update_rate='100.000000' visualize='0'>
        <origin>0.000000 0.000000 0.000000 0.000000 -0.000000 0.000000</origin>
        <contact>
          <collision name='base_footprint_geom_base_link'/>
        </contact>
        <plugin name='gazebo_contact' filename='libContactPlugin.so'/>
      </sensor>
      <sensor name='base_laser' type='ray' always_on='1' update_rate='20' visualize='true'>
        <origin>0.275000 0.000000 0.303000 0.000000 -0.000000 0.000000</origin>
        <ray>
          <scan>
            <horizontal samples='640' resolution='1.000000' min_angle='-2.268900' max_angle='2.268900'/>
          </scan>
          <range min='0.080000' max='10.000000' resolution='0.010000'/>
        </ray>
        <plugin name='laser' filename='libRayPlugin.so'/>
      </sensor>
    </link>
    <link name='bl_caster_rotation_link' gravity='1' self_collide='0' kinematic='0'>
      <origin>-0.224600 0.224600 0.079200 0.000000 -0.000000 0.000000</origin>
      <inertial mass='3.473080'>
        <origin>0.000000 0.000000 0.070000 0.000000 -0.000000 0.000000</origin>
        <inertia ixx='0.012412' ixy='-0.000712' ixz='0.000503' iyy='0.015218' iyz='-0.000004' izz='0.011764'/>
      </inertial>
      <collision name='bl_caster_rotation_link_geom' laser_retro='0.000000'>
        <origin>0.000000 0.000000 0.000000 0.000000 -0.000000 0.000000</origin>
        <geometry>
          <mesh filename='pr2/base_v0/caster_L.stl' scale='1.000000 1.000000 1.000000'/>
        </geometry>
        <surface>
          <friction>
            <ode mu='0.000000' mu2='0.000000' fdir1='0.000000 0.000000 0.000000' slip1='0.000000' slip2='0.000000'/>
          </friction>
          <bounce restitution_coefficient='0.000000' threshold='100000.000000'/>
          <contact>
            <ode soft_cfm='0.000000' soft_erp='0.200000' kp='1000000000000.000000' kd='10000.000000' max_vel='100.000000' min_depth='0.000000'/>
          </contact>
        </surface>
      </collision>
      <visual name='bl_caster_rotation_link_geom_visual'>
        <origin>0.000000 0.000000 0.000000 0.000000 -0.000000 0.000000</origin>
        <geometry>
          <mesh filename='pr2/base_v0/caster.stl' scale='1.000000 1.000000 1.000000'/>
        </geometry>
      </visual>
    </link>
    <link name='bl_caster_l_wheel_link' gravity='1' self_collide='0' kinematic='0'>
      <origin>-0.224600 0.273600 0.079200 0.000000 -0.000000 0.000000</origin>
      <inertial mass='0.440360'>
        <origin>0.000000 0.000000 0.000000 0.000000 -0.000000 0.000000</origin>
        <inertia ixx='0.012412' ixy='-0.000712' ixz='0.000503' iyy='0.015218' iyz='-0.000004' izz='0.011764'/>
      </inertial>
      <collision name='bl_caster_l_wheel_link_geom' laser_retro='0.000000'>
        <origin>0.000000 0.000000 0.000000 1.570800 -0.000000 0.000000</origin>
        <geometry>
          <cylinder radius='0.074792' length='0.034000'/>
        </geometry>
        <surface>
          <friction>
            <ode mu='100.000000' mu2='100.000000' fdir1='0.000000 0.000000 0.000000' slip1='0.000000' slip2='0.000000'/>
          </friction>
          <bounce restitution_coefficient='0.000000' threshold='100000.000000'/>
          <contact>
            <ode soft_cfm='0.000000' soft_erp='0.200000' kp='1000000.000000' kd='1.000000' max_vel='100.000000' min_depth='0.000000'/>
          </contact>
        </surface>
      </collision>
      <visual name='bl_caster_l_wheel_link_geom_visual'>
        <origin>0.000000 0.000000 0.000000 0.000000 -0.000000 0.000000</origin>
        <geometry>
          <mesh filename='pr2/base_v0/wheel.dae' scale='1.000000 1.000000 1.000000'/>
        </geometry>
      </visual>
    </link>
    <link name='bl_caster_r_wheel_link' gravity='1' self_collide='0' kinematic='0'>
      <origin>-0.224600 0.175600 0.079200 0.000000 -0.000000 0.000000</origin>
      <inertial mass='0.440360'>
        <origin>0.000000 0.000000 0.000000 0.000000 -0.000000 0.000000</origin>
        <inertia ixx='0.012412' ixy='-0.000712' ixz='0.000503' iyy='0.015218' iyz='-0.000004' izz='0.011764'/>
      </inertial>
      <collision name='bl_caster_r_wheel_link_geom' laser_retro='0.000000'>
        <origin>0.000000 0.000000 0.000000 1.570800 -0.000000 0.000000</origin>
        <geometry>
          <cylinder radius='0.074792' length='0.034000'/>
        </geometry>
        <surface>
          <friction>
            <ode mu='100.000000' mu2='100.000000' fdir1='0.000000 0.000000 0.000000' slip1='0.000000' slip2='0.000000'/>
          </friction>
          <bounce restitution_coefficient='0.000000' threshold='100000.000000'/>
          <contact>
            <ode soft_cfm='0.000000' soft_erp='0.200000' kp='1000000.000000' kd='1.000000' max_vel='100.000000' min_depth='0.000000'/>
          </contact>
        </surface>
      </collision>
      <visual name='bl_caster_r_wheel_link_geom_visual'>
        <origin>0.000000 0.000000 0.000000 0.000000 -0.000000 0.000000</origin>
        <geometry>
          <mesh filename='pr2/base_v0/wheel.dae' scale='1.000000 1.000000 1.000000'/>
        </geometry>
      </visual>
    </link>
    <link name='br_caster_rotation_link' gravity='1' self_collide='0' kinematic='0'>
      <origin>-0.224600 -0.224600 0.079200 0.000000 -0.000000 0.000000</origin>
      <inertial mass='3.473080'>
        <origin>0.000000 0.000000 0.070000 0.000000 -0.000000 0.000000</origin>
        <inertia ixx='0.012412' ixy='-0.000712' ixz='0.000503' iyy='0.015218' iyz='-0.000004' izz='0.011764'/>
      </inertial>
      <collision name='br_caster_rotation_link_geom' laser_retro='0.000000'>
        <origin>0.000000 0.000000 0.000000 0.000000 -0.000000 0.000000</origin>
        <geometry>
          <mesh filename='pr2/base_v0/caster_L.stl' scale='1.000000 1.000000 1.000000'/>
        </geometry>
        <surface>
          <friction>
            <ode mu='0.000000' mu2='0.000000' fdir1='0.000000 0.000000 0.000000' slip1='0.000000' slip2='0.000000'/>
          </friction>
          <bounce restitution_coefficient='0.000000' threshold='100000.000000'/>
          <contact>
            <ode soft_cfm='0.000000' soft_erp='0.200000' kp='1000000000000.000000' kd='10000.000000' max_vel='100.000000' min_depth='0.000000'/>
          </contact>
        </surface>
      </collision>
      <visual name='br_caster_rotation_link_geom_visual'>
        <origin>0.000000 0.000000 0.000000 0.000000 -0.000000 0.000000</origin>
        <geometry>
          <mesh filename='pr2/base_v0/caster.stl' scale='1.000000 1.000000 1.000000'/>
        </geometry>
      </visual>
    </link>
    <link name='br_caster_l_wheel_link' gravity='1' self_collide='0' kinematic='0'>
      <origin>-0.224600 -0.175600 0.079200 0.000000 -0.000000 0.000000</origin>
      <inertial mass='0.440360'>
        <origin>0.000000 0.000000 0.000000 0.000000 -0.000000 0.000000</origin>
        <inertia ixx='0.012412' ixy='-0.000712' ixz='0.000503' iyy='0.015218' iyz='-0.000004' izz='0.011764'/>
      </inertial>
      <collision name='br_caster_l_wheel_link_geom' laser_retro='0.000000'>
        <origin>0.000000 0.000000 0.000000 1.570800 -0.000000 0.000000</origin>
        <geometry>
          <cylinder radius='0.074792' length='0.034000'/>
        </geometry>
        <surface>
          <friction>
            <ode mu='100.000000' mu2='100.000000' fdir1='0.000000 0.000000 0.000000' slip1='0.000000' slip2='0.000000'/>
          </friction>
          <bounce restitution_coefficient='0.000000' threshold='100000.000000'/>
          <contact>
            <ode soft_cfm='0.000000' soft_erp='0.200000' kp='1000000.000000' kd='1.000000' max_vel='100.000000' min_depth='0.000000'/>
          </contact>
        </surface>
      </collision>
      <visual name='br_caster_l_wheel_link_geom_visual'>
        <origin>0.000000 0.000000 0.000000 0.000000 -0.000000 0.000000</origin>
        <geometry>
          <mesh filename='pr2/base_v0/wheel.dae' scale='1.000000 1.000000 1.000000'/>
        </geometry>
      </visual>
    </link>
    <link name='br_caster_r_wheel_link' gravity='1' self_collide='0' kinematic='0'>
      <origin>-0.224600 -0.273600 0.079200 0.000000 -0.000000 0.000000</origin>
      <inertial mass='0.440360'>
        <origin>0.000000 0.000000 0.000000 0.000000 -0.000000 0.000000</origin>
        <inertia ixx='0.012412' ixy='-0.000712' ixz='0.000503' iyy='0.015218' iyz='-0.000004' izz='0.011764'/>
      </inertial>
      <collision name='br_caster_r_wheel_link_geom' laser_retro='0.000000'>
        <origin>0.000000 0.000000 0.000000 1.570800 -0.000000 0.000000</origin>
        <geometry>
          <cylinder radius='0.074792' length='0.034000'/>
        </geometry>
        <surface>
          <friction>
            <ode mu='100.000000' mu2='100.000000' fdir1='0.000000 0.000000 0.000000' slip1='0.000000' slip2='0.000000'/>
          </friction>
          <bounce restitution_coefficient='0.000000' threshold='100000.000000'/>
          <contact>
            <ode soft_cfm='0.000000' soft_erp='0.200000' kp='1000000.000000' kd='1.000000' max_vel='100.000000' min_depth='0.000000'/>
          </contact>
        </surface>
      </collision>
      <visual name='br_caster_r_wheel_link_geom_visual'>
        <origin>0.000000 0.000000 0.000000 0.000000 -0.000000 0.000000</origin>
        <geometry>
          <mesh filename='pr2/base_v0/wheel.dae' scale='1.000000 1.000000 1.000000'/>
        </geometry>
      </visual>
    </link>
    <link name='fl_caster_rotation_link' gravity='1' self_collide='0' kinematic='0'>
      <origin>0.224600 0.224600 0.079200 0.000000 -0.000000 0.000000</origin>
      <inertial mass='3.473080'>
        <origin>0.000000 0.000000 0.070000 0.000000 -0.000000 0.000000</origin>
        <inertia ixx='0.012412' ixy='-0.000712' ixz='0.000503' iyy='0.015218' iyz='-0.000004' izz='0.011764'/>
      </inertial>
      <collision name='fl_caster_rotation_link_geom' laser_retro='0.000000'>
        <origin>0.000000 0.000000 0.000000 0.000000 -0.000000 0.000000</origin>
        <geometry>
          <mesh filename='pr2/base_v0/caster_L.stl' scale='1.000000 1.000000 1.000000'/>
        </geometry>
        <surface>
          <friction>
            <ode mu='0.000000' mu2='0.000000' fdir1='0.000000 0.000000 0.000000' slip1='0.000000' slip2='0.000000'/>
          </friction>
          <bounce restitution_coefficient='0.000000' threshold='100000.000000'/>
          <contact>
            <ode soft_cfm='0.000000' soft_erp='0.200000' kp='1000000000000.000000' kd='10000.000000' max_vel='100.000000' min_depth='0.000000'/>
          </contact>
        </surface>
      </collision>
      <visual name='fl_caster_rotation_link_geom_visual'>
        <origin>0.000000 0.000000 0.000000 0.000000 -0.000000 0.000000</origin>
        <geometry>
          <mesh filename='pr2/base_v0/caster.stl' scale='1.000000 1.000000 1.000000'/>
        </geometry>
      </visual>
    </link>
    <link name='fl_caster_l_wheel_link' gravity='1' self_collide='0' kinematic='0'>
      <origin>0.224600 0.273600 0.079200 0.000000 -0.000000 0.000000</origin>
      <inertial mass='0.440360'>
        <origin>0.000000 0.000000 0.000000 0.000000 -0.000000 0.000000</origin>
        <inertia ixx='0.012412' ixy='-0.000712' ixz='0.000503' iyy='0.015218' iyz='-0.000004' izz='0.011764'/>
      </inertial>
      <collision name='fl_caster_l_wheel_link_geom' laser_retro='0.000000'>
        <origin>0.000000 0.000000 0.000000 1.570800 -0.000000 0.000000</origin>
        <geometry>
          <cylinder radius='0.074792' length='0.034000'/>
        </geometry>
        <surface>
          <friction>
            <ode mu='100.000000' mu2='100.000000' fdir1='0.000000 0.000000 0.000000' slip1='0.000000' slip2='0.000000'/>
          </friction>
          <bounce restitution_coefficient='0.000000' threshold='100000.000000'/>
          <contact>
            <ode soft_cfm='0.000000' soft_erp='0.200000' kp='1000000.000000' kd='1.000000' max_vel='100.000000' min_depth='0.000000'/>
          </contact>
        </surface>
      </collision>
      <visual name='fl_caster_l_wheel_link_geom_visual'>
        <origin>0.000000 0.000000 0.000000 0.000000 -0.000000 0.000000</origin>
        <geometry>
          <mesh filename='pr2/base_v0/wheel.dae' scale='1.000000 1.000000 1.000000'/>
        </geometry>
      </visual>
    </link>
    <link name='fl_caster_r_wheel_link' gravity='1' self_collide='0' kinematic='0'>
      <origin>0.224600 0.175600 0.079200 0.000000 -0.000000 0.000000</origin>
      <inertial mass='0.440360'>
        <origin>0.000000 0.000000 0.000000 0.000000 -0.000000 0.000000</origin>
        <inertia ixx='0.012412' ixy='-0.000712' ixz='0.000503' iyy='0.015218' iyz='-0.000004' izz='0.011764'/>
      </inertial>
      <collision name='fl_caster_r_wheel_link_geom' laser_retro='0.000000'>
        <origin>0.000000 0.000000 0.000000 1.570800 -0.000000 0.000000</origin>
        <geometry>
          <cylinder radius='0.074792' length='0.034000'/>
        </geometry>
        <surface>
          <friction>
            <ode mu='100.000000' mu2='100.000000' fdir1='0.000000 0.000000 0.000000' slip1='0.000000' slip2='0.000000'/>
          </friction>
          <bounce restitution_coefficient='0.000000' threshold='100000.000000'/>
          <contact>
            <ode soft_cfm='0.000000' soft_erp='0.200000' kp='1000000.000000' kd='1.000000' max_vel='100.000000' min_depth='0.000000'/>
          </contact>
        </surface>
      </collision>
      <visual name='fl_caster_r_wheel_link_geom_visual'>
        <origin>0.000000 0.000000 0.000000 0.000000 -0.000000 0.000000</origin>
        <geometry>
          <mesh filename='pr2/base_v0/wheel.dae' scale='1.000000 1.000000 1.000000'/>
        </geometry>
      </visual>
    </link>
    <link name='fr_caster_rotation_link' gravity='1' self_collide='0' kinematic='0'>
      <origin>0.224600 -0.224600 0.079200 0.000000 -0.000000 0.000000</origin>
      <inertial mass='3.473080'>
        <origin>0.000000 0.000000 0.070000 0.000000 -0.000000 0.000000</origin>
        <inertia ixx='0.012412' ixy='-0.000712' ixz='0.000503' iyy='0.015218' iyz='-0.000004' izz='0.011764'/>
      </inertial>
      <collision name='fr_caster_rotation_link_geom' laser_retro='0.000000'>
        <origin>0.000000 0.000000 0.000000 0.000000 -0.000000 0.000000</origin>
        <geometry>
          <mesh filename='pr2/base_v0/caster_L.stl' scale='1.000000 1.000000 1.000000'/>
        </geometry>
        <surface>
          <friction>
            <ode mu='0.000000' mu2='0.000000' fdir1='0.000000 0.000000 0.000000' slip1='0.000000' slip2='0.000000'/>
          </friction>
          <bounce restitution_coefficient='0.000000' threshold='100000.000000'/>
          <contact>
            <ode soft_cfm='0.000000' soft_erp='0.200000' kp='1000000000000.000000' kd='10000.000000' max_vel='100.000000' min_depth='0.000000'/>
          </contact>
        </surface>
      </collision>
      <visual name='fr_caster_rotation_link_geom_visual'>
        <origin>0.000000 0.000000 0.000000 0.000000 -0.000000 0.000000</origin>
        <geometry>
          <mesh filename='pr2/base_v0/caster.stl' scale='1.000000 1.000000 1.000000'/>
        </geometry>
      </visual>
    </link>
    <link name='fr_caster_l_wheel_link' gravity='1' self_collide='0' kinematic='0'>
      <origin>0.224600 -0.175600 0.079200 0.000000 -0.000000 0.000000</origin>
      <inertial mass='0.440360'>
        <origin>0.000000 0.000000 0.000000 0.000000 -0.000000 0.000000</origin>
        <inertia ixx='0.012412' ixy='-0.000712' ixz='0.000503' iyy='0.015218' iyz='-0.000004' izz='0.011764'/>
      </inertial>
      <collision name='fr_caster_l_wheel_link_geom' laser_retro='0.000000'>
        <origin>0.000000 0.000000 0.000000 1.570800 -0.000000 0.000000</origin>
        <geometry>
          <cylinder radius='0.074792' length='0.034000'/>
        </geometry>
        <surface>
          <friction>
            <ode mu='100.000000' mu2='100.000000' fdir1='0.000000 0.000000 0.000000' slip1='0.000000' slip2='0.000000'/>
          </friction>
          <bounce restitution_coefficient='0.000000' threshold='100000.000000'/>
          <contact>
            <ode soft_cfm='0.000000' soft_erp='0.200000' kp='1000000.000000' kd='1.000000' max_vel='100.000000' min_depth='0.000000'/>
          </contact>
        </surface>
      </collision>
      <visual name='fr_caster_l_wheel_link_geom_visual'>
        <origin>0.000000 0.000000 0.000000 0.000000 -0.000000 0.000000</origin>
        <geometry>
          <mesh filename='pr2/base_v0/wheel.dae' scale='1.000000 1.000000 1.000000'/>
        </geometry>
      </visual>
    </link>
    <link name='fr_caster_r_wheel_link' gravity='1' self_collide='0' kinematic='0'>
      <origin>0.224600 -0.273600 0.079200 0.000000 -0.000000 0.000000</origin>
      <inertial mass='0.440360'>
        <origin>0.000000 0.000000 0.000000 0.000000 -0.000000 0.000000</origin>
        <inertia ixx='0.012412' ixy='-0.000712' ixz='0.000503' iyy='0.015218' iyz='-0.000004' izz='0.011764'/>
      </inertial>
      <collision name='fr_caster_r_wheel_link_geom' laser_retro='0.000000'>
        <origin>0.000000 0.000000 0.000000 1.570800 -0.000000 0.000000</origin>
        <geometry>
          <cylinder radius='0.074792' length='0.034000'/>
        </geometry>
        <surface>
          <friction>
            <ode mu='100.000000' mu2='100.000000' fdir1='0.000000 0.000000 0.000000' slip1='0.000000' slip2='0.000000'/>
          </friction>
          <bounce restitution_coefficient='0.000000' threshold='100000.000000'/>
          <contact>
            <ode soft_cfm='0.000000' soft_erp='0.200000' kp='1000000.000000' kd='1.000000' max_vel='100.000000' min_depth='0.000000'/>
          </contact>
        </surface>
      </collision>
      <visual name='fr_caster_r_wheel_link_geom_visual'>
        <origin>0.000000 0.000000 0.000000 0.000000 -0.000000 0.000000</origin>
        <geometry>
          <mesh filename='pr2/base_v0/wheel.dae' scale='1.000000 1.000000 1.000000'/>
        </geometry>
      </visual>
    </link>
    <link name='torso_lift_link' gravity='1' self_collide='0' kinematic='0'>
      <origin>-0.050000 0.000000 0.790675 0.000000 -0.000000 0.000000</origin>
      <inertial mass='36.449000'>
        <origin>-0.099499 -0.000004 -0.086764 0.000000 -0.000000 0.000000</origin>
        <inertia ixx='2.792330' ixy='0.004280' ixz='-0.160631' iyy='2.521060' iyz='0.029689' izz='0.536551'/>
      </inertial>
      <collision name='torso_lift_link_geom' laser_retro='0.000000'>
        <origin>0.000000 0.000000 0.000000 0.000000 -0.000000 0.000000</origin>
        <geometry>
          <mesh filename='pr2/torso_v0/torso_lift_L.stl' scale='1.000000 1.000000 1.000000'/>
        </geometry>
        <surface>
          <friction>
            <ode mu='0.000000' mu2='0.000000' fdir1='0.000000 0.000000 0.000000' slip1='0.000000' slip2='0.000000'/>
          </friction>
          <bounce restitution_coefficient='0.000000' threshold='100000.000000'/>
          <contact>
            <ode soft_cfm='0.000000' soft_erp='0.200000' kp='1000000000000.000000' kd='10000.000000' max_vel='100.000000' min_depth='0.000000'/>
          </contact>
        </surface>
      </collision>
      <visual name='torso_lift_link_geom_visual'>
        <origin>0.000000 0.000000 0.000000 0.000000 -0.000000 0.000000</origin>
        <geometry>
          <mesh filename='pr2/torso_v0/torso_lift.dae' scale='1.000000 1.000000 1.000000'/>
        </geometry>
      </visual>
      <sensor name='torso_lift_contact_sensor' type='contact' always_on='0' update_rate='100.000000' visualize='0'>
        <origin>0.000000 0.000000 0.000000 0.000000 -0.000000 0.000000</origin>
        <contact>
          <collision name='torso_lift_link_geom'/>
        </contact>
      </sensor>
    </link>
    <link name='head_pan_link' gravity='1' self_collide='0' kinematic='0'>
      <origin>-0.067070 0.000000 1.172130 0.000000 -0.000000 0.000000</origin>
      <inertial mass='6.339000'>
        <origin>0.010907 0.031693 0.090507 0.000000 -0.000000 0.000000</origin>
        <inertia ixx='0.032498' ixy='0.000636' ixz='0.002585' iyy='0.046546' iyz='-0.002453' izz='0.057653'/>
      </inertial>
      <collision name='head_pan_link_geom' laser_retro='0.000000'>
        <origin>0.000000 0.000000 0.000000 0.000000 -0.000000 0.000000</origin>
        <geometry>
          <mesh filename='pr2/head_v0/head_pan_L.stl' scale='1.000000 1.000000 1.000000'/>
        </geometry>
        <surface>
          <friction>
            <ode mu='0.000000' mu2='0.000000' fdir1='0.000000 0.000000 0.000000' slip1='0.000000' slip2='0.000000'/>
          </friction>
          <bounce restitution_coefficient='0.000000' threshold='100000.000000'/>
          <contact>
            <ode soft_cfm='0.000000' soft_erp='0.200000' kp='1000000000000.000000' kd='10000.000000' max_vel='100.000000' min_depth='0.000000'/>
          </contact>
        </surface>
      </collision>
      <visual name='head_pan_link_geom_visual'>
        <origin>0.000000 0.000000 0.000000 0.000000 -0.000000 0.000000</origin>
        <geometry>
          <mesh filename='pr2/head_v0/head_pan.dae' scale='1.000000 1.000000 1.000000'/>
        </geometry>
      </visual>
    </link>
    <link name='head_tilt_link' gravity='1' self_collide='0' kinematic='0'>
      <origin>0.000930 0.000000 1.172130 0.000000 -0.000000 0.000000</origin>
      <inertial mass='5.319000'>
        <origin>-0.005151 -0.014635 0.072819 0.000000 -0.000000 0.000000</origin>
        <inertia ixx='0.126134' ixy='0.000237' ixz='0.011881' iyy='0.165102' iyz='0.001606' izz='0.166947'/>
      </inertial>
      <collision name='head_tilt_link_geom' laser_retro='0.000000'>
        <origin>0.000000 0.000000 0.000000 0.000000 -0.000000 0.000000</origin>
        <geometry>
          <mesh filename='pr2/head_v0/head_tilt_L.stl' scale='1.000000 1.000000 1.000000'/>
        </geometry>
        <surface>
          <friction>
            <ode mu='0.000000' mu2='0.000000' fdir1='0.000000 0.000000 0.000000' slip1='0.000000' slip2='0.000000'/>
          </friction>
          <bounce restitution_coefficient='0.000000' threshold='100000.000000'/>
          <contact>
            <ode soft_cfm='0.000000' soft_erp='0.200000' kp='1000000000000.000000' kd='10000.000000' max_vel='100.000000' min_depth='0.000000'/>
          </contact>
        </surface>
      </collision>
      <visual name='head_tilt_link_geom_visual'>
        <origin>0.000000 0.000000 0.000000 0.000000 -0.000000 0.000000</origin>
        <geometry>
          <mesh filename='pr2/head_v0/head_tilt.dae' scale='1.000000 1.000000 1.000000'/>
        </geometry>
      </visual>
      <collision name='head_tilt_link_geom_head_mount_kinect_ir_link' laser_retro='0.000000'>
        <origin>-0.147067 0.012500 0.291953 0.000000 -0.000000 0.000000</origin>
        <geometry>
          <sphere radius='0.000500'/>
        </geometry>
        <surface>
          <friction>
            <ode mu='0.000000' mu2='0.000000' fdir1='0.000000 0.000000 0.000000' slip1='0.000000' slip2='0.000000'/>
          </friction>
          <bounce restitution_coefficient='0.000000' threshold='100000.000000'/>
          <contact>
            <ode soft_cfm='0.000000' soft_erp='0.200000' kp='1000000000000.000000' kd='10000.000000' max_vel='100.000000' min_depth='0.000000'/>
          </contact>
        </surface>
      </collision>
      <visual name='head_tilt_link_geom_head_mount_kinect_ir_link_visual'>
        <origin>-0.147067 0.012500 0.291953 0.000000 -0.000000 0.000000</origin>
        <geometry>
          <sphere radius='0.000250'/>
        </geometry>
        <material script='Gazebo/Red'/>
      </visual>
      <collision name='head_tilt_link_geom_head_mount_kinect_rgb_link' laser_retro='0.000000'>
        <origin>-0.147067 -0.017500 0.291953 0.000000 -0.000000 0.000000</origin>
        <geometry>
          <sphere radius='0.000500'/>
        </geometry>
        <surface>
          <friction>
            <ode mu='0.000000' mu2='0.000000' fdir1='0.000000 0.000000 0.000000' slip1='0.000000' slip2='0.000000'/>
          </friction>
          <bounce restitution_coefficient='0.000000' threshold='100000.000000'/>
          <contact>
            <ode soft_cfm='0.000000' soft_erp='0.200000' kp='1000000000000.000000' kd='10000.000000' max_vel='100.000000' min_depth='0.000000'/>
          </contact>
        </surface>
      </collision>
      <visual name='head_tilt_link_geom_head_mount_kinect_rgb_link_visual'>
        <origin>-0.147067 -0.017500 0.291953 0.000000 -0.000000 0.000000</origin>
        <geometry>
          <sphere radius='0.000250'/>
        </geometry>
        <material script='Gazebo/Red'/>
      </visual>
      <collision name='head_tilt_link_geom_head_mount_link' laser_retro='0.000000'>
        <origin>-0.114800 0.000000 0.155500 0.000000 -0.000000 0.000000</origin>
        <geometry>
          <sphere radius='0.000500'/>
        </geometry>
        <surface>
          <friction>
            <ode mu='0.000000' mu2='0.000000' fdir1='0.000000 0.000000 0.000000' slip1='0.000000' slip2='0.000000'/>
          </friction>
          <bounce restitution_coefficient='0.000000' threshold='100000.000000'/>
          <contact>
            <ode soft_cfm='0.000000' soft_erp='0.200000' kp='1000000000000.000000' kd='10000.000000' max_vel='100.000000' min_depth='0.000000'/>
          </contact>
        </surface>
      </collision>
      <visual name='head_tilt_link_geom_head_mount_link_visual'>
        <origin>-0.114800 0.000000 0.155500 0.000000 -0.000000 0.000000</origin>
        <geometry>
          <mesh filename='pr2/sensors/kinect_prosilica_v0/115x100_swept_back--coarse.STL' scale='0.001000 0.001000 0.001000'/>
        </geometry>
      </visual>
      <collision name='head_tilt_link_geom_head_mount_prosilica_link' laser_retro='0.000000'>
        <origin>-0.161257 0.012500 0.244421 0.000000 -0.000000 0.000000</origin>
        <geometry>
          <sphere radius='0.000500'/>
        </geometry>
        <surface>
          <friction>
            <ode mu='0.000000' mu2='0.000000' fdir1='0.000000 0.000000 0.000000' slip1='0.000000' slip2='0.000000'/>
          </friction>
          <bounce restitution_coefficient='0.000000' threshold='100000.000000'/>
          <contact>
            <ode soft_cfm='0.000000' soft_erp='0.200000' kp='1000000000000.000000' kd='10000.000000' max_vel='100.000000' min_depth='0.000000'/>
          </contact>
        </surface>
      </collision>
      <visual name='head_tilt_link_geom_head_mount_prosilica_link_visual'>
        <origin>-0.161257 0.012500 0.244421 0.000000 -0.000000 0.000000</origin>
        <geometry>
          <sphere radius='0.000250'/>
        </geometry>
        <material script='Gazebo/Red'/>
      </visual>
      <collision name='head_tilt_link_geom_head_plate_frame' laser_retro='0.000000'>
        <origin>0.023200 0.000000 0.064500 0.000000 -0.000000 0.000000</origin>
        <geometry>
          <box size='0.010000 0.010000 0.010000'/>
        </geometry>
        <surface>
          <friction>
            <ode mu='0.000000' mu2='0.000000' fdir1='0.000000 0.000000 0.000000' slip1='0.000000' slip2='0.000000'/>
          </friction>
          <bounce restitution_coefficient='0.000000' threshold='100000.000000'/>
          <contact>
            <ode soft_cfm='0.000000' soft_erp='0.200000' kp='1000000000000.000000' kd='10000.000000' max_vel='100.000000' min_depth='0.000000'/>
          </contact>
        </surface>
      </collision>
      <visual name='head_tilt_link_geom_head_plate_frame_visual'>
        <origin>0.023200 0.000000 0.064500 0.000000 -0.000000 0.000000</origin>
        <geometry>
          <box size='0.010000 0.010000 0.010000'/>
        </geometry>
        <material script='Gazebo/Grey'/>
      </visual>
      <sensor name='head_mount_sensor' type='camera' always_on='1' update_rate='1.000000' visualize='1'>
        <origin>-0.147067 0.012500 0.291953 0.000000 -0.000000 0.000000</origin>
        <camera>
          <horizontal_fov angle='0.994838'/>
          <image width='640' height='480' format='L8'/>
          <clip near='0.010000' far='5.000000'/>
        </camera>
      </sensor>
      <sensor name='head_mount_sensor' type='camera' always_on='0' update_rate='1.000000' visualize='0'>
        <origin>-0.147067 -0.017500 0.291953 0.000000 -0.000000 0.000000</origin>
        <camera>
          <horizontal_fov angle='0.994838'/>
          <image width='640' height='480' format='R8G8B8'/>
          <clip near='0.010000' far='5.000000'/>
        </camera>
      </sensor>
      <sensor name='head_mount_prosilica_link_sensor' type='camera' always_on='0' update_rate='1.000000' visualize='0'>
        <origin>-0.161257 0.012500 0.244421 0.000000 -0.000000 0.000000</origin>
        <camera>
          <horizontal_fov angle='1.120501'/>
          <image width='320' height='240' format='R8G8B8'/>
          <clip near='0.100000' far='100.000000'/>
        </camera>
      </sensor>
      <sensor name='head_mount_prosilica_link_sim_pcd_sensor' type='camera' always_on='0' update_rate='1.000000' visualize='0'>
        <origin>-0.161257 0.012500 0.244421 0.000000 -0.000000 0.000000</origin>
        <camera>
          <horizontal_fov angle='1.120501'/>
          <image width='320' height='240' format='R8G8B8'/>
          <clip near='0.100000' far='100.000000'/>
        </camera>
      </sensor>
      <sensor name='narrow_stereo_gazebo_l_stereo_camera_sensor' type='camera' always_on='0' update_rate='25.000000' visualize='0'>
        <origin>0.068200 0.060000 0.114600 0.000000 -0.000000 0.000000</origin>
        <camera>
          <horizontal_fov angle='0.785398'/>
          <image width='640' height='480' format='L8'/>
          <clip near='0.100000' far='100.000000'/>
        </camera>
      </sensor>
      <sensor name='narrow_stereo_gazebo_r_stereo_camera_sensor' type='camera' always_on='0' update_rate='25.000000' visualize='0'>
        <origin>0.068200 -0.030000 0.114600 0.000000 -0.000000 0.000000</origin>
        <camera>
          <horizontal_fov angle='0.785398'/>
          <image width='640' height='480' format='L8'/>
          <clip near='0.100000' far='100.000000'/>
        </camera>
      </sensor>
      <sensor name='wide_stereo_gazebo_l_stereo_camera_sensor' type='camera' always_on='0' update_rate='25.000000' visualize='0'>
        <origin>0.068200 0.030000 0.114600 0.000000 -0.000000 0.000000</origin>
        <camera>
          <horizontal_fov angle='1.570796'/>
          <image width='640' height='480' format='BAYER_BGGR8'/>
          <clip near='0.100000' far='100.000000'/>
        </camera>
      </sensor>
      <sensor name='wide_stereo_gazebo_r_stereo_camera_sensor' type='camera' always_on='0' update_rate='25.000000' visualize='0'>
        <origin>0.068200 -0.060000 0.114600 0.000000 -0.000000 0.000000</origin>
        <camera>
          <horizontal_fov angle='1.570796'/>
          <image width='640' height='480' format='BAYER_BGGR8'/>
          <clip near='0.100000' far='100.000000'/>
        </camera>
      </sensor>
      <sensor name='high_def_sensor' type='camera' always_on='0' update_rate='20.000000' visualize='0'>
        <origin>0.069657 -0.110000 0.119100 0.000000 -0.000000 0.000000</origin>
        <camera>
          <horizontal_fov angle='0.785398'/>
          <image width='2448' height='2050' format='R8G8B8'/>
          <clip near='0.100000' far='100.000000'/>
        </camera>
      </sensor>
    </link>
    <link name='l_shoulder_pan_link' gravity='0' self_collide='0' kinematic='0'>
      <origin>-0.050000 0.188000 0.790675 0.000000 -0.000000 0.000000</origin>
      <inertial mass='25.799300'>
        <origin>-0.001201 0.024513 -0.098231 0.000000 -0.000000 0.000000</origin>
        <inertia ixx='0.866179' ixy='-0.060865' ixz='-0.121181' iyy='0.874217' iyz='-0.058866' izz='0.273538'/>
      </inertial>
      <collision name='l_shoulder_pan_link_geom' laser_retro='0.000000'>
        <origin>0.000000 0.000000 0.000000 0.000000 -0.000000 0.000000</origin>
        <geometry>
          <mesh filename='pr2/shoulder_v0/shoulder_pan.stl' scale='1.000000 1.000000 1.000000'/>
        </geometry>
        <surface>
          <friction>
            <ode mu='0.000000' mu2='0.000000' fdir1='0.000000 0.000000 0.000000' slip1='0.000000' slip2='0.000000'/>
          </friction>
          <bounce restitution_coefficient='0.000000' threshold='100000.000000'/>
          <contact>
            <ode soft_cfm='0.000000' soft_erp='0.200000' kp='1000000000000.000000' kd='10000.000000' max_vel='100.000000' min_depth='0.000000'/>
          </contact>
        </surface>
      </collision>
      <visual name='l_shoulder_pan_link_geom_visual'>
        <origin>0.000000 0.000000 0.000000 0.000000 -0.000000 0.000000</origin>
        <geometry>
          <mesh filename='pr2/shoulder_v0/shoulder_pan.dae' scale='1.000000 1.000000 1.000000'/>
        </geometry>
      </visual>
    </link>
    <link name='l_shoulder_lift_link' gravity='0' self_collide='0' kinematic='0'>
      <origin>0.050000 0.188000 0.790675 0.000000 -0.000000 0.000000</origin>
      <inertial mass='2.749880'>
        <origin>0.021950 -0.026640 -0.031270 0.000000 -0.000000 0.000000</origin>
        <inertia ixx='0.021056' ixy='0.004967' ixz='-0.001948' iyy='0.021272' iyz='0.001104' izz='0.019758'/>
      </inertial>
      <collision name='l_shoulder_lift_link_geom' laser_retro='0.000000'>
        <origin>0.000000 0.000000 0.000000 0.000000 -0.000000 0.000000</origin>
        <geometry>
          <mesh filename='pr2/shoulder_v0/shoulder_lift.stl' scale='1.000000 1.000000 1.000000'/>
        </geometry>
        <surface>
          <friction>
            <ode mu='0.000000' mu2='0.000000' fdir1='0.000000 0.000000 0.000000' slip1='0.000000' slip2='0.000000'/>
          </friction>
          <bounce restitution_coefficient='0.000000' threshold='100000.000000'/>
          <contact>
            <ode soft_cfm='0.000000' soft_erp='0.200000' kp='1000000000000.000000' kd='10000.000000' max_vel='100.000000' min_depth='0.000000'/>
          </contact>
        </surface>
      </collision>
      <visual name='l_shoulder_lift_link_geom_visual'>
        <origin>0.000000 0.000000 0.000000 0.000000 -0.000000 0.000000</origin>
        <geometry>
          <mesh filename='pr2/shoulder_v0/shoulder_lift.dae' scale='1.000000 1.000000 1.000000'/>
        </geometry>
      </visual>
    </link>
    <link name='l_upper_arm_roll_link' gravity='0' self_collide='0' kinematic='0'>
      <origin>0.050000 0.188000 0.790675 0.000000 -0.000000 0.000000</origin>
      <inertial mass='6.117690'>
        <origin>0.210551 0.016309 -0.000561 0.000000 -0.000000 0.000000</origin>
        <inertia ixx='0.025306' ixy='-0.003393' ixz='0.000608' iyy='0.084737' iyz='-0.000200' izz='0.086016'/>
      </inertial>
      <collision name='l_upper_arm_roll_link_geom' laser_retro='0.000000'>
        <origin>0.000000 0.000000 0.000000 0.000000 -0.000000 0.000000</origin>
        <geometry>
          <mesh filename='pr2/shoulder_v0/upper_arm_roll_L.stl' scale='1.000000 1.000000 1.000000'/>
        </geometry>
        <surface>
          <friction>
            <ode mu='0.000000' mu2='0.000000' fdir1='0.000000 0.000000 0.000000' slip1='0.000000' slip2='0.000000'/>
          </friction>
          <bounce restitution_coefficient='0.000000' threshold='100000.000000'/>
          <contact>
            <ode soft_cfm='0.000000' soft_erp='0.200000' kp='1000000000000.000000' kd='10000.000000' max_vel='100.000000' min_depth='0.000000'/>
          </contact>
        </surface>
      </collision>
      <visual name='l_upper_arm_roll_link_geom_visual'>
        <origin>0.000000 0.000000 0.000000 0.000000 -0.000000 0.000000</origin>
        <geometry>
          <mesh filename='pr2/shoulder_v0/upper_arm_roll.stl' scale='1.000000 1.000000 1.000000'/>
        </geometry>
      </visual>
      <collision name='l_upper_arm_roll_link_geom_l_upper_arm_link' laser_retro='0.000000'>
        <origin>0.000000 0.000000 0.000000 0.000000 -0.000000 0.000000</origin>
        <geometry>
          <mesh filename='pr2/upper_arm_v0/upper_arm.stl' scale='1.000000 1.000000 1.000000'/>
        </geometry>
        <surface>
          <friction>
            <ode mu='0.000000' mu2='0.000000' fdir1='0.000000 0.000000 0.000000' slip1='0.000000' slip2='0.000000'/>
          </friction>
          <bounce restitution_coefficient='0.000000' threshold='100000.000000'/>
          <contact>
            <ode soft_cfm='0.000000' soft_erp='0.200000' kp='1000000000000.000000' kd='10000.000000' max_vel='100.000000' min_depth='0.000000'/>
          </contact>
        </surface>
      </collision>
      <visual name='l_upper_arm_roll_link_geom_l_upper_arm_link_visual'>
        <origin>0.000000 0.000000 0.000000 0.000000 -0.000000 0.000000</origin>
        <geometry>
          <mesh filename='pr2/upper_arm_v0/upper_arm.dae' scale='1.000000 1.000000 1.000000'/>
        </geometry>
      </visual>
    </link>
    <link name='l_elbow_flex_link' gravity='0' self_collide='0' kinematic='0'>
      <origin>0.450000 0.188000 0.790675 0.000000 -0.000000 0.000000</origin>
      <inertial mass='1.903270'>
        <origin>0.010140 0.000320 -0.012110 0.000000 -0.000000 0.000000</origin>
        <inertia ixx='0.003465' ixy='0.000041' ixz='0.000432' iyy='0.004416' iyz='-0.000040' izz='0.003592'/>
      </inertial>
      <collision name='l_elbow_flex_link_geom' laser_retro='0.000000'>
        <origin>0.000000 0.000000 0.000000 0.000000 -0.000000 0.000000</origin>
        <geometry>
          <mesh filename='pr2/upper_arm_v0/elbow_flex.stl' scale='1.000000 1.000000 1.000000'/>
        </geometry>
        <surface>
          <friction>
            <ode mu='0.000000' mu2='0.000000' fdir1='0.000000 0.000000 0.000000' slip1='0.000000' slip2='0.000000'/>
          </friction>
          <bounce restitution_coefficient='0.000000' threshold='100000.000000'/>
          <contact>
            <ode soft_cfm='0.000000' soft_erp='0.200000' kp='1000000000000.000000' kd='10000.000000' max_vel='100.000000' min_depth='0.000000'/>
          </contact>
        </surface>
      </collision>
      <visual name='l_elbow_flex_link_geom_visual'>
        <origin>0.000000 0.000000 0.000000 0.000000 -0.000000 0.000000</origin>
        <geometry>
          <mesh filename='pr2/upper_arm_v0/elbow_flex.dae' scale='1.000000 1.000000 1.000000'/>
        </geometry>
      </visual>
    </link>
    <link name='l_forearm_roll_link' gravity='0' self_collide='0' kinematic='0'>
      <origin>0.450000 0.188000 0.790675 0.000000 -0.000000 0.000000</origin>
      <inertial mass='2.689680'>
        <origin>0.180727 -0.000163 -0.008583 0.000000 -0.000000 0.000000</origin>
        <inertia ixx='0.014668' ixy='0.000052' ixz='0.000656' iyy='0.026279' iyz='-0.000013' izz='0.027775'/>
      </inertial>
      <collision name='l_forearm_roll_link_geom' laser_retro='0.000000'>
        <origin>0.000000 0.000000 0.000000 0.000000 -0.000000 0.000000</origin>
        <geometry>
          <mesh filename='pr2/upper_arm_v0/forearm_roll_L.stl' scale='1.000000 1.000000 1.000000'/>
        </geometry>
        <surface>
          <friction>
            <ode mu='0.000000' mu2='0.000000' fdir1='0.000000 0.000000 0.000000' slip1='0.000000' slip2='0.000000'/>
          </friction>
          <bounce restitution_coefficient='0.000000' threshold='100000.000000'/>
          <contact>
            <ode soft_cfm='0.000000' soft_erp='0.200000' kp='1000000000000.000000' kd='10000.000000' max_vel='100.000000' min_depth='0.000000'/>
          </contact>
        </surface>
      </collision>
      <visual name='l_forearm_roll_link_geom_visual'>
        <origin>0.000000 0.000000 0.000000 0.000000 -0.000000 0.000000</origin>
        <geometry>
          <mesh filename='pr2/upper_arm_v0/forearm_roll.stl' scale='1.000000 1.000000 1.000000'/>
        </geometry>
      </visual>
      <collision name='l_forearm_roll_link_geom_l_forearm_link' laser_retro='0.000000'>
        <origin>0.000000 0.000000 0.000000 0.000000 -0.000000 0.000000</origin>
        <geometry>
          <mesh filename='pr2/forearm_v0/forearm.stl' scale='1.000000 1.000000 1.000000'/>
        </geometry>
        <surface>
          <friction>
            <ode mu='0.000000' mu2='0.000000' fdir1='0.000000 0.000000 0.000000' slip1='0.000000' slip2='0.000000'/>
          </friction>
          <bounce restitution_coefficient='0.000000' threshold='100000.000000'/>
          <contact>
            <ode soft_cfm='0.000000' soft_erp='0.200000' kp='1000000000000.000000' kd='10000.000000' max_vel='100.000000' min_depth='0.000000'/>
          </contact>
        </surface>
      </collision>
      <visual name='l_forearm_roll_link_geom_l_forearm_link_visual'>
        <origin>0.000000 0.000000 0.000000 0.000000 -0.000000 0.000000</origin>
        <geometry>
          <mesh filename='pr2/forearm_v0/forearm.dae' scale='1.000000 1.000000 1.000000'/>
        </geometry>
      </visual>
      <sensor name='l_forearm_cam_sensor' type='camera' always_on='0' update_rate='25.000000' visualize='0'>
        <origin>0.135000 0.000000 0.044000 -1.570800 -0.562869 0.000000</origin>
        <camera>
          <horizontal_fov angle='1.570796'/>
          <image width='640' height='480' format='R8G8B8'/>
          <clip near='0.100000' far='100.000000'/>
        </camera>
      </sensor>
    </link>
    <link name='l_wrist_flex_link' gravity='0' self_collide='0' kinematic='0'>
      <origin>0.771000 0.188000 0.790675 0.000000 -0.000000 0.000000</origin>
      <inertial mass='0.614020'>
        <origin>-0.001570 0.000000 -0.000750 0.000000 -0.000000 0.000000</origin>
        <inertia ixx='0.000652' ixy='0.000000' ixz='0.000003' iyy='0.000198' iyz='-0.000000' izz='0.000645'/>
      </inertial>
      <collision name='l_wrist_flex_link_geom' laser_retro='0.000000'>
        <origin>0.000000 0.000000 0.000000 0.000000 -0.000000 0.000000</origin>
        <geometry>
          <mesh filename='pr2/forearm_v0/wrist_flex.stl' scale='1.000000 1.000000 1.000000'/>
        </geometry>
        <surface>
          <friction>
            <ode mu='0.000000' mu2='0.000000' fdir1='0.000000 0.000000 0.000000' slip1='0.000000' slip2='0.000000'/>
          </friction>
          <bounce restitution_coefficient='0.000000' threshold='100000.000000'/>
          <contact>
            <ode soft_cfm='0.000000' soft_erp='0.200000' kp='1000000000000.000000' kd='10000.000000' max_vel='100.000000' min_depth='0.000000'/>
          </contact>
        </surface>
      </collision>
      <visual name='l_wrist_flex_link_geom_visual'>
        <origin>0.000000 0.000000 0.000000 0.000000 -0.000000 0.000000</origin>
        <geometry>
          <mesh filename='pr2/forearm_v0/wrist_flex.dae' scale='1.000000 1.000000 1.000000'/>
        </geometry>
      </visual>
    </link>
    <link name='l_wrist_roll_link' gravity='0' self_collide='0' kinematic='0'>
      <origin>0.771000 0.188000 0.790675 0.000000 -0.000000 0.000000</origin>
      <inertial mass='0.681070'>
        <origin>0.056408 0.000451 -0.001014 0.000000 -0.000000 0.000000</origin>
        <inertia ixx='0.011352' ixy='-0.000016' ixz='-0.000001' iyy='0.011677' iyz='-0.000001' izz='0.011866'/>
      </inertial>
      <collision name='l_wrist_roll_link_geom' laser_retro='0.000000'>
        <origin>0.000000 0.000000 0.000000 0.000000 -0.000000 0.000000</origin>
        <geometry>
          <mesh filename='pr2/forearm_v0/wrist_roll_L.stl' scale='1.000000 1.000000 1.000000'/>
        </geometry>
        <surface>
          <friction>
            <ode mu='0.000000' mu2='0.000000' fdir1='0.000000 0.000000 0.000000' slip1='0.000000' slip2='0.000000'/>
          </friction>
          <bounce restitution_coefficient='0.000000' threshold='100000.000000'/>
          <contact>
            <ode soft_cfm='0.000000' soft_erp='0.200000' kp='1000000000000.000000' kd='10000.000000' max_vel='100.000000' min_depth='0.000000'/>
          </contact>
        </surface>
      </collision>
      <visual name='l_wrist_roll_link_geom_visual'>
        <origin>0.000000 0.000000 0.000000 0.000000 -0.000000 0.000000</origin>
        <geometry>
          <mesh filename='pr2/forearm_v0/wrist_roll.stl' scale='1.000000 1.000000 1.000000'/>
        </geometry>
      </visual>
      <collision name='l_wrist_roll_link_geom_l_gripper_motor_accelerometer_link' laser_retro='0.000000'>
        <origin>0.000000 0.000000 0.000000 0.000000 -0.000000 0.000000</origin>
        <geometry>
          <box size='0.001000 0.001000 0.001000'/>
        </geometry>
        <surface>
          <friction>
            <ode mu='0.000000' mu2='0.000000' fdir1='0.000000 0.000000 0.000000' slip1='0.000000' slip2='0.000000'/>
          </friction>
          <bounce restitution_coefficient='0.000000' threshold='100000.000000'/>
          <contact>
            <ode soft_cfm='0.000000' soft_erp='0.200000' kp='1000000000000.000000' kd='10000.000000' max_vel='100.000000' min_depth='0.000000'/>
          </contact>
        </surface>
      </collision>
      <visual name='l_wrist_roll_link_geom_l_gripper_motor_accelerometer_link_visual'>
        <origin>0.000000 0.000000 0.000000 0.000000 -0.000000 0.000000</origin>
        <geometry>
          <box size='0.001000 0.001000 0.001000'/>
        </geometry>
      </visual>
      <collision name='l_wrist_roll_link_geom_l_gripper_palm_link' laser_retro='0.000000'>
        <origin>0.000000 0.000000 0.000000 0.000000 -0.000000 0.000000</origin>
        <geometry>
          <mesh filename='pr2/gripper_v0/gripper_palm.stl' scale='1.000000 1.000000 1.000000'/>
        </geometry>
        <surface>
          <friction>
            <ode mu='0.000000' mu2='0.000000' fdir1='0.000000 0.000000 0.000000' slip1='0.000000' slip2='0.000000'/>
          </friction>
          <bounce restitution_coefficient='0.000000' threshold='100000.000000'/>
          <contact>
            <ode soft_cfm='0.000000' soft_erp='0.200000' kp='1000000000000.000000' kd='10000.000000' max_vel='100.000000' min_depth='0.000000'/>
          </contact>
        </surface>
      </collision>
      <visual name='l_wrist_roll_link_geom_l_gripper_palm_link_visual'>
        <origin>0.000000 0.000000 0.000000 0.000000 -0.000000 0.000000</origin>
        <geometry>
          <mesh filename='pr2/gripper_v0/gripper_palm.dae' scale='1.000000 1.000000 1.000000'/>
        </geometry>
      </visual>
    </link>
    <link name='l_gripper_l_finger_link' gravity='0' self_collide='0' kinematic='0'>
      <origin>0.847910 0.198000 0.790675 0.000000 -0.000000 0.000000</origin>
      <inertial mass='0.171260'>
        <origin>0.035980 0.017300 -0.001640 0.000000 -0.000000 0.000000</origin>
        <inertia ixx='0.000078' ixy='0.000001' ixz='-0.000010' iyy='0.000197' iyz='-0.000003' izz='0.000181'/>
      </inertial>
      <collision name='l_gripper_l_finger_link_geom' laser_retro='0.000000'>
        <origin>0.000000 0.000000 0.000000 0.000000 -0.000000 0.000000</origin>
        <geometry>
          <mesh filename='pr2/gripper_v0/l_finger.stl' scale='1.000000 1.000000 1.000000'/>
        </geometry>
        <surface>
          <friction>
            <ode mu='500.000000' mu2='500.000000' fdir1='0.000000 0.000000 0.000000' slip1='0.000000' slip2='0.000000'/>
          </friction>
          <bounce restitution_coefficient='0.000000' threshold='100000.000000'/>
          <contact>
            <ode soft_cfm='0.000000' soft_erp='0.200000' kp='1000000.000000' kd='1.000000' max_vel='100.000000' min_depth='0.000000'/>
          </contact>
        </surface>
      </collision>
      <visual name='l_gripper_l_finger_link_geom_visual'>
        <origin>0.000000 0.000000 0.000000 0.000000 -0.000000 0.000000</origin>
        <geometry>
          <mesh filename='pr2/gripper_v0/l_finger.dae' scale='1.000000 1.000000 1.000000'/>
        </geometry>
      </visual>
    </link>
    <link name='l_gripper_l_finger_tip_link' gravity='0' self_collide='0' kinematic='0'>
      <origin>0.939280 0.202950 0.790675 0.000000 -0.000000 0.000000</origin>
      <inertial mass='0.044190'>
        <origin>0.004230 0.002840 0.000000 0.000000 -0.000000 0.000000</origin>
        <inertia ixx='0.000008' ixy='0.000006' ixz='0.000000' iyy='0.000010' iyz='0.000000' izz='0.000015'/>
      </inertial>
      <collision name='l_gripper_l_finger_tip_link_geom' laser_retro='0.000000'>
        <origin>0.000000 0.000000 0.000000 0.000000 -0.000000 0.000000</origin>
        <geometry>
          <mesh filename='pr2/gripper_v0/l_finger_tip.stl' scale='1.000000 1.000000 1.000000'/>
        </geometry>
        <surface>
          <friction>
            <ode mu='500.000000' mu2='500.000000' fdir1='0.000000 0.000000 0.000000' slip1='0.000000' slip2='0.000000'/>
          </friction>
          <bounce restitution_coefficient='0.000000' threshold='100000.000000'/>
          <contact>
            <ode soft_cfm='0.000000' soft_erp='0.200000' kp='10000000.000000' kd='1.000000' max_vel='100.000000' min_depth='0.000000'/>
          </contact>
        </surface>
      </collision>
      <visual name='l_gripper_l_finger_tip_link_geom_visual'>
        <origin>0.000000 0.000000 0.000000 0.000000 -0.000000 0.000000</origin>
        <geometry>
          <mesh filename='pr2/gripper_v0/l_finger_tip.dae' scale='1.000000 1.000000 1.000000'/>
        </geometry>
      </visual>
      <sensor name='l_gripper_l_finger_tip_contact_sensor' type='contact' always_on='0' update_rate='100.000000' visualize='0'>
        <origin>0.000000 0.000000 0.000000 0.000000 -0.000000 0.000000</origin>
        <contact>
          <collision name='l_gripper_l_finger_tip_link_geom'/>
        </contact>
      </sensor>
    </link>
    <link name='l_gripper_motor_slider_link' gravity='0' self_collide='0' kinematic='0'>
      <origin>0.939280 0.188000 0.790675 0.000000 -0.000000 0.000000</origin>
      <inertial mass='0.010000'>
        <origin>0.000000 0.000000 0.000000 0.000000 -0.000000 0.000000</origin>
        <inertia ixx='0.001000' ixy='0.000000' ixz='0.000000' iyy='0.001000' iyz='0.000000' izz='0.001000'/>
      </inertial>
    </link>
    <link name='l_gripper_motor_screw_link' gravity='0' self_collide='0' kinematic='0'>
      <origin>0.939280 0.188000 0.790675 0.000000 -0.000000 0.000000</origin>
      <inertial mass='0.010000'>
        <origin>0.000000 0.000000 0.000000 0.000000 -0.000000 0.000000</origin>
        <inertia ixx='0.000100' ixy='0.000000' ixz='0.000000' iyy='0.000100' iyz='0.000000' izz='0.000100'/>
      </inertial>
    </link>
    <link name='l_gripper_r_finger_link' gravity='0' self_collide='0' kinematic='0'>
      <origin>0.847910 0.178000 0.790675 0.000000 -0.000000 0.000000</origin>
      <inertial mass='0.173890'>
        <origin>0.035760 -0.017360 -0.000950 0.000000 -0.000000 0.000000</origin>
        <inertia ixx='0.000077' ixy='-0.000002' ixz='-0.000008' iyy='0.000198' iyz='0.000002' izz='0.000181'/>
      </inertial>
      <collision name='l_gripper_r_finger_link_geom' laser_retro='0.000000'>
        <origin>0.000000 0.000000 0.000000 -3.141590 -0.000000 0.000000</origin>
        <geometry>
          <mesh filename='pr2/gripper_v0/l_finger.stl' scale='1.000000 1.000000 1.000000'/>
        </geometry>
        <surface>
          <friction>
            <ode mu='500.000000' mu2='500.000000' fdir1='0.000000 0.000000 0.000000' slip1='0.000000' slip2='0.000000'/>
          </friction>
          <bounce restitution_coefficient='0.000000' threshold='100000.000000'/>
          <contact>
            <ode soft_cfm='0.000000' soft_erp='0.200000' kp='1000000.000000' kd='1.000000' max_vel='100.000000' min_depth='0.000000'/>
          </contact>
        </surface>
      </collision>
      <visual name='l_gripper_r_finger_link_geom_visual'>
        <origin>0.000000 0.000000 0.000000 -3.141590 0.000000 0.000000</origin>
        <geometry>
          <mesh filename='pr2/gripper_v0/l_finger.dae' scale='1.000000 1.000000 1.000000'/>
        </geometry>
      </visual>
    </link>
    <link name='l_gripper_r_finger_tip_link' gravity='0' self_collide='0' kinematic='0'>
      <origin>0.939280 0.173050 0.790675 0.000000 -0.000000 0.000000</origin>
      <inertial mass='0.044190'>
        <origin>0.004230 -0.002840 0.000000 0.000000 -0.000000 0.000000</origin>
        <inertia ixx='0.000008' ixy='-0.000006' ixz='0.000000' iyy='0.000010' iyz='0.000000' izz='0.000015'/>
      </inertial>
      <collision name='l_gripper_r_finger_tip_link_geom' laser_retro='0.000000'>
        <origin>0.000000 0.000000 0.000000 -3.141590 -0.000000 0.000000</origin>
        <geometry>
          <mesh filename='pr2/gripper_v0/l_finger_tip.stl' scale='1.000000 1.000000 1.000000'/>
        </geometry>
        <surface>
          <friction>
            <ode mu='500.000000' mu2='500.000000' fdir1='0.000000 0.000000 0.000000' slip1='0.000000' slip2='0.000000'/>
          </friction>
          <bounce restitution_coefficient='0.000000' threshold='100000.000000'/>
          <contact>
            <ode soft_cfm='0.000000' soft_erp='0.200000' kp='10000000.000000' kd='1.000000' max_vel='100.000000' min_depth='0.000000'/>
          </contact>
        </surface>
      </collision>
      <visual name='l_gripper_r_finger_tip_link_geom_visual'>
        <origin>0.000000 0.000000 0.000000 -3.141590 0.000000 0.000000</origin>
        <geometry>
          <mesh filename='pr2/gripper_v0/l_finger_tip.dae' scale='1.000000 1.000000 1.000000'/>
        </geometry>
      </visual>
      <sensor name='l_gripper_r_finger_tip_contact_sensor' type='contact' always_on='0' update_rate='100.000000' visualize='0'>
        <origin>0.000000 0.000000 0.000000 0.000000 -0.000000 0.000000</origin>
        <contact>
          <collision name='l_gripper_r_finger_tip_link_geom'/>
        </contact>
      </sensor>
    </link>
    <link name='laser_tilt_mount_link' gravity='1' self_collide='0' kinematic='0'>
      <origin>0.048930 0.000000 1.017680 0.000000 -0.000000 0.000000</origin>
      <inertial mass='0.592000'>
        <origin>-0.001134 0.001667 -0.007067 0.000000 -0.000000 0.000000</origin>
        <inertia ixx='0.001296' ixy='0.000023' ixz='0.000037' iyy='0.001086' iyz='0.000035' izz='0.000895'/>
      </inertial>
      <collision name='laser_tilt_mount_link_geom' laser_retro='0.000000'>
        <origin>0.000000 0.000000 0.000000 0.000000 -0.000000 0.000000</origin>
        <geometry>
          <mesh filename='pr2/tilting_laser_v0/tilting_hokuyo_L.stl' scale='1.000000 1.000000 1.000000'/>
        </geometry>
        <surface>
          <friction>
            <ode mu='0.000000' mu2='0.000000' fdir1='0.000000 0.000000 0.000000' slip1='0.000000' slip2='0.000000'/>
          </friction>
          <bounce restitution_coefficient='0.000000' threshold='100000.000000'/>
          <contact>
            <ode soft_cfm='0.000000' soft_erp='0.200000' kp='1000000000000.000000' kd='10000.000000' max_vel='100.000000' min_depth='0.000000'/>
          </contact>
        </surface>
      </collision>
      <visual name='laser_tilt_mount_link_geom_visual'>
        <origin>0.000000 0.000000 0.000000 0.000000 -0.000000 0.000000</origin>
        <geometry>
          <mesh filename='pr2/tilting_laser_v0/tilting_hokuyo.dae' scale='1.000000 1.000000 1.000000'/>
        </geometry>
      </visual>
      <sensor name='laser_tilt' type='ray' always_on='0' update_rate='40.000000' visualize='0'>
        <origin>0.000000 0.000000 0.030000 0.000000 -0.000000 0.000000</origin>
        <ray>
          <scan>
            <horizontal samples='640' resolution='1.000000' min_angle='-1.396263' max_angle='1.396263'/>
          </scan>
          <range min='0.080000' max='10.000000' resolution='0.010000'/>
        </ray>
      </sensor>
    </link>
    <link name='r_shoulder_pan_link' gravity='0' self_collide='0' kinematic='0'>
      <origin>-0.050000 -0.188000 0.790675 0.000000 -0.000000 0.000000</origin>
      <inertial mass='25.799300'>
        <origin>-0.001201 0.024513 -0.098231 0.000000 -0.000000 0.000000</origin>
        <inertia ixx='0.866179' ixy='-0.060865' ixz='-0.121181' iyy='0.874217' iyz='-0.058866' izz='0.273538'/>
      </inertial>
      <collision name='r_shoulder_pan_link_geom' laser_retro='0.000000'>
        <origin>0.000000 0.000000 0.000000 0.000000 -0.000000 0.000000</origin>
        <geometry>
          <mesh filename='pr2/shoulder_v0/shoulder_pan.stl' scale='1.000000 1.000000 1.000000'/>
        </geometry>
        <surface>
          <friction>
            <ode mu='0.000000' mu2='0.000000' fdir1='0.000000 0.000000 0.000000' slip1='0.000000' slip2='0.000000'/>
          </friction>
          <bounce restitution_coefficient='0.000000' threshold='100000.000000'/>
          <contact>
            <ode soft_cfm='0.000000' soft_erp='0.200000' kp='1000000000000.000000' kd='10000.000000' max_vel='100.000000' min_depth='0.000000'/>
          </contact>
        </surface>
      </collision>
      <visual name='r_shoulder_pan_link_geom_visual'>
        <origin>0.000000 0.000000 0.000000 0.000000 -0.000000 0.000000</origin>
        <geometry>
          <mesh filename='pr2/shoulder_v0/shoulder_pan.dae' scale='1.000000 1.000000 1.000000'/>
        </geometry>
      </visual>
    </link>
    <link name='r_shoulder_lift_link' gravity='0' self_collide='0' kinematic='0'>
      <origin>0.050000 -0.188000 0.790675 0.000000 -0.000000 0.000000</origin>
      <inertial mass='2.749880'>
        <origin>0.021950 -0.026640 -0.031270 0.000000 -0.000000 0.000000</origin>
        <inertia ixx='0.021056' ixy='0.004967' ixz='-0.001948' iyy='0.021272' iyz='0.001104' izz='0.019758'/>
      </inertial>
      <collision name='r_shoulder_lift_link_geom' laser_retro='0.000000'>
        <origin>0.000000 0.000000 0.000000 0.000000 -0.000000 0.000000</origin>
        <geometry>
          <mesh filename='pr2/shoulder_v0/shoulder_lift.stl' scale='1.000000 1.000000 1.000000'/>
        </geometry>
        <surface>
          <friction>
            <ode mu='0.000000' mu2='0.000000' fdir1='0.000000 0.000000 0.000000' slip1='0.000000' slip2='0.000000'/>
          </friction>
          <bounce restitution_coefficient='0.000000' threshold='100000.000000'/>
          <contact>
            <ode soft_cfm='0.000000' soft_erp='0.200000' kp='1000000000000.000000' kd='10000.000000' max_vel='100.000000' min_depth='0.000000'/>
          </contact>
        </surface>
      </collision>
      <visual name='r_shoulder_lift_link_geom_visual'>
        <origin>0.000000 0.000000 0.000000 0.000000 -0.000000 0.000000</origin>
        <geometry>
          <mesh filename='pr2/shoulder_v0/shoulder_lift.dae' scale='1.000000 1.000000 1.000000'/>
        </geometry>
      </visual>
    </link>
    <link name='r_upper_arm_roll_link' gravity='0' self_collide='0' kinematic='0'>
      <origin>0.050000 -0.188000 0.790675 0.000000 -0.000000 0.000000</origin>
      <inertial mass='6.117690'>
        <origin>0.210482 -0.015945 -0.000197 0.000000 -0.000000 0.000000</origin>
        <inertia ixx='0.025378' ixy='0.003757' ixz='-0.000709' iyy='0.084737' iyz='-0.000179' izz='0.086088'/>
      </inertial>
      <collision name='r_upper_arm_roll_link_geom' laser_retro='0.000000'>
        <origin>0.000000 0.000000 0.000000 0.000000 -0.000000 0.000000</origin>
        <geometry>
          <mesh filename='pr2/shoulder_v0/upper_arm_roll_L.stl' scale='1.000000 1.000000 1.000000'/>
        </geometry>
        <surface>
          <friction>
            <ode mu='0.000000' mu2='0.000000' fdir1='0.000000 0.000000 0.000000' slip1='0.000000' slip2='0.000000'/>
          </friction>
          <bounce restitution_coefficient='0.000000' threshold='100000.000000'/>
          <contact>
            <ode soft_cfm='0.000000' soft_erp='0.200000' kp='1000000000000.000000' kd='10000.000000' max_vel='100.000000' min_depth='0.000000'/>
          </contact>
        </surface>
      </collision>
      <visual name='r_upper_arm_roll_link_geom_visual'>
        <origin>0.000000 0.000000 0.000000 0.000000 -0.000000 0.000000</origin>
        <geometry>
          <mesh filename='pr2/shoulder_v0/upper_arm_roll.stl' scale='1.000000 1.000000 1.000000'/>
        </geometry>
      </visual>
      <collision name='r_upper_arm_roll_link_geom_r_upper_arm_link' laser_retro='0.000000'>
        <origin>0.000000 0.000000 0.000000 0.000000 -0.000000 0.000000</origin>
        <geometry>
          <mesh filename='pr2/upper_arm_v0/upper_arm.stl' scale='1.000000 1.000000 1.000000'/>
        </geometry>
        <surface>
          <friction>
            <ode mu='0.000000' mu2='0.000000' fdir1='0.000000 0.000000 0.000000' slip1='0.000000' slip2='0.000000'/>
          </friction>
          <bounce restitution_coefficient='0.000000' threshold='100000.000000'/>
          <contact>
            <ode soft_cfm='0.000000' soft_erp='0.200000' kp='1000000000000.000000' kd='10000.000000' max_vel='100.000000' min_depth='0.000000'/>
          </contact>
        </surface>
      </collision>
      <visual name='r_upper_arm_roll_link_geom_r_upper_arm_link_visual'>
        <origin>0.000000 0.000000 0.000000 0.000000 -0.000000 0.000000</origin>
        <geometry>
          <mesh filename='pr2/upper_arm_v0/upper_arm.dae' scale='1.000000 1.000000 1.000000'/>
        </geometry>
      </visual>
    </link>
    <link name='r_elbow_flex_link' gravity='0' self_collide='0' kinematic='0'>
      <origin>0.450000 -0.188000 0.790675 0.000000 -0.000000 0.000000</origin>
      <inertial mass='1.903270'>
        <origin>0.010140 0.000320 -0.012110 0.000000 -0.000000 0.000000</origin>
        <inertia ixx='0.003465' ixy='0.000041' ixz='0.000432' iyy='0.004416' iyz='-0.000040' izz='0.003592'/>
      </inertial>
      <collision name='r_elbow_flex_link_geom' laser_retro='0.000000'>
        <origin>0.000000 0.000000 0.000000 0.000000 -0.000000 0.000000</origin>
        <geometry>
          <mesh filename='pr2/upper_arm_v0/elbow_flex.stl' scale='1.000000 1.000000 1.000000'/>
        </geometry>
        <surface>
          <friction>
            <ode mu='0.000000' mu2='0.000000' fdir1='0.000000 0.000000 0.000000' slip1='0.000000' slip2='0.000000'/>
          </friction>
          <bounce restitution_coefficient='0.000000' threshold='100000.000000'/>
          <contact>
            <ode soft_cfm='0.000000' soft_erp='0.200000' kp='1000000000000.000000' kd='10000.000000' max_vel='100.000000' min_depth='0.000000'/>
          </contact>
        </surface>
      </collision>
      <visual name='r_elbow_flex_link_geom_visual'>
        <origin>0.000000 0.000000 0.000000 0.000000 -0.000000 0.000000</origin>
        <geometry>
          <mesh filename='pr2/upper_arm_v0/elbow_flex.dae' scale='1.000000 1.000000 1.000000'/>
        </geometry>
      </visual>
    </link>
    <link name='r_forearm_roll_link' gravity='0' self_collide='0' kinematic='0'>
      <origin>0.450000 -0.188000 0.790675 0.000000 -0.000000 0.000000</origin>
      <inertial mass='2.689680'>
        <origin>0.180727 -0.000163 -0.008583 0.000000 -0.000000 0.000000</origin>
        <inertia ixx='0.014668' ixy='0.000052' ixz='0.000656' iyy='0.026279' iyz='-0.000013' izz='0.027775'/>
      </inertial>
      <collision name='r_forearm_roll_link_geom' laser_retro='0.000000'>
        <origin>0.000000 0.000000 0.000000 0.000000 -0.000000 0.000000</origin>
        <geometry>
          <mesh filename='pr2/upper_arm_v0/forearm_roll_L.stl' scale='1.000000 1.000000 1.000000'/>
        </geometry>
        <surface>
          <friction>
            <ode mu='0.000000' mu2='0.000000' fdir1='0.000000 0.000000 0.000000' slip1='0.000000' slip2='0.000000'/>
          </friction>
          <bounce restitution_coefficient='0.000000' threshold='100000.000000'/>
          <contact>
            <ode soft_cfm='0.000000' soft_erp='0.200000' kp='1000000000000.000000' kd='10000.000000' max_vel='100.000000' min_depth='0.000000'/>
          </contact>
        </surface>
      </collision>
      <visual name='r_forearm_roll_link_geom_visual'>
        <origin>0.000000 0.000000 0.000000 0.000000 -0.000000 0.000000</origin>
        <geometry>
          <mesh filename='pr2/upper_arm_v0/forearm_roll.stl' scale='1.000000 1.000000 1.000000'/>
        </geometry>
      </visual>
      <collision name='r_forearm_roll_link_geom_r_forearm_link' laser_retro='0.000000'>
        <origin>0.000000 0.000000 0.000000 0.000000 -0.000000 0.000000</origin>
        <geometry>
          <mesh filename='pr2/forearm_v0/forearm.stl' scale='1.000000 1.000000 1.000000'/>
        </geometry>
        <surface>
          <friction>
            <ode mu='0.000000' mu2='0.000000' fdir1='0.000000 0.000000 0.000000' slip1='0.000000' slip2='0.000000'/>
          </friction>
          <bounce restitution_coefficient='0.000000' threshold='100000.000000'/>
          <contact>
            <ode soft_cfm='0.000000' soft_erp='0.200000' kp='1000000000000.000000' kd='10000.000000' max_vel='100.000000' min_depth='0.000000'/>
          </contact>
        </surface>
      </collision>
      <visual name='r_forearm_roll_link_geom_r_forearm_link_visual'>
        <origin>0.000000 0.000000 0.000000 0.000000 -0.000000 0.000000</origin>
        <geometry>
          <mesh filename='pr2/forearm_v0/forearm.dae' scale='1.000000 1.000000 1.000000'/>
        </geometry>
      </visual>
      <sensor name='r_forearm_cam_sensor' type='camera' always_on='0' update_rate='25.000000' visualize='0'>
        <origin>0.135000 0.000000 0.044000 1.570800 -0.562869 -0.000000</origin>
        <camera>
          <horizontal_fov angle='1.570796'/>
          <image width='640' height='480' format='R8G8B8'/>
          <clip near='0.100000' far='100.000000'/>
        </camera>
      </sensor>
    </link>
    <link name='r_wrist_flex_link' gravity='0' self_collide='0' kinematic='0'>
      <origin>0.771000 -0.188000 0.790675 0.000000 -0.000000 0.000000</origin>
      <inertial mass='0.614020'>
        <origin>-0.001570 0.000000 -0.000750 0.000000 -0.000000 0.000000</origin>
        <inertia ixx='0.000652' ixy='0.000000' ixz='0.000003' iyy='0.000198' iyz='-0.000000' izz='0.000645'/>
      </inertial>
      <collision name='r_wrist_flex_link_geom' laser_retro='0.000000'>
        <origin>0.000000 0.000000 0.000000 0.000000 -0.000000 0.000000</origin>
        <geometry>
          <mesh filename='pr2/forearm_v0/wrist_flex.stl' scale='1.000000 1.000000 1.000000'/>
        </geometry>
        <surface>
          <friction>
            <ode mu='0.000000' mu2='0.000000' fdir1='0.000000 0.000000 0.000000' slip1='0.000000' slip2='0.000000'/>
          </friction>
          <bounce restitution_coefficient='0.000000' threshold='100000.000000'/>
          <contact>
            <ode soft_cfm='0.000000' soft_erp='0.200000' kp='1000000000000.000000' kd='10000.000000' max_vel='100.000000' min_depth='0.000000'/>
          </contact>
        </surface>
      </collision>
      <visual name='r_wrist_flex_link_geom_visual'>
        <origin>0.000000 0.000000 0.000000 0.000000 -0.000000 0.000000</origin>
        <geometry>
          <mesh filename='pr2/forearm_v0/wrist_flex.dae' scale='1.000000 1.000000 1.000000'/>
        </geometry>
      </visual>
    </link>
    <link name='r_wrist_roll_link' gravity='0' self_collide='0' kinematic='0'>
      <origin>0.771000 -0.188000 0.790675 0.000000 -0.000000 0.000000</origin>
      <inertial mass='0.681070'>
        <origin>0.056408 0.000451 -0.001014 0.000000 -0.000000 0.000000</origin>
        <inertia ixx='0.011352' ixy='-0.000016' ixz='-0.000001' iyy='0.011677' iyz='-0.000001' izz='0.011866'/>
      </inertial>
      <collision name='r_wrist_roll_link_geom' laser_retro='0.000000'>
        <origin>0.000000 0.000000 0.000000 0.000000 -0.000000 0.000000</origin>
        <geometry>
          <mesh filename='pr2/forearm_v0/wrist_roll_L.stl' scale='1.000000 1.000000 1.000000'/>
        </geometry>
        <surface>
          <friction>
            <ode mu='0.000000' mu2='0.000000' fdir1='0.000000 0.000000 0.000000' slip1='0.000000' slip2='0.000000'/>
          </friction>
          <bounce restitution_coefficient='0.000000' threshold='100000.000000'/>
          <contact>
            <ode soft_cfm='0.000000' soft_erp='0.200000' kp='1000000000000.000000' kd='10000.000000' max_vel='100.000000' min_depth='0.000000'/>
          </contact>
        </surface>
      </collision>
      <visual name='r_wrist_roll_link_geom_visual'>
        <origin>0.000000 0.000000 0.000000 0.000000 -0.000000 0.000000</origin>
        <geometry>
          <mesh filename='pr2/forearm_v0/wrist_roll.stl' scale='1.000000 1.000000 1.000000'/>
        </geometry>
      </visual>
      <collision name='r_wrist_roll_link_geom_r_gripper_motor_accelerometer_link' laser_retro='0.000000'>
        <origin>0.000000 0.000000 0.000000 0.000000 -0.000000 0.000000</origin>
        <geometry>
          <box size='0.001000 0.001000 0.001000'/>
        </geometry>
        <surface>
          <friction>
            <ode mu='0.000000' mu2='0.000000' fdir1='0.000000 0.000000 0.000000' slip1='0.000000' slip2='0.000000'/>
          </friction>
          <bounce restitution_coefficient='0.000000' threshold='100000.000000'/>
          <contact>
            <ode soft_cfm='0.000000' soft_erp='0.200000' kp='1000000000000.000000' kd='10000.000000' max_vel='100.000000' min_depth='0.000000'/>
          </contact>
        </surface>
      </collision>
      <visual name='r_wrist_roll_link_geom_r_gripper_motor_accelerometer_link_visual'>
        <origin>0.000000 0.000000 0.000000 0.000000 -0.000000 0.000000</origin>
        <geometry>
          <box size='0.001000 0.001000 0.001000'/>
        </geometry>
      </visual>
      <collision name='r_wrist_roll_link_geom_r_gripper_palm_link' laser_retro='0.000000'>
        <origin>0.000000 0.000000 0.000000 0.000000 -0.000000 0.000000</origin>
        <geometry>
          <mesh filename='pr2/gripper_v0/gripper_palm.stl' scale='1.000000 1.000000 1.000000'/>
        </geometry>
        <surface>
          <friction>
            <ode mu='0.000000' mu2='0.000000' fdir1='0.000000 0.000000 0.000000' slip1='0.000000' slip2='0.000000'/>
          </friction>
          <bounce restitution_coefficient='0.000000' threshold='100000.000000'/>
          <contact>
            <ode soft_cfm='0.000000' soft_erp='0.200000' kp='1000000000000.000000' kd='10000.000000' max_vel='100.000000' min_depth='0.000000'/>
          </contact>
        </surface>
      </collision>
      <visual name='r_wrist_roll_link_geom_r_gripper_palm_link_visual'>
        <origin>0.000000 0.000000 0.000000 0.000000 -0.000000 0.000000</origin>
        <geometry>
          <mesh filename='pr2/gripper_v0/gripper_palm.dae' scale='1.000000 1.000000 1.000000'/>
        </geometry>
      </visual>
    </link>
    <link name='r_gripper_l_finger_link' gravity='0' self_collide='0' kinematic='0'>
      <origin>0.847910 -0.178000 0.790675 0.000000 -0.000000 0.000000</origin>
      <inertial mass='0.171260'>
        <origin>0.035980 0.017300 -0.001640 0.000000 -0.000000 0.000000</origin>
        <inertia ixx='0.000078' ixy='0.000001' ixz='-0.000010' iyy='0.000197' iyz='-0.000003' izz='0.000181'/>
      </inertial>
      <collision name='r_gripper_l_finger_link_geom' laser_retro='0.000000'>
        <origin>0.000000 0.000000 0.000000 0.000000 -0.000000 0.000000</origin>
        <geometry>
          <mesh filename='pr2/gripper_v0/l_finger.stl' scale='1.000000 1.000000 1.000000'/>
        </geometry>
        <surface>
          <friction>
            <ode mu='500.000000' mu2='500.000000' fdir1='0.000000 0.000000 0.000000' slip1='0.000000' slip2='0.000000'/>
          </friction>
          <bounce restitution_coefficient='0.000000' threshold='100000.000000'/>
          <contact>
            <ode soft_cfm='0.000000' soft_erp='0.200000' kp='1000000.000000' kd='1.000000' max_vel='100.000000' min_depth='0.000000'/>
          </contact>
        </surface>
      </collision>
      <visual name='r_gripper_l_finger_link_geom_visual'>
        <origin>0.000000 0.000000 0.000000 0.000000 -0.000000 0.000000</origin>
        <geometry>
          <mesh filename='pr2/gripper_v0/l_finger.dae' scale='1.000000 1.000000 1.000000'/>
        </geometry>
      </visual>
    </link>
    <link name='r_gripper_l_finger_tip_link' gravity='0' self_collide='0' kinematic='0'>
      <origin>0.939280 -0.173050 0.790675 0.000000 -0.000000 0.000000</origin>
      <inertial mass='0.044190'>
        <origin>0.004230 0.002840 0.000000 0.000000 -0.000000 0.000000</origin>
        <inertia ixx='0.000008' ixy='0.000006' ixz='0.000000' iyy='0.000010' iyz='0.000000' izz='0.000015'/>
      </inertial>
      <collision name='r_gripper_l_finger_tip_link_geom' laser_retro='0.000000'>
        <origin>0.000000 0.000000 0.000000 0.000000 -0.000000 0.000000</origin>
        <geometry>
          <mesh filename='pr2/gripper_v0/l_finger_tip.stl' scale='1.000000 1.000000 1.000000'/>
        </geometry>
        <surface>
          <friction>
            <ode mu='500.000000' mu2='500.000000' fdir1='0.000000 0.000000 0.000000' slip1='0.000000' slip2='0.000000'/>
          </friction>
          <bounce restitution_coefficient='0.000000' threshold='100000.000000'/>
          <contact>
            <ode soft_cfm='0.000000' soft_erp='0.200000' kp='10000000.000000' kd='1.000000' max_vel='100.000000' min_depth='0.000000'/>
          </contact>
        </surface>
      </collision>
      <visual name='r_gripper_l_finger_tip_link_geom_visual'>
        <origin>0.000000 0.000000 0.000000 0.000000 -0.000000 0.000000</origin>
        <geometry>
          <mesh filename='pr2/gripper_v0/l_finger_tip.dae' scale='1.000000 1.000000 1.000000'/>
        </geometry>
      </visual>
      <sensor name='r_gripper_l_finger_tip_contact_sensor' type='contact' always_on='0' update_rate='100.000000' visualize='0'>
        <origin>0.000000 0.000000 0.000000 0.000000 -0.000000 0.000000</origin>
        <contact>
          <collision name='r_gripper_l_finger_tip_link_geom'/>
        </contact>
      </sensor>
    </link>
    <link name='r_gripper_motor_slider_link' gravity='0' self_collide='0' kinematic='0'>
      <origin>0.939280 -0.188000 0.790675 0.000000 -0.000000 0.000000</origin>
      <inertial mass='0.010000'>
        <origin>0.000000 0.000000 0.000000 0.000000 -0.000000 0.000000</origin>
        <inertia ixx='0.001000' ixy='0.000000' ixz='0.000000' iyy='0.001000' iyz='0.000000' izz='0.001000'/>
      </inertial>
    </link>
    <link name='r_gripper_motor_screw_link' gravity='0' self_collide='0' kinematic='0'>
      <origin>0.939280 -0.188000 0.790675 0.000000 -0.000000 0.000000</origin>
      <inertial mass='0.010000'>
        <origin>0.000000 0.000000 0.000000 0.000000 -0.000000 0.000000</origin>
        <inertia ixx='0.000100' ixy='0.000000' ixz='0.000000' iyy='0.000100' iyz='0.000000' izz='0.000100'/>
      </inertial>
    </link>
    <link name='r_gripper_r_finger_link' gravity='0' self_collide='0' kinematic='0'>
      <origin>0.847910 -0.198000 0.790675 0.000000 -0.000000 0.000000</origin>
      <inertial mass='0.173890'>
        <origin>0.035760 -0.017360 -0.000950 0.000000 -0.000000 0.000000</origin>
        <inertia ixx='0.000077' ixy='-0.000002' ixz='-0.000008' iyy='0.000198' iyz='0.000002' izz='0.000181'/>
      </inertial>
      <collision name='r_gripper_r_finger_link_geom' laser_retro='0.000000'>
        <origin>0.000000 0.000000 0.000000 -3.141590 -0.000000 0.000000</origin>
        <geometry>
          <mesh filename='pr2/gripper_v0/l_finger.stl' scale='1.000000 1.000000 1.000000'/>
        </geometry>
        <surface>
          <friction>
            <ode mu='500.000000' mu2='500.000000' fdir1='0.000000 0.000000 0.000000' slip1='0.000000' slip2='0.000000'/>
          </friction>
          <bounce restitution_coefficient='0.000000' threshold='100000.000000'/>
          <contact>
            <ode soft_cfm='0.000000' soft_erp='0.200000' kp='1000000.000000' kd='1.000000' max_vel='100.000000' min_depth='0.000000'/>
          </contact>
        </surface>
      </collision>
      <visual name='r_gripper_r_finger_link_geom_visual'>
        <origin>0.000000 0.000000 0.000000 -3.141590 0.000000 0.000000</origin>
        <geometry>
          <mesh filename='pr2/gripper_v0/l_finger.dae' scale='1.000000 1.000000 1.000000'/>
        </geometry>
      </visual>
    </link>
    <link name='r_gripper_r_finger_tip_link' gravity='0' self_collide='0' kinematic='0'>
      <origin>0.939280 -0.202950 0.790675 0.000000 -0.000000 0.000000</origin>
      <inertial mass='0.044190'>
        <origin>0.004230 -0.002840 0.000000 0.000000 -0.000000 0.000000</origin>
        <inertia ixx='0.000008' ixy='-0.000006' ixz='0.000000' iyy='0.000010' iyz='0.000000' izz='0.000015'/>
      </inertial>
      <collision name='r_gripper_r_finger_tip_link_geom' laser_retro='0.000000'>
        <origin>0.000000 0.000000 0.000000 -3.141590 -0.000000 0.000000</origin>
        <geometry>
          <mesh filename='pr2/gripper_v0/l_finger_tip.stl' scale='1.000000 1.000000 1.000000'/>
        </geometry>
        <surface>
          <friction>
            <ode mu='500.000000' mu2='500.000000' fdir1='0.000000 0.000000 0.000000' slip1='0.000000' slip2='0.000000'/>
          </friction>
          <bounce restitution_coefficient='0.000000' threshold='100000.000000'/>
          <contact>
            <ode soft_cfm='0.000000' soft_erp='0.200000' kp='10000000.000000' kd='1.000000' max_vel='100.000000' min_depth='0.000000'/>
          </contact>
        </surface>
      </collision>
      <visual name='r_gripper_r_finger_tip_link_geom_visual'>
        <origin>0.000000 0.000000 0.000000 -3.141590 0.000000 0.000000</origin>
        <geometry>
          <mesh filename='pr2/gripper_v0/l_finger_tip.dae' scale='1.000000 1.000000 1.000000'/>
        </geometry>
      </visual>
      <sensor name='r_gripper_r_finger_tip_contact_sensor' type='contact' always_on='0' update_rate='100.000000' visualize='0'>
        <origin>0.000000 0.000000 0.000000 0.000000 -0.000000 0.000000</origin>
        <contact>
          <collision name='r_gripper_r_finger_tip_link_geom'/>
        </contact>
      </sensor>
    </link>
    <link name='torso_lift_motor_screw_link' gravity='1' self_collide='0' kinematic='0'>
      <origin>-0.150000 0.000000 0.751000 0.000000 -0.000000 0.000000</origin>
      <inertial mass='1.000000'>
        <origin>0.000000 0.000000 0.000000 0.000000 -0.000000 0.000000</origin>
        <inertia ixx='0.001000' ixy='0.000000' ixz='0.000000' iyy='0.001000' iyz='0.000000' izz='0.001000'/>
      </inertial>
    </link>
    <link name='r_gripper_l_parallel_link' gravity='0' self_collide='0' kinematic='0'>
      <origin>0.829910 -0.157000 0.790675 0.000000 -0.000000 0.000000</origin>
      <inertial mass='0.171260'>
        <origin>0.035980 0.017300 -0.001640 0.000000 -0.000000 0.000000</origin>
        <inertia ixx='0.000078' ixy='0.000001' ixz='-0.000010' iyy='0.000197' iyz='-0.000003' izz='0.000181'/>
      </inertial>
    </link>
    <link name='r_gripper_r_parallel_link' gravity='0' self_collide='0' kinematic='0'>
      <origin>0.829910 -0.219000 0.790675 0.000000 -0.000000 0.000000</origin>
      <inertial mass='0.173890'>
        <origin>0.035760 -0.017360 -0.000950 0.000000 -0.000000 0.000000</origin>
        <inertia ixx='0.000077' ixy='-0.000002' ixz='-0.000008' iyy='0.000198' iyz='0.000002' izz='0.000181'/>
      </inertial>
    </link>
    <link name='l_gripper_l_parallel_link' gravity='0' self_collide='0' kinematic='0'>
      <origin>0.829910 0.219000 0.790675 0.000000 -0.000000 0.000000</origin>
      <inertial mass='0.171260'>
        <origin>0.035980 0.017300 -0.001640 0.000000 -0.000000 0.000000</origin>
        <inertia ixx='0.000078' ixy='0.000001' ixz='-0.000010' iyy='0.000197' iyz='-0.000003' izz='0.000181'/>
      </inertial>
    </link>
    <link name='l_gripper_r_parallel_link' gravity='0' self_collide='0' kinematic='0'>
      <origin>0.829910 0.157000 0.790675 0.000000 -0.000000 0.000000</origin>
      <inertial mass='0.173890'>
        <origin>0.035760 -0.017360 -0.000950 0.000000 -0.000000 0.000000</origin>
        <inertia ixx='0.000077' ixy='-0.000002' ixz='-0.000008' iyy='0.000198' iyz='0.000002' izz='0.000181'/>
      </inertial>
    </link>
    <joint name='bl_caster_rotation_joint' type='revolute'>
      <origin>0.000000 0.000000 0.000000 0.000000 -0.000000 0.000000</origin>
      <parent link='base_footprint'/>
      <child link='bl_caster_rotation_link'/>
      <axis xyz='0.000000 0.000000 1.000000'>
        <dynamics damping='0.000000' friction='0.000000'/>
        <limit lower='-10000000000000000.000000' upper='10000000000000000.000000' effort='0.000000' velocity='0.000000'/>
      </axis>
    </joint>
    <joint name='bl_caster_l_wheel_joint' type='revolute'>
      <origin>0.000000 0.000000 0.000000 0.000000 -0.000000 0.000000</origin>
      <parent link='bl_caster_rotation_link'/>
      <child link='bl_caster_l_wheel_link'/>
      <axis xyz='0.000000 1.000000 0.000000'>
        <dynamics damping='0.000000' friction='0.000000'/>
        <limit lower='-10000000000000000.000000' upper='10000000000000000.000000' effort='0.000000' velocity='0.000000'/>
      </axis>
    </joint>
    <joint name='bl_caster_r_wheel_joint' type='revolute'>
      <origin>0.000000 0.000000 0.000000 0.000000 -0.000000 0.000000</origin>
      <parent link='bl_caster_rotation_link'/>
      <child link='bl_caster_r_wheel_link'/>
      <axis xyz='0.000000 1.000000 0.000000'>
        <dynamics damping='0.000000' friction='0.000000'/>
        <limit lower='-10000000000000000.000000' upper='10000000000000000.000000' effort='0.000000' velocity='0.000000'/>
      </axis>
    </joint>
    <joint name='br_caster_rotation_joint' type='revolute'>
      <origin>0.000000 0.000000 0.000000 0.000000 -0.000000 0.000000</origin>
      <parent link='base_footprint'/>
      <child link='br_caster_rotation_link'/>
      <axis xyz='0.000000 0.000000 1.000000'>
        <dynamics damping='0.000000' friction='0.000000'/>
        <limit lower='-10000000000000000.000000' upper='10000000000000000.000000' effort='0.000000' velocity='0.000000'/>
      </axis>
    </joint>
    <joint name='br_caster_l_wheel_joint' type='revolute'>
      <origin>0.000000 0.000000 0.000000 0.000000 -0.000000 0.000000</origin>
      <parent link='br_caster_rotation_link'/>
      <child link='br_caster_l_wheel_link'/>
      <axis xyz='0.000000 1.000000 0.000000'>
        <dynamics damping='0.000000' friction='0.000000'/>
        <limit lower='-10000000000000000.000000' upper='10000000000000000.000000' effort='0.000000' velocity='0.000000'/>
      </axis>
    </joint>
    <joint name='br_caster_r_wheel_joint' type='revolute'>
      <origin>0.000000 0.000000 0.000000 0.000000 -0.000000 0.000000</origin>
      <parent link='br_caster_rotation_link'/>
      <child link='br_caster_r_wheel_link'/>
      <axis xyz='0.000000 1.000000 0.000000'>
        <dynamics damping='0.000000' friction='0.000000'/>
        <limit lower='-10000000000000000.000000' upper='10000000000000000.000000' effort='0.000000' velocity='0.000000'/>
      </axis>
    </joint>
    <joint name='fl_caster_rotation_joint' type='revolute'>
      <origin>0.000000 0.000000 0.000000 0.000000 -0.000000 0.000000</origin>
      <parent link='base_footprint'/>
      <child link='fl_caster_rotation_link'/>
      <axis xyz='0.000000 0.000000 1.000000'>
        <dynamics damping='0.000000' friction='0.000000'/>
        <limit lower='-10000000000000000.000000' upper='10000000000000000.000000' effort='0.000000' velocity='0.000000'/>
      </axis>
    </joint>
    <joint name='fl_caster_l_wheel_joint' type='revolute'>
      <origin>0.000000 0.000000 0.000000 0.000000 -0.000000 0.000000</origin>
      <parent link='fl_caster_rotation_link'/>
      <child link='fl_caster_l_wheel_link'/>
      <axis xyz='0.000000 1.000000 0.000000'>
        <dynamics damping='0.000000' friction='0.000000'/>
        <limit lower='-10000000000000000.000000' upper='10000000000000000.000000' effort='0.000000' velocity='0.000000'/>
      </axis>
    </joint>
    <joint name='fl_caster_r_wheel_joint' type='revolute'>
      <origin>0.000000 0.000000 0.000000 0.000000 -0.000000 0.000000</origin>
      <parent link='fl_caster_rotation_link'/>
      <child link='fl_caster_r_wheel_link'/>
      <axis xyz='0.000000 1.000000 0.000000'>
        <dynamics damping='0.000000' friction='0.000000'/>
        <limit lower='-10000000000000000.000000' upper='10000000000000000.000000' effort='0.000000' velocity='0.000000'/>
      </axis>
    </joint>
    <joint name='fr_caster_rotation_joint' type='revolute'>
      <origin>0.000000 0.000000 0.000000 0.000000 -0.000000 0.000000</origin>
      <parent link='base_footprint'/>
      <child link='fr_caster_rotation_link'/>
      <axis xyz='0.000000 0.000000 1.000000'>
        <dynamics damping='0.000000' friction='0.000000'/>
        <limit lower='-10000000000000000.000000' upper='10000000000000000.000000' effort='0.000000' velocity='0.000000'/>
      </axis>
    </joint>
    <joint name='fr_caster_l_wheel_joint' type='revolute'>
      <origin>0.000000 0.000000 0.000000 0.000000 -0.000000 0.000000</origin>
      <parent link='fr_caster_rotation_link'/>
      <child link='fr_caster_l_wheel_link'/>
      <axis xyz='0.000000 1.000000 0.000000'>
        <dynamics damping='0.000000' friction='0.000000'/>
        <limit lower='-10000000000000000.000000' upper='10000000000000000.000000' effort='0.000000' velocity='0.000000'/>
      </axis>
    </joint>
    <joint name='fr_caster_r_wheel_joint' type='revolute'>
      <origin>0.000000 0.000000 0.000000 0.000000 -0.000000 0.000000</origin>
      <parent link='fr_caster_rotation_link'/>
      <child link='fr_caster_r_wheel_link'/>
      <axis xyz='0.000000 1.000000 0.000000'>
        <dynamics damping='0.000000' friction='0.000000'/>
        <limit lower='-10000000000000000.000000' upper='10000000000000000.000000' effort='0.000000' velocity='0.000000'/>
      </axis>
    </joint>
    <joint name='torso_lift_joint' type='prismatic'>
      <origin>0.000000 0.000000 0.000000 0.000000 -0.000000 0.000000</origin>
      <parent link='base_footprint'/>
      <child link='torso_lift_link'/>
      <axis xyz='0.000000 0.000000 1.000000'>
        <dynamics damping='20000.000000' friction='0.000000'/>
        <limit lower='0.000000' upper='0.330000' effort='0.000000' velocity='0.000000'/>
      </axis>
    </joint>
    <joint name='head_pan_joint' type='revolute'>
      <origin>0.000000 0.000000 0.000000 0.000000 -0.000000 0.000000</origin>
      <parent link='torso_lift_link'/>
      <child link='head_pan_link'/>
      <axis xyz='0.000000 0.000000 1.000000'>
        <dynamics damping='2.000000' friction='0.000000'/>
        <limit lower='-3.006993' upper='3.006993' effort='0.000000' velocity='0.000000'/>
      </axis>
    </joint>
    <joint name='head_tilt_joint' type='revolute'>
      <origin>0.000000 0.000000 0.000000 0.000000 -0.000000 0.000000</origin>
      <parent link='head_pan_link'/>
      <child link='head_tilt_link'/>
      <axis xyz='0.000000 1.000000 0.000000'>
        <dynamics damping='10.000000' friction='0.000000'/>
        <limit lower='-0.471237' upper='1.396260' effort='0.000000' velocity='0.000000'/>
      </axis>
    </joint>
    <joint name='l_shoulder_pan_joint' type='revolute'>
      <origin>0.000000 0.000000 0.000000 0.000000 -0.000000 0.000000</origin>
      <parent link='torso_lift_link'/>
      <child link='l_shoulder_pan_link'/>
      <axis xyz='0.000000 0.000000 1.000000'>
        <dynamics damping='10.000000' friction='0.000000'/>
        <limit lower='-0.714602' upper='2.285404' effort='0.000000' velocity='0.000000'/>
      </axis>
    </joint>
    <joint name='l_shoulder_lift_joint' type='revolute'>
      <origin>0.000000 0.000000 0.000000 0.000000 -0.000000 0.000000</origin>
      <parent link='l_shoulder_pan_link'/>
      <child link='l_shoulder_lift_link'/>
      <axis xyz='0.000000 1.000000 0.000000'>
        <dynamics damping='10.000000' friction='0.000000'/>
        <limit lower='-0.523601' upper='1.396300' effort='0.000000' velocity='0.000000'/>
      </axis>
    </joint>
    <joint name='l_upper_arm_roll_joint' type='revolute'>
      <origin>0.000000 0.000000 0.000000 0.000000 -0.000000 0.000000</origin>
      <parent link='l_shoulder_lift_link'/>
      <child link='l_upper_arm_roll_link'/>
      <axis xyz='1.000000 0.000000 0.000000'>
        <dynamics damping='0.100000' friction='0.000000'/>
        <limit lower='-0.800000' upper='3.900008' effort='0.000000' velocity='0.000000'/>
      </axis>
    </joint>
    <joint name='l_elbow_flex_joint' type='revolute'>
      <origin>0.000000 0.000000 0.000000 0.000000 -0.000000 0.000000</origin>
      <parent link='l_upper_arm_roll_link'/>
      <child link='l_elbow_flex_link'/>
      <axis xyz='0.000000 1.000000 0.000000'>
        <dynamics damping='1.000000' friction='0.000000'/>
        <limit lower='-2.321305' upper='0.000000' effort='0.000000' velocity='0.000000'/>
      </axis>
    </joint>
    <joint name='l_forearm_roll_joint' type='revolute'>
      <origin>0.000000 0.000000 0.000000 0.000000 -0.000000 0.000000</origin>
      <parent link='l_elbow_flex_link'/>
      <child link='l_forearm_roll_link'/>
      <axis xyz='1.000000 0.000000 0.000000'>
        <dynamics damping='0.100000' friction='0.000000'/>
        <limit lower='-10000000000000000.000000' upper='10000000000000000.000000' effort='0.000000' velocity='0.000000'/>
      </axis>
    </joint>
    <joint name='l_wrist_flex_joint' type='revolute'>
      <origin>0.000000 0.000000 0.000000 0.000000 -0.000000 0.000000</origin>
      <parent link='l_forearm_roll_link'/>
      <child link='l_wrist_flex_link'/>
      <axis xyz='0.000000 1.000000 0.000000'>
        <dynamics damping='0.100000' friction='0.000000'/>
        <limit lower='-2.180004' upper='0.000000' effort='0.000000' velocity='0.000000'/>
      </axis>
    </joint>
    <joint name='l_wrist_roll_joint' type='revolute'>
      <origin>0.000000 0.000000 0.000000 0.000000 -0.000000 0.000000</origin>
      <parent link='l_wrist_flex_link'/>
      <child link='l_wrist_roll_link'/>
      <axis xyz='1.000000 0.000000 0.000000'>
        <dynamics damping='0.100000' friction='0.000000'/>
        <limit lower='-10000000000000000.000000' upper='10000000000000000.000000' effort='0.000000' velocity='0.000000'/>
      </axis>
    </joint>
    <joint name='l_gripper_l_finger_joint' type='revolute'>
      <origin>0.000000 0.000000 0.000000 0.000000 -0.000000 0.000000</origin>
      <parent link='l_wrist_roll_link'/>
      <child link='l_gripper_l_finger_link'/>
      <axis xyz='0.000000 0.000000 1.000000'>
        <dynamics damping='0.020000' friction='0.000000'/>
        <limit lower='0.000000' upper='0.548000' effort='0.000000' velocity='0.000000'/>
      </axis>
    </joint>
    <joint name='l_gripper_l_finger_tip_joint' type='revolute'>
      <origin>0.000000 0.000000 0.000000 0.000000 -0.000000 0.000000</origin>
      <parent link='l_gripper_l_finger_link'/>
      <child link='l_gripper_l_finger_tip_link'/>
      <axis xyz='0.000000 0.000000 -1.000000'>
        <dynamics damping='0.001000' friction='0.000000'/>
        <limit lower='0.000000' upper='0.548000' effort='0.000000' velocity='0.000000'/>
      </axis>
    </joint>
    <joint name='l_gripper_motor_slider_joint' type='prismatic'>
      <origin>0.000000 0.000000 0.000000 0.000000 -0.000000 0.000000</origin>
      <parent link='l_wrist_roll_link'/>
      <child link='l_gripper_motor_slider_link'/>
      <axis xyz='1.000000 0.000000 0.000000'>
        <dynamics damping='0.000000' friction='0.000000'/>
        <limit lower='-0.100000' upper='0.100000' effort='0.000000' velocity='0.000000'/>
      </axis>
    </joint>
    <joint name='l_gripper_motor_screw_joint' type='revolute'>
      <origin>0.000000 0.000000 0.000000 0.000000 -0.000000 0.000000</origin>
      <parent link='l_gripper_motor_slider_link'/>
      <child link='l_gripper_motor_screw_link'/>
      <axis xyz='0.000000 1.000000 0.000000'>
        <dynamics damping='0.000100' friction='0.000000'/>
        <limit lower='-10000000000000000.000000' upper='10000000000000000.000000' effort='0.000000' velocity='0.000000'/>
      </axis>
    </joint>
    <joint name='l_gripper_r_finger_joint' type='revolute'>
      <origin>0.000000 0.000000 0.000000 0.000000 -0.000000 0.000000</origin>
      <parent link='l_wrist_roll_link'/>
      <child link='l_gripper_r_finger_link'/>
      <axis xyz='0.000000 0.000000 -1.000000'>
        <dynamics damping='0.020000' friction='0.000000'/>
        <limit lower='0.000000' upper='0.548000' effort='0.000000' velocity='0.000000'/>
      </axis>
    </joint>
    <joint name='l_gripper_r_finger_tip_joint' type='revolute'>
      <origin>0.000000 0.000000 0.000000 0.000000 -0.000000 0.000000</origin>
      <parent link='l_gripper_r_finger_link'/>
      <child link='l_gripper_r_finger_tip_link'/>
      <axis xyz='0.000000 0.000000 1.000000'>
        <dynamics damping='0.001000' friction='0.000000'/>
        <limit lower='0.000000' upper='0.548000' effort='0.000000' velocity='0.000000'/>
      </axis>
    </joint>
    <joint name='laser_tilt_mount_joint' type='revolute'>
      <origin>0.000000 0.000000 0.000000 0.000000 -0.000000 0.000000</origin>
      <parent link='torso_lift_link'/>
      <child link='laser_tilt_mount_link'/>
      <axis xyz='0.000000 1.000000 0.000000'>
        <dynamics damping='0.008000' friction='0.000000'/>
        <limit lower='-0.785400' upper='1.483530' effort='0.000000' velocity='0.000000'/>
      </axis>
    </joint>
    <joint name='r_shoulder_pan_joint' type='revolute'>
      <origin>0.000000 0.000000 0.000000 0.000000 -0.000000 0.000000</origin>
      <parent link='torso_lift_link'/>
      <child link='r_shoulder_pan_link'/>
      <axis xyz='0.000000 0.000000 1.000000'>
        <dynamics damping='10.000000' friction='0.000000'/>
        <limit lower='-2.285404' upper='0.714602' effort='0.000000' velocity='0.000000'/>
      </axis>
    </joint>
    <joint name='r_shoulder_lift_joint' type='revolute'>
      <origin>0.000000 0.000000 0.000000 0.000000 -0.000000 0.000000</origin>
      <parent link='r_shoulder_pan_link'/>
      <child link='r_shoulder_lift_link'/>
      <axis xyz='0.000000 1.000000 0.000000'>
        <dynamics damping='10.000000' friction='0.000000'/>
        <limit lower='-0.523601' upper='1.396300' effort='0.000000' velocity='0.000000'/>
      </axis>
    </joint>
    <joint name='r_upper_arm_roll_joint' type='revolute'>
      <origin>0.000000 0.000000 0.000000 0.000000 -0.000000 0.000000</origin>
      <parent link='r_shoulder_lift_link'/>
      <child link='r_upper_arm_roll_link'/>
      <axis xyz='1.000000 0.000000 0.000000'>
        <dynamics damping='0.100000' friction='0.000000'/>
        <limit lower='-3.900008' upper='0.800000' effort='0.000000' velocity='0.000000'/>
      </axis>
    </joint>
    <joint name='r_elbow_flex_joint' type='revolute'>
      <origin>0.000000 0.000000 0.000000 0.000000 -0.000000 0.000000</origin>
      <parent link='r_upper_arm_roll_link'/>
      <child link='r_elbow_flex_link'/>
      <axis xyz='0.000000 1.000000 0.000000'>
        <dynamics damping='1.000000' friction='0.000000'/>
        <limit lower='-2.321305' upper='0.000000' effort='0.000000' velocity='0.000000'/>
      </axis>
    </joint>
    <joint name='r_forearm_roll_joint' type='revolute'>
      <origin>0.000000 0.000000 0.000000 0.000000 -0.000000 0.000000</origin>
      <parent link='r_elbow_flex_link'/>
      <child link='r_forearm_roll_link'/>
      <axis xyz='1.000000 0.000000 0.000000'>
        <dynamics damping='0.100000' friction='0.000000'/>
        <limit lower='-10000000000000000.000000' upper='10000000000000000.000000' effort='0.000000' velocity='0.000000'/>
      </axis>
    </joint>
    <joint name='r_wrist_flex_joint' type='revolute'>
      <origin>0.000000 0.000000 0.000000 0.000000 -0.000000 0.000000</origin>
      <parent link='r_forearm_roll_link'/>
      <child link='r_wrist_flex_link'/>
      <axis xyz='0.000000 1.000000 0.000000'>
        <dynamics damping='0.100000' friction='0.000000'/>
        <limit lower='-2.180004' upper='0.000000' effort='0.000000' velocity='0.000000'/>
      </axis>
    </joint>
    <joint name='r_wrist_roll_joint' type='revolute'>
      <origin>0.000000 0.000000 0.000000 0.000000 -0.000000 0.000000</origin>
      <parent link='r_wrist_flex_link'/>
      <child link='r_wrist_roll_link'/>
      <axis xyz='1.000000 0.000000 0.000000'>
        <dynamics damping='0.100000' friction='0.000000'/>
        <limit lower='-10000000000000000.000000' upper='10000000000000000.000000' effort='0.000000' velocity='0.000000'/>
      </axis>
    </joint>
    <joint name='r_gripper_l_finger_joint' type='revolute'>
      <origin>0.000000 0.000000 0.000000 0.000000 -0.000000 0.000000</origin>
      <parent link='r_wrist_roll_link'/>
      <child link='r_gripper_l_finger_link'/>
      <axis xyz='0.000000 0.000000 1.000000'>
        <dynamics damping='0.020000' friction='0.000000'/>
        <limit lower='0.000000' upper='0.548000' effort='0.000000' velocity='0.000000'/>
      </axis>
    </joint>
    <joint name='r_gripper_l_finger_tip_joint' type='revolute'>
      <origin>0.000000 0.000000 0.000000 0.000000 -0.000000 0.000000</origin>
      <parent link='r_gripper_l_finger_link'/>
      <child link='r_gripper_l_finger_tip_link'/>
      <axis xyz='0.000000 0.000000 -1.000000'>
        <dynamics damping='0.001000' friction='0.000000'/>
        <limit lower='0.000000' upper='0.548000' effort='0.000000' velocity='0.000000'/>
      </axis>
    </joint>
    <joint name='r_gripper_motor_slider_joint' type='prismatic'>
      <origin>0.000000 0.000000 0.000000 0.000000 -0.000000 0.000000</origin>
      <parent link='r_wrist_roll_link'/>
      <child link='r_gripper_motor_slider_link'/>
      <axis xyz='1.000000 0.000000 0.000000'>
        <dynamics damping='0.000000' friction='0.000000'/>
        <limit lower='-0.100000' upper='0.100000' effort='0.000000' velocity='0.000000'/>
      </axis>
    </joint>
    <joint name='r_gripper_motor_screw_joint' type='revolute'>
      <origin>0.000000 0.000000 0.000000 0.000000 -0.000000 0.000000</origin>
      <parent link='r_gripper_motor_slider_link'/>
      <child link='r_gripper_motor_screw_link'/>
      <axis xyz='0.000000 1.000000 0.000000'>
        <dynamics damping='0.000100' friction='0.000000'/>
        <limit lower='-10000000000000000.000000' upper='10000000000000000.000000' effort='0.000000' velocity='0.000000'/>
      </axis>
    </joint>
    <joint name='r_gripper_r_finger_joint' type='revolute'>
      <origin>0.000000 0.000000 0.000000 0.000000 -0.000000 0.000000</origin>
      <parent link='r_wrist_roll_link'/>
      <child link='r_gripper_r_finger_link'/>
      <axis xyz='0.000000 0.000000 -1.000000'>
        <dynamics damping='0.020000' friction='0.000000'/>
        <limit lower='0.000000' upper='0.548000' effort='0.000000' velocity='0.000000'/>
      </axis>
    </joint>
    <joint name='r_gripper_r_finger_tip_joint' type='revolute'>
      <origin>0.000000 0.000000 0.000000 0.000000 -0.000000 0.000000</origin>
      <parent link='r_gripper_r_finger_link'/>
      <child link='r_gripper_r_finger_tip_link'/>
      <axis xyz='0.000000 0.000000 1.000000'>
        <dynamics damping='0.001000' friction='0.000000'/>
        <limit lower='0.000000' upper='0.548000' effort='0.000000' velocity='0.000000'/>
      </axis>
    </joint>
    <joint name='torso_lift_motor_screw_joint' type='revolute'>
      <origin>0.000000 0.000000 0.000000 0.000000 -0.000000 0.000000</origin>
      <parent link='base_footprint'/>
      <child link='torso_lift_motor_screw_link'/>
      <axis xyz='0.000000 0.000000 1.000000'>
        <dynamics damping='0.000100' friction='0.000000'/>
        <limit lower='-10000000000000000.000000' upper='10000000000000000.000000' effort='0.000000' velocity='0.000000'/>
      </axis>
    </joint>
    <joint name='torso_lift_screw_torso_lift_joint' type='screw'>
      <origin>0.000000 0.000000 0.000000 0.000000 -0.000000 0.000000</origin>
      <parent link='torso_lift_link'/>
      <child link='torso_lift_motor_screw_link'/>
      <thread_pitch>3141.600000</thread_pitch>
      <axis xyz='0.000000 0.000000 1.000000'>
        <dynamics damping='0.000000' friction='0.000000'/>
        <limit lower='-10000000000000000.000000' upper='10000000000000000.000000' effort='0.000000' velocity='0.000000'/>
      </axis>
    </joint>
    <joint name='r_gripper_r_screw_screw_joint' type='screw'>
      <origin>0.000000 0.000000 0.000000 0.000000 -0.000000 0.000000</origin>
      <parent link='r_gripper_r_finger_tip_link'/>
      <child link='r_gripper_motor_screw_link'/>
      <thread_pitch>-3141.600000</thread_pitch>
      <axis xyz='0.000000 1.000000 0.000000'>
        <dynamics damping='0.000000' friction='0.000000'/>
        <limit lower='-10000000000000000.000000' upper='10000000000000000.000000' effort='0.000000' velocity='0.000000'/>
      </axis>
    </joint>
    <joint name='r_gripper_l_screw_screw_joint' type='screw'>
      <origin>0.000000 0.000000 0.000000 0.000000 -0.000000 0.000000</origin>
      <parent link='r_gripper_l_finger_tip_link'/>
      <child link='r_gripper_motor_screw_link'/>
      <thread_pitch>3141.600000</thread_pitch>
      <axis xyz='0.000000 1.000000 0.000000'>
        <dynamics damping='0.000000' friction='0.000000'/>
        <limit lower='-10000000000000000.000000' upper='10000000000000000.000000' effort='0.000000' velocity='0.000000'/>
      </axis>
    </joint>
    <joint name='r_gripper_r_parallel_root_joint' type='revolute'>
      <origin>0.058910 -0.031000 0.000000 0.000000 -0.000000 0.000000</origin>
      <parent link='r_gripper_r_parallel_link'/>
      <child link='r_wrist_roll_link'/>
      <axis xyz='0.000000 0.000000 -1.000000'>
        <dynamics damping='0.200000' friction='0.000000'/>
        <limit lower='-10000000000000000.000000' upper='10000000000000000.000000' effort='0.000000' velocity='0.000000'/>
      </axis>
    </joint>
    <joint name='r_gripper_l_parallel_root_joint' type='revolute'>
      <origin>0.058910 0.031000 0.000000 0.000000 -0.000000 0.000000</origin>
      <parent link='r_gripper_l_parallel_link'/>
      <child link='r_wrist_roll_link'/>
      <axis xyz='0.000000 0.000000 1.000000'>
        <dynamics damping='0.200000' friction='0.000000'/>
        <limit lower='-10000000000000000.000000' upper='10000000000000000.000000' effort='0.000000' velocity='0.000000'/>
      </axis>
    </joint>
    <joint name='r_gripper_r_parallel_tip_joint' type='revolute'>
      <origin>-0.018000 -0.021000 0.000000 0.000000 -0.000000 0.000000</origin>
      <parent link='r_gripper_r_parallel_link'/>
      <child link='r_gripper_r_finger_tip_link'/>
      <axis xyz='0.000000 0.000000 1.000000'>
        <dynamics damping='0.000000' friction='0.000000'/>
        <limit lower='-10000000000000000.000000' upper='10000000000000000.000000' effort='0.000000' velocity='0.000000'/>
      </axis>
    </joint>
    <joint name='r_gripper_l_parallel_tip_joint' type='revolute'>
      <origin>-0.018000 0.021000 0.000000 0.000000 -0.000000 0.000000</origin>
      <parent link='r_gripper_l_parallel_link'/>
      <child link='r_gripper_l_finger_tip_link'/>
      <axis xyz='0.000000 0.000000 1.000000'>
        <dynamics damping='0.000000' friction='0.000000'/>
        <limit lower='-10000000000000000.000000' upper='10000000000000000.000000' effort='0.000000' velocity='0.000000'/>
      </axis>
    </joint>
    <joint name='r_gripper_joint' type='prismatic'>
      <origin>0.000000 0.000000 0.000000 0.000000 -0.000000 0.000000</origin>
      <parent link='r_gripper_r_finger_tip_link'/>
      <child link='r_gripper_l_finger_tip_link'/>
      <axis xyz='0.000000 1.000000 0.000000'>
        <dynamics damping='0.000000' friction='0.000000'/>
        <limit lower='-10000000000000000.000000' upper='10000000000000000.000000' effort='0.000000' velocity='0.000000'/>
      </axis>
    </joint>
    <joint name='l_gripper_r_screw_screw_joint' type='screw'>
      <origin>0.000000 0.000000 0.000000 0.000000 -0.000000 0.000000</origin>
      <parent link='l_gripper_r_finger_tip_link'/>
      <child link='l_gripper_motor_screw_link'/>
      <thread_pitch>-3141.600000</thread_pitch>
      <axis xyz='0.000000 1.000000 0.000000'>
        <dynamics damping='0.000000' friction='0.000000'/>
        <limit lower='-10000000000000000.000000' upper='10000000000000000.000000' effort='0.000000' velocity='0.000000'/>
      </axis>
    </joint>
    <joint name='l_gripper_l_screw_screw_joint' type='screw'>
      <origin>0.000000 0.000000 0.000000 0.000000 -0.000000 0.000000</origin>
      <parent link='l_gripper_l_finger_tip_link'/>
      <child link='l_gripper_motor_screw_link'/>
      <thread_pitch>3141.600000</thread_pitch>
      <axis xyz='0.000000 1.000000 0.000000'>
        <dynamics damping='0.000000' friction='0.000000'/>
        <limit lower='-10000000000000000.000000' upper='10000000000000000.000000' effort='0.000000' velocity='0.000000'/>
      </axis>
    </joint>
    <joint name='l_gripper_r_parallel_root_joint' type='revolute'>
      <origin>0.058910 -0.031000 0.000000 0.000000 -0.000000 0.000000</origin>
      <parent link='l_gripper_r_parallel_link'/>
      <child link='l_wrist_roll_link'/>
      <axis xyz='0.000000 0.000000 -1.000000'>
        <dynamics damping='0.200000' friction='0.000000'/>
        <limit lower='-10000000000000000.000000' upper='10000000000000000.000000' effort='0.000000' velocity='0.000000'/>
      </axis>
    </joint>
    <joint name='l_gripper_l_parallel_root_joint' type='revolute'>
      <origin>0.058910 0.031000 0.000000 0.000000 -0.000000 0.000000</origin>
      <parent link='l_gripper_l_parallel_link'/>
      <child link='l_wrist_roll_link'/>
      <axis xyz='0.000000 0.000000 1.000000'>
        <dynamics damping='0.200000' friction='0.000000'/>
        <limit lower='-10000000000000000.000000' upper='10000000000000000.000000' effort='0.000000' velocity='0.000000'/>
      </axis>
    </joint>
    <joint name='l_gripper_r_parallel_tip_joint' type='revolute'>
      <origin>-0.018000 -0.021000 0.000000 0.000000 -0.000000 0.000000</origin>
      <parent link='l_gripper_r_parallel_link'/>
      <child link='l_gripper_r_finger_tip_link'/>
      <axis xyz='0.000000 0.000000 1.000000'>
        <dynamics damping='0.000000' friction='0.000000'/>
        <limit lower='-10000000000000000.000000' upper='10000000000000000.000000' effort='0.000000' velocity='0.000000'/>
      </axis>
    </joint>
    <joint name='l_gripper_l_parallel_tip_joint' type='revolute'>
      <origin>-0.018000 0.021000 0.000000 0.000000 -0.000000 0.000000</origin>
      <parent link='l_gripper_l_parallel_link'/>
      <child link='l_gripper_l_finger_tip_link'/>
      <axis xyz='0.000000 0.000000 1.000000'>
        <dynamics damping='0.000000' friction='0.000000'/>
        <limit lower='-10000000000000000.000000' upper='10000000000000000.000000' effort='0.000000' velocity='0.000000'/>
      </axis>
    </joint>
    <joint name='l_gripper_joint' type='prismatic'>
      <origin>0.000000 0.000000 0.000000 0.000000 -0.000000 0.000000</origin>
      <parent link='l_gripper_r_finger_tip_link'/>
      <child link='l_gripper_l_finger_tip_link'/>
      <axis xyz='0.000000 1.000000 0.000000'>
        <dynamics damping='0.000000' friction='0.000000'/>
        <limit lower='-10000000000000000.000000' upper='10000000000000000.000000' effort='0.000000' velocity='0.000000'/>
      </axis>
    </joint>
  </model>
</gazebo>
