<gazebo version='1.0'>
  <model name='pr2_gripper' static='0'>
    <origin pose='-0.771000 0.188000 -0.790675 0.000000 -1.57079633 0.000000'/>
    <link name='r_wrist_roll_link' gravity='1' self_collide='0' kinematic='0'>
      <origin pose='0.771000 -0.188000 0.790675 0.000000 -0.000000 0.000000'/>
      <inertial mass='0.681070'>
        <origin pose='0.056408 0.000451 -0.001014 0.000000 -0.000000 0.000000'/>
        <inertia ixx='0.011352' ixy='-0.000016' ixz='-0.000001' iyy='0.011677' iyz='-0.000001' izz='0.011866'/>
      </inertial>
      <collision name='r_wrist_roll_link_geom' laser_retro='0.000000'>
        <origin pose='0.000000 0.000000 0.000000 0.000000 -0.000000 0.000000'/>
        <geometry>
          <mesh filename='pr2_gripper_meshes/forearm_v0/wrist_roll_L.stl' scale='1.000000 1.000000 1.000000'/>
        </geometry>
        <surface>
          <friction>
            <ode mu='-1.000000' mu2='-1.000000' fdir1='0.000000 0.000000 0.000000' slip1='0.000000' slip2='0.000000'/>
          </friction>
          <bounce restitution_coefficient='0.000000' threshold='100000.000000'/>
          <contact>
            <ode soft_cfm='0.000000' soft_erp='0.200000' kp='1000000000000.000000' kd='1.000000' max_vel='100.000000' min_depth='0.001000'/>
          </contact>
        </surface>
      </collision>
      <visual name='r_wrist_roll_link_geom_visual' cast_shadows='1' laser_retro='0.000000' transparency='0.000000'>
        <origin pose='0.000000 0.000000 0.000000 0.000000 -0.000000 0.000000'/>
        <geometry>
          <mesh filename='pr2_gripper_meshes/forearm_v0/wrist_roll.stl' scale='1.000000 1.000000 1.000000'/>
        </geometry>
        <material script='PR2/RollLinks'/>
      </visual>
      <visual name='r_wrist_roll_link_geom_r_gripper_palm_link_visual' cast_shadows='1' laser_retro='0.000000' transparency='0.000000'>
        <origin pose='0.000000 0.000000 0.000000 0.000000 -0.000000 0.000000'/>
        <geometry>
          <mesh filename='pr2_gripper_meshes/gripper_v0/gripper_palm.dae' scale='1.000000 1.000000 1.000000'/>
        </geometry>
      </visual>
    </link>
    <link name='r_gripper_l_finger_link' gravity='1' self_collide='0' kinematic='0'>
      <origin pose='0.847910 -0.178000 0.790675 0.000000 -0.000000 0.000000'/>
      <inertial mass='0.171260'>
        <origin pose='0.035980 0.017300 -0.001640 0.000000 -0.000000 0.000000'/>
        <inertia ixx='0.000078' ixy='0.000001' ixz='-0.000010' iyy='0.000197' iyz='-0.000003' izz='0.000181'/>
      </inertial>
      <collision name='r_gripper_l_finger_link_geom' laser_retro='0.000000'>
        <origin pose='0.000000 0.000000 0.000000 0.000000 -0.000000 0.000000'/>
        <geometry>
          <mesh filename='pr2_gripper_meshes/gripper_v0/l_finger.stl' scale='1.000000 1.000000 1.000000'/>
        </geometry>
        <surface>
          <friction>
            <ode mu='500.000000' mu2='500.000000' fdir1='0.000000 0.000000 0.000000' slip1='0.000000' slip2='0.000000'/>
          </friction>
          <bounce restitution_coefficient='0.000000' threshold='100000.000000'/>
          <contact>
            <ode soft_cfm='0.000000' soft_erp='0.200000' kp='1000000.000000' kd='1.000000' max_vel='100.000000' min_depth='0.001000'/>
          </contact>
        </surface>
      </collision>
      <visual name='r_gripper_l_finger_link_geom_visual' cast_shadows='1' laser_retro='0.000000' transparency='0.000000'>
        <origin pose='0.000000 0.000000 0.000000 0.000000 -0.000000 0.000000'/>
        <geometry>
          <mesh filename='pr2_gripper_meshes/gripper_v0/l_finger.dae' scale='1.000000 1.000000 1.000000'/>
        </geometry>
      </visual>
    </link>
    <link name='r_gripper_l_finger_tip_link' gravity='1' self_collide='0' kinematic='0'>
      <origin pose='0.939280 -0.173050 0.790675 0.000000 -0.000000 0.000000'/>
      <inertial mass='0.044190'>
        <origin pose='0.004230 0.002840 0.000000 0.000000 -0.000000 0.000000'/>
        <inertia ixx='0.000008' ixy='0.000006' ixz='0.000000' iyy='0.000010' iyz='0.000000' izz='0.000015'/>
      </inertial>
      <collision name='r_gripper_l_finger_tip_link_geom' laser_retro='0.000000'>
        <origin pose='0.000000 0.000000 0.000000 0.000000 -0.000000 0.000000'/>
        <geometry>
          <mesh filename='pr2_gripper_meshes/gripper_v0/l_finger_tip.stl' scale='1.000000 1.000000 1.000000'/>
        </geometry>
        <surface>
          <friction>
            <ode mu='500.000000' mu2='500.000000' fdir1='0.000000 0.000000 0.000000' slip1='0.000000' slip2='0.000000'/>
          </friction>
          <bounce restitution_coefficient='0.000000' threshold='100000.000000'/>
          <contact>
            <ode soft_cfm='0.000000' soft_erp='0.200000' kp='10000000.000000' kd='1.000000' max_vel='100.000000' min_depth='0.001000'/>
          </contact>
        </surface>
      </collision>
      <visual name='r_gripper_l_finger_tip_link_geom_visual' cast_shadows='1' laser_retro='0.000000' transparency='0.000000'>
        <origin pose='0.000000 0.000000 0.000000 0.000000 -0.000000 0.000000'/>
        <geometry>
          <mesh filename='pr2_gripper_meshes/gripper_v0/l_finger_tip.dae' scale='1.000000 1.000000 1.000000'/>
        </geometry>
      </visual>
      <sensor name='r_gripper_l_finger_tip_contact_sensor' type='contact' always_on='0' update_rate='100.000000' visualize='0'>
        <origin pose='0.000000 0.000000 0.000000 0.000000 -0.000000 0.000000'/>
        <contact>
          <collision name='r_gripper_l_finger_tip_link_geom'/>
        </contact>
        <plugin name='r_gripper_l_finger_tip_gazebo_ros_bumper_controller' filename='libgazebo_ros_bumper.so'>
          <alwaysOn>1</alwaysOn>
          <frameName>r_gripper_l_finger_tip_link</frameName>
          <updateRate>100.0</updateRate>
          <bumperTopicName>r_gripper_l_finger_tip_bumper</bumperTopicName>
        </plugin>
      </sensor>
    </link>
    <link name='r_gripper_motor_slider_link' gravity='1' self_collide='0' kinematic='0'>
      <origin pose='0.939280 -0.188000 0.790675 0.000000 -0.000000 0.000000'/>
      <inertial mass='0.010000'>
        <origin pose='0.000000 0.000000 0.000000 0.000000 -0.000000 0.000000'/>
        <inertia ixx='0.001000' ixy='0.000000' ixz='0.000000' iyy='0.001000' iyz='0.000000' izz='0.001000'/>
      </inertial>
    </link>
    <link name='r_gripper_motor_screw_link' gravity='1' self_collide='0' kinematic='0'>
      <origin pose='0.939280 -0.188000 0.790675 0.000000 -0.000000 0.000000'/>
      <inertial mass='0.010000'>
        <origin pose='0.000000 0.000000 0.000000 0.000000 -0.000000 0.000000'/>
        <inertia ixx='0.000100' ixy='0.000000' ixz='0.000000' iyy='0.000100' iyz='0.000000' izz='0.000100'/>
      </inertial>
    </link>
    <link name='r_gripper_r_finger_link' gravity='1' self_collide='0' kinematic='0'>
      <origin pose='0.847910 -0.198000 0.790675 0.000000 -0.000000 0.000000'/>
      <inertial mass='0.173890'>
        <origin pose='0.035760 -0.017360 -0.000950 0.000000 -0.000000 0.000000'/>
        <inertia ixx='0.000077' ixy='-0.000002' ixz='-0.000008' iyy='0.000198' iyz='0.000002' izz='0.000181'/>
      </inertial>
      <collision name='r_gripper_r_finger_link_geom' laser_retro='0.000000'>
        <origin pose='0.000000 0.000000 0.000000 -3.141590 -0.000000 0.000000'/>
        <geometry>
          <mesh filename='pr2_gripper_meshes/gripper_v0/l_finger.stl' scale='1.000000 1.000000 1.000000'/>
        </geometry>
        <surface>
          <friction>
            <ode mu='500.000000' mu2='500.000000' fdir1='0.000000 0.000000 0.000000' slip1='0.000000' slip2='0.000000'/>
          </friction>
          <bounce restitution_coefficient='0.000000' threshold='100000.000000'/>
          <contact>
            <ode soft_cfm='0.000000' soft_erp='0.200000' kp='1000000.000000' kd='1.000000' max_vel='100.000000' min_depth='0.001000'/>
          </contact>
        </surface>
      </collision>
      <visual name='r_gripper_r_finger_link_geom_visual' cast_shadows='1' laser_retro='0.000000' transparency='0.000000'>
        <origin pose='0.000000 0.000000 0.000000 -3.141590 0.000000 0.000000'/>
        <geometry>
          <mesh filename='pr2_gripper_meshes/gripper_v0/l_finger.dae' scale='1.000000 1.000000 1.000000'/>
        </geometry>
      </visual>
    </link>
    <link name='r_gripper_r_finger_tip_link' gravity='1' self_collide='0' kinematic='0'>
      <origin pose='0.939280 -0.202950 0.790675 0.000000 -0.000000 0.000000'/>
      <inertial mass='0.044190'>
        <origin pose='0.004230 -0.002840 0.000000 0.000000 -0.000000 0.000000'/>
        <inertia ixx='0.000008' ixy='-0.000006' ixz='0.000000' iyy='0.000010' iyz='0.000000' izz='0.000015'/>
      </inertial>
      <collision name='r_gripper_r_finger_tip_link_geom' laser_retro='0.000000'>
        <origin pose='0.000000 0.000000 0.000000 -3.141590 -0.000000 0.000000'/>
        <geometry>
          <mesh filename='pr2_gripper_meshes/gripper_v0/l_finger_tip.stl' scale='1.000000 1.000000 1.000000'/>
        </geometry>
        <surface>
          <friction>
            <ode mu='500.000000' mu2='500.000000' fdir1='0.000000 0.000000 0.000000' slip1='0.000000' slip2='0.000000'/>
          </friction>
          <bounce restitution_coefficient='0.000000' threshold='100000.000000'/>
          <contact>
            <ode soft_cfm='0.000000' soft_erp='0.200000' kp='10000000.000000' kd='1.000000' max_vel='100.000000' min_depth='0.001000'/>
          </contact>
        </surface>
      </collision>
      <visual name='r_gripper_r_finger_tip_link_geom_visual' cast_shadows='1' laser_retro='0.000000' transparency='0.000000'>
        <origin pose='0.000000 0.000000 0.000000 -3.141590 0.000000 0.000000'/>
        <geometry>
          <mesh filename='pr2_gripper_meshes/gripper_v0/l_finger_tip.dae' scale='1.000000 1.000000 1.000000'/>
        </geometry>
      </visual>
      <sensor name='r_gripper_r_finger_tip_contact_sensor' type='contact' always_on='0' update_rate='100.000000' visualize='0'>
        <origin pose='0.000000 0.000000 0.000000 0.000000 -0.000000 0.000000'/>
        <contact>
          <collision name='r_gripper_r_finger_tip_link_geom'/>
        </contact>
        <plugin name='r_gripper_r_finger_tip_gazebo_ros_bumper_controller' filename='libgazebo_ros_bumper.so'>
          <alwaysOn>1</alwaysOn>
          <frameName>r_gripper_r_finger_tip_link</frameName>
          <updateRate>100.0</updateRate>
          <bumperTopicName>r_gripper_r_finger_tip_bumper</bumperTopicName>
        </plugin>
      </sensor>
    </link>
    <link name='torso_lift_motor_screw_link' gravity='1' self_collide='0' kinematic='0'>
      <origin pose='-0.150000 0.000000 0.751000 0.000000 -0.000000 0.000000'/>
      <inertial mass='1.000000'>
        <origin pose='0.000000 0.000000 0.000000 0.000000 -0.000000 0.000000'/>
        <inertia ixx='0.001000' ixy='0.000000' ixz='0.000000' iyy='0.001000' iyz='0.000000' izz='0.001000'/>
      </inertial>
    </link>
    <link name='r_gripper_l_parallel_link' gravity='1' self_collide='0' kinematic='0'>
      <origin pose='0.829910 -0.157000 0.790675 0.000000 -0.000000 0.000000'/>
      <inertial mass='0.171260'>
        <origin pose='0.035980 0.017300 -0.001640 0.000000 -0.000000 0.000000'/>
        <inertia ixx='0.000078' ixy='0.000001' ixz='-0.000010' iyy='0.000197' iyz='-0.000003' izz='0.000181'/>
      </inertial>
    </link>
    <link name='r_gripper_r_parallel_link' gravity='1' self_collide='0' kinematic='0'>
      <origin pose='0.829910 -0.219000 0.790675 0.000000 -0.000000 0.000000'/>
      <inertial mass='0.173890'>
        <origin pose='0.035760 -0.017360 -0.000950 0.000000 -0.000000 0.000000'/>
        <inertia ixx='0.000077' ixy='-0.000002' ixz='-0.000008' iyy='0.000198' iyz='0.000002' izz='0.000181'/>
      </inertial>
    </link>
    <joint name='r_gripper_l_finger_joint' type='revolute'>
      <origin pose='0.000000 0.000000 0.000000 0.000000 -0.000000 0.000000'/>
      <parent link='r_wrist_roll_link'/>
      <child link='r_gripper_l_finger_link'/>
      <axis xyz='0.000000 0.000000 1.000000'>
        <dynamics damping='0.020000' friction='0.000000'/>
        <limit lower='0.000000' upper='0.548000' effort='0.000000' velocity='0.000000'/>
      </axis>
    </joint>
    <joint name='r_gripper_l_finger_tip_joint' type='revolute'>
      <origin pose='0.000000 0.000000 0.000000 0.000000 -0.000000 0.000000'/>
      <parent link='r_gripper_l_finger_link'/>
      <child link='r_gripper_l_finger_tip_link'/>
      <axis xyz='0.000000 0.000000 -1.000000'>
        <dynamics damping='0.001000' friction='0.000000'/>
        <limit lower='0.000000' upper='0.548000' effort='0.000000' velocity='0.000000'/>
      </axis>
    </joint>
    <joint name='r_gripper_motor_slider_joint' type='prismatic'>
      <origin pose='0.000000 0.000000 0.000000 0.000000 -0.000000 0.000000'/>
      <parent link='r_wrist_roll_link'/>
      <child link='r_gripper_motor_slider_link'/>
      <axis xyz='1.000000 0.000000 0.000000'>
        <dynamics damping='0.000000' friction='0.000000'/>
        <limit lower='-0.100000' upper='0.100000' effort='0.000000' velocity='0.000000'/>
      </axis>
    </joint>
    <joint name='r_gripper_motor_screw_joint' type='revolute'>
      <origin pose='0.000000 0.000000 0.000000 0.000000 -0.000000 0.000000'/>
      <parent link='r_gripper_motor_slider_link'/>
      <child link='r_gripper_motor_screw_link'/>
      <axis xyz='0.000000 1.000000 0.000000'>
        <dynamics damping='0.000100' friction='0.000000'/>
        <limit lower='-10000000000000000.000000' upper='10000000000000000.000000' effort='0.000000' velocity='0.000000'/>
      </axis>
    </joint>
    <joint name='r_gripper_r_finger_joint' type='revolute'>
      <origin pose='0.000000 0.000000 0.000000 0.000000 -0.000000 0.000000'/>
      <parent link='r_wrist_roll_link'/>
      <child link='r_gripper_r_finger_link'/>
      <axis xyz='0.000000 0.000000 -1.000000'>
        <dynamics damping='0.020000' friction='0.000000'/>
        <limit lower='0.000000' upper='0.548000' effort='0.000000' velocity='0.000000'/>
      </axis>
    </joint>
    <joint name='r_gripper_r_finger_tip_joint' type='revolute'>
      <origin pose='0.000000 0.000000 0.000000 0.000000 -0.000000 0.000000'/>
      <parent link='r_gripper_r_finger_link'/>
      <child link='r_gripper_r_finger_tip_link'/>
      <axis xyz='0.000000 0.000000 1.000000'>
        <dynamics damping='0.001000' friction='0.000000'/>
        <limit lower='0.000000' upper='0.548000' effort='0.000000' velocity='0.000000'/>
      </axis>
    </joint>
    <joint name='r_gripper_r_screw_screw_joint' type='screw'>
      <origin pose='0.000000 0.000000 0.000000 0.000000 -0.000000 0.000000'/>
      <parent link='r_gripper_r_finger_tip_link'/>
      <child link='r_gripper_motor_screw_link'/>
      <thread_pitch>-3141.600000</thread_pitch>
      <axis xyz='0.000000 1.000000 0.000000'>
        <dynamics damping='0.000000' friction='0.000000'/>
        <limit lower='-10000000000000000.000000' upper='10000000000000000.000000' effort='0.000000' velocity='0.000000'/>
      </axis>
    </joint>
    <joint name='r_gripper_l_screw_screw_joint' type='screw'>
      <origin pose='0.000000 0.000000 0.000000 0.000000 -0.000000 0.000000'/>
      <parent link='r_gripper_l_finger_tip_link'/>
      <child link='r_gripper_motor_screw_link'/>
      <thread_pitch>3141.600000</thread_pitch>
      <axis xyz='0.000000 1.000000 0.000000'>
        <dynamics damping='0.000000' friction='0.000000'/>
        <limit lower='-10000000000000000.000000' upper='10000000000000000.000000' effort='0.000000' velocity='0.000000'/>
      </axis>
    </joint>
    <joint name='r_gripper_r_parallel_root_joint' type='revolute'>
      <origin pose='0.058910 -0.031000 0.000000 0.000000 -0.000000 0.000000'/>
      <parent link='r_gripper_r_parallel_link'/>
      <child link='r_wrist_roll_link'/>
      <axis xyz='0.000000 0.000000 -1.000000'>
        <dynamics damping='0.200000' friction='0.000000'/>
        <limit lower='-10000000000000000.000000' upper='10000000000000000.000000' effort='0.000000' velocity='0.000000'/>
      </axis>
    </joint>
    <joint name='r_gripper_l_parallel_root_joint' type='revolute'>
      <origin pose='0.058910 0.031000 0.000000 0.000000 -0.000000 0.000000'/>
      <parent link='r_gripper_l_parallel_link'/>
      <child link='r_wrist_roll_link'/>
      <axis xyz='0.000000 0.000000 1.000000'>
        <dynamics damping='0.200000' friction='0.000000'/>
        <limit lower='-10000000000000000.000000' upper='10000000000000000.000000' effort='0.000000' velocity='0.000000'/>
      </axis>
    </joint>
    <joint name='r_gripper_r_parallel_tip_joint' type='revolute'>
      <origin pose='-0.018000 -0.021000 0.000000 0.000000 -0.000000 0.000000'/>
      <parent link='r_gripper_r_parallel_link'/>
      <child link='r_gripper_r_finger_tip_link'/>
      <axis xyz='0.000000 0.000000 1.000000'>
        <dynamics damping='0.000000' friction='0.000000'/>
        <limit lower='-10000000000000000.000000' upper='10000000000000000.000000' effort='0.000000' velocity='0.000000'/>
      </axis>
    </joint>
    <joint name='r_gripper_l_parallel_tip_joint' type='revolute'>
      <origin pose='-0.018000 0.021000 0.000000 0.000000 -0.000000 0.000000'/>
      <parent link='r_gripper_l_parallel_link'/>
      <child link='r_gripper_l_finger_tip_link'/>
      <axis xyz='0.000000 0.000000 1.000000'>
        <dynamics damping='0.000000' friction='0.000000'/>
        <limit lower='-10000000000000000.000000' upper='10000000000000000.000000' effort='0.000000' velocity='0.000000'/>
      </axis>
    </joint>
    <joint name='r_gripper_joint' type='prismatic'>
      <origin pose='0.000000 0.000000 0.000000 0.000000 -0.000000 0.000000'/>
      <parent link='r_gripper_r_finger_tip_link'/>
      <child link='r_gripper_l_finger_tip_link'/>
      <axis xyz='0.000000 1.000000 0.000000'>
        <dynamics damping='0.000000' friction='0.000000'/>
        <limit lower='-10000000000000000.000000' upper='10000000000000000.000000' effort='0.000000' velocity='0.000000'/>
      </axis>
    </joint>
    <plugin name='p3d_r_gripper_l_finger_controller' filename='libgazebo_ros_p3d.so'>
      <alwaysOn>1</alwaysOn>
      <updateRate>100.0</updateRate>
      <bodyName>r_gripper_l_finger_link</bodyName>
      <topicName>r_gripper_l_finger_pose_ground_truth</topicName>
      <gaussianNoise>0.0</gaussianNoise>
      <frameName>base_link</frameName>
      <xyz>0 0 0</xyz>
      <rpy>0 -0 0</rpy>
    </plugin>
    <plugin name='f3d_r_gripper_l_finger_controller' filename='libgazebo_ros_f3d.so'>
      <alwaysOn>1</alwaysOn>
      <updateRate>100.0</updateRate>
      <bodyName>r_gripper_l_finger_link</bodyName>
      <topicName>r_gripper_l_finger_force_ground_truth</topicName>
      <frameName>r_gripper_l_finger_link</frameName>
    </plugin>
    <plugin name='p3d_r_gripper_palm_controller' filename='libgazebo_ros_p3d.so'>
      <alwaysOn>1</alwaysOn>
      <updateRate>100.0</updateRate>
      <topicName>r_gripper_palm_pose_ground_truth</topicName>
      <xyzOffsets>0 0 0</xyzOffsets>
      <rpyOffsets>0 0 0</rpyOffsets>
      <gaussianNoise>0.0</gaussianNoise>
      <frameName>map</frameName>
      <xyz>0 0 0</xyz>
      <rpy>0 -0 0</rpy>
      <bodyName>r_wrist_roll_link</bodyName>
    </plugin>
  </model>
</gazebo>
