<gazebo version='1.0'>
  <model name='simple_arm'>
    <link name='arm_base'>
      <inertial mass='101.0'>
        <origin pose='0 0 0.00099 0 0 0'/>
        <inertia ixx='1.11' ixy='0' ixz='0' iyy='100.11' iyz='0' izz='1.01'/>
      </inertial>
      <collision name='arm_base_geom'>
        <origin pose='0 0 0.05 0 0 0'/>
        <geometry>
          <box size='1.0 1.0 0.1'/>
        </geometry>
      </collision>

      <visual name='arm_base_geom_visual'>
        <origin pose='0 0 0.05 0 0 0'/>
        <geometry>
          <box size='1.0 1.0 0.1'/>
        </geometry>
        <material script='Gazebo/Blue'/>
      </visual>

      <collision name='arm_base_geom_arm_trunk'>
        <origin pose='0 0 0.6 0 0 0'/>
        <geometry>
          <cylinder radius='0.05' length='1.0'/>
        </geometry>
      </collision>
      <visual name='arm_base_geom_arm_trunk_visual'>
        <origin pose='0 0 0.6 0 0 0'/>
        <geometry>
          <cylinder radius='0.05' length='1.0'/>
        </geometry>
        <material script='Gazebo/Red'/>
      </visual>
    </link>

    <link name='arm_shoulder_pan'>
      <origin pose='0 0 1.1 0 0 0'/>
      <inertial mass='1.1'>
        <origin pose='0.045455 0 0 0 0 0'/>
        <inertia ixx='0.011' ixy='0' ixz='0' iyy='0.0225' iyz='0' izz='0.0135'/>
      </inertial>
      <collision name='arm_shoulder_pan_geom' >
        <origin pose='0 0 0.05 0 0 0'/>
        <geometry>
          <cylinder radius='0.05' length='0.1'/>
        </geometry>
      </collision>

      <visual name='arm_shoulder_pan_geom_visual'>
        <origin pose='0 0 0.05 0 0 0'/>
        <geometry>
          <cylinder radius='0.05' length='0.1'/>
        </geometry>
        <material script='Gazebo/Yellow'/>
      </visual>

      <collision name='arm_shoulder_pan_geom_arm_shoulder' >
        <origin pose='0.55 0 0.05 0 0 0'/>
        <geometry>
          <box size='1.0 0.05 0.1'/>
        </geometry>
      </collision>

      <visual name='arm_shoulder_pan_geom_arm_shoulder_visual'>
        <origin pose='0.55 0 0.05 0 0 0'/>
        <geometry>
          <box size='1.0 0.05 0.1'/>
        </geometry>
        <material script='Gazebo/Yellow'/>
      </visual>
    </link>

    <link name='arm_elbow_pan'>
      <origin pose='1.05 0 1.1 0 0 0'/>
      <inertial mass='1.2'>
        <origin pose='0.0875 0 0.083333 0 0 0'/>
        <inertia ixx='0.031' ixy='0' ixz='0.005' iyy='0.07275' iyz='0' izz='0.04475'/>
      </inertial>
      <collision name='arm_elbow_pan_geom' >
        <origin pose='0 0 0.1 0 0 0'/>
        <geometry>
          <cylinder radius='0.05' length='0.2'/>
        </geometry>
      </collision>

      <visual name='arm_elbow_pan_geom_visual'>
        <origin pose='0 0 0.1 0 0 0'/>
        <geometry>
          <cylinder radius='0.05' length='0.2'/>
        </geometry>
        <material script='Gazebo/Red'/>
      </visual>

      <collision name='arm_elbow_pan_geom_arm_elbow'>
        <origin pose='0.3 0 0.15 0 0 0'/>
        <geometry>
          <box size='0.5 0.03 0.1'/>
        </geometry>
      </collision>

      <visual name='arm_elbow_pan_geom_arm_elbow_visual'>
        <origin pose='0.3 0 0.15 0 0 0'/>
        <geometry>
          <box size='0.5 0.03 0.1'/>
        </geometry>
        <material script='Gazebo/Yellow'/>
      </visual>

      <collision name='arm_elbow_pan_geom_arm_wrist'>
        <origin pose='0.55 0 0.15 0 0 0'/>
        <geometry>
          <cylinder radius='0.05' length='0.3'/>
        </geometry>
      </collision>

      <visual name='arm_elbow_pan_geom_arm_wrist_visual'>
        <origin pose='0.55 0 0.15 0 0 0'/>
        <geometry>
          <cylinder radius='0.05' length='0.3'/>
        </geometry>
        <material script='Gazebo/Red'/>
      </visual>
    </link>

    <link name='arm_wrist_lift'>
      <origin pose='1.6 0 1.05 0 0 0'/>
      <inertial mass='0.1'>
        <origin pose='0 0 0 0 0 0'/>
        <inertia ixx='0.01' ixy='0' ixz='0' iyy='0.01' iyz='0' izz='0.001'/>
      </inertial>
      <collision name='arm_wrist_lift_geom'>
        <origin pose='0 0 0.5 0 0 0'/>
        <geometry>
          <cylinder radius='0.03' length='1.0'/>
        </geometry>
      </collision>

      <visual name='arm_wrist_lift_geom_visual'>
        <origin pose='0 0 0.5 0 0 0'/>
        <geometry>
          <cylinder radius='0.03' length='1.0'/>
        </geometry>
        <material script='Gazebo/Yellow'/>
      </visual>
    </link>

    <link name='arm_wrist_roll'>
      <origin pose='1.6 0 1.0 0 0 0'/>
      <inertial mass='0.1'>
        <origin pose='0 0 0 0 0 0'/>
        <inertia ixx='0.01' ixy='0' ixz='0' iyy='0.01' iyz='0' izz='0.001'/>
      </inertial>
      <collision name='arm_wrist_roll_geom'>
        <origin pose='0 0 0.025 0 0 0'/>
        <geometry>
          <cylinder radius='0.05' length='0.05'/>
        </geometry>
      </collision>

      <visual name='arm_wrist_roll_geom_visual'>
        <origin pose='0 0 0.025 0 0 0'/>
        <geometry>
          <cylinder radius='0.05' length='0.05'/>
        </geometry>
        <material script='Gazebo/Red'/>
      </visual>
    </link>

    <joint name='arm_base_joint' type='revolute'>
      <parent link='world'/>
      <child link='arm_base'/>
      <axis xyz='0 0 1'>
        <limit lower='0' upper='0'/>
      </axis>
    </joint>

    <joint name='arm_shoulder_pan_joint' type='revolute'>
      <parent link='world'/>
      <child link='arm_shoulder_pan'/>
      <axis xyz='0 0 1'/>
    </joint>

    <joint name='arm_elbow_pan_joint' type='revolute'>
      <parent link='arm_shoulder_pan'/>
      <child link='arm_elbow_pan'/>
      <axis xyz='0 0 1'/>
    </joint>

    <joint name='arm_wrist_lift_joint' type='prismatic'>
      <parent link='arm_elbow_pan'/>
      <child link='arm_wrist_lift'/>
      <axis xyz='0 0 1'>
        <limit lower='-0.8' upper='0.1'/>
      </axis>
    </joint>

    <joint name='arm_wrist_roll_joint' type='revolute'>
      <parent link='arm_wrist_lift'/>
      <child link='arm_wrist_roll'/>
      <axis xyz='0 0 1'>
        <limit lower='-2.999994' upper='2.999994'/>
      </axis>
    </joint>

    <plugin name="simple_arm_plugin" filename="libSimpleArmPlugin.so">
      <joint1>arm_base_joint</joint1>
      <joint2>arm_shoulder_pan_joint</joint2>
      <joint3>arm_elbow_pan_joint</joint3>
      <joint4>arm_wrist_lift_joint</joint4>
      <joint5>arm_wrist_roll_joint</joint5>
      <joint1_pid>1 0.01 0.1</joint1_pid>
      <joint2_pid>1 0.01 0.1</joint2_pid>
      <joint3_pid>1 0.01 0.1</joint3_pid>
      <joint4_pid>20 0.05 0.5</joint4_pid>
      <joint5_pid>1 0.01 0.1</joint5_pid>
      <joint1_ilim>-1 1</joint1_ilim>
      <joint2_ilim>-1 1</joint2_ilim>
      <joint3_ilim>-1 1</joint3_ilim>
      <joint4_ilim>-10 10</joint4_ilim>
      <joint5_ilim>-1 1</joint5_ilim>
    </plugin>
  </model>
</gazebo>
