<gazebo version='1.0'>
  <model name='simple_arm' static='0'>
    <origin pose='0.000000 0.000000 0.000000 0.000000 -0.000000 0.000000'/>
    <link name='arm_base' gravity='1' self_collide='0' kinematic='0'>
      <origin pose='0.000000 0.000000 0.000000 0.000000 -0.000000 0.000000'/>
      <inertial mass='101.000000'>
        <origin pose='0.000000 0.000000 0.000990 0.000000 -0.000000 0.000000'/>
        <inertia ixx='1.110000' ixy='0.000000' ixz='0.000000' iyy='100.110000' iyz='0.000000' izz='1.010000'/>
      </inertial>
      <collision name='arm_base_geom' laser_retro='0.000000'>
        <origin pose='0.000000 0.000000 0.050000 0.000000 -0.000000 0.000000'/>
        <geometry>
          <box size='1.000000 1.000000 0.100000'/>
        </geometry>
        <surface>
          <friction>
            <ode mu='-1.000000' mu2='-1.000000' fdir1='0.000000 0.000000 0.000000' slip1='0.000000' slip2='0.000000'/>
          </friction>
          <bounce restitution_coefficient='0.000000' threshold='100000.000000'/>
          <contact>
            <ode soft_cfm='0.000000' soft_erp='0.200000' kp='1000000000000.000000' kd='1.000000' max_vel='100.000000' min_depth='0.000000'/>
          </contact>
        </surface>
      </collision>
      <visual name='arm_base_geom_visual' cast_shadows='1' laser_retro='0.000000' transparency='0.000000'>
        <origin pose='0.000000 0.000000 0.050000 0.000000 -0.000000 0.000000'/>
        <geometry>
          <box size='1.000000 1.000000 0.100000'/>
        </geometry>
        <material script='Gazebo/Blue'/>
      </visual>
      <collision name='arm_base_geom_arm_trunk' laser_retro='0.000000'>
        <origin pose='0.000000 0.000000 0.600000 0.000000 -0.000000 0.000000'/>
        <geometry>
          <cylinder radius='0.050000' length='1.000000'/>
        </geometry>
        <surface>
          <friction>
            <ode mu='-1.000000' mu2='-1.000000' fdir1='0.000000 0.000000 0.000000' slip1='0.000000' slip2='0.000000'/>
          </friction>
          <bounce restitution_coefficient='0.000000' threshold='100000.000000'/>
          <contact>
            <ode soft_cfm='0.000000' soft_erp='0.200000' kp='1000000000000.000000' kd='1.000000' max_vel='100.000000' min_depth='0.000000'/>
          </contact>
        </surface>
      </collision>
      <visual name='arm_base_geom_arm_trunk_visual' cast_shadows='1' laser_retro='0.000000' transparency='0.000000'>
        <origin pose='0.000000 0.000000 0.600000 0.000000 -0.000000 0.000000'/>
        <geometry>
          <cylinder radius='0.050000' length='1.000000'/>
        </geometry>
        <material script='Gazebo/Red'/>
      </visual>
    </link>
    <link name='arm_shoulder_pan' gravity='1' self_collide='0' kinematic='0'>
      <origin pose='0.000000 0.000000 1.100000 0.000000 -0.000000 0.000000'/>
      <inertial mass='0.100000'>
        <origin pose='0.000000 0.000000 0.000000 0.000000 -0.000000 0.000000'/>
        <inertia ixx='0.010000' ixy='0.000000' ixz='0.000000' iyy='0.010000' iyz='0.000000' izz='0.001000'/>
      </inertial>
      <collision name='arm_shoulder_pan_geom' laser_retro='0.000000'>
        <origin pose='0.000000 0.000000 0.050000 0.000000 -0.000000 0.000000'/>
        <geometry>
          <cylinder radius='0.050000' length='0.100000'/>
        </geometry>
        <surface>
          <friction>
            <ode mu='-1.000000' mu2='-1.000000' fdir1='0.000000 0.000000 0.000000' slip1='0.000000' slip2='0.000000'/>
          </friction>
          <bounce restitution_coefficient='0.000000' threshold='100000.000000'/>
          <contact>
            <ode soft_cfm='0.000000' soft_erp='0.200000' kp='1000000000000.000000' kd='1.000000' max_vel='100.000000' min_depth='0.000000'/>
          </contact>
        </surface>
      </collision>
      <visual name='arm_shoulder_pan_geom_visual' cast_shadows='1' laser_retro='0.000000' transparency='0.000000'>
        <origin pose='0.000000 0.000000 0.050000 0.000000 -0.000000 0.000000'/>
        <geometry>
          <cylinder radius='0.050000' length='0.100000'/>
        </geometry>
        <material script='Gazebo/Yellow'/>
      </visual>
    </link>
    <link name='arm_shoulder' gravity='1' self_collide='0' kinematic='0'>
      <origin pose='0.050000 0.000000 1.100000 0.000000 -0.000000 0.000000'/>
      <inertial mass='1.000000'>
        <origin pose='0.000000 0.000000 0.000000 0.000000 -0.000000 0.000000'/>
        <inertia ixx='0.001000' ixy='0.000000' ixz='0.000000' iyy='0.010000' iyz='0.000000' izz='0.010000'/>
      </inertial>
      <collision name='arm_shoulder_geom' laser_retro='0.000000'>
        <origin pose='0.500000 0.000000 0.050000 0.000000 -0.000000 0.000000'/>
        <geometry>
          <box size='1.000000 0.050000 0.100000'/>
        </geometry>
        <surface>
          <friction>
            <ode mu='-1.000000' mu2='-1.000000' fdir1='0.000000 0.000000 0.000000' slip1='0.000000' slip2='0.000000'/>
          </friction>
          <bounce restitution_coefficient='0.000000' threshold='100000.000000'/>
          <contact>
            <ode soft_cfm='0.000000' soft_erp='0.200000' kp='1000000000000.000000' kd='1.000000' max_vel='100.000000' min_depth='0.000000'/>
          </contact>
        </surface>
      </collision>
      <visual name='arm_shoulder_geom_visual' cast_shadows='1' laser_retro='0.000000' transparency='0.000000'>
        <origin pose='0.500000 0.000000 0.050000 0.000000 -0.000000 0.000000'/>
        <geometry>
          <box size='1.000000 0.050000 0.100000'/>
        </geometry>
        <material script='Gazebo/Yellow'/>
      </visual>
    </link>
    <link name='arm_elbow_pan' gravity='1' self_collide='0' kinematic='0'>
      <origin pose='1.050000 0.000000 1.100000 0.000000 -0.000000 0.000000'/>
      <inertial mass='0.100000'>
        <origin pose='0.000000 0.000000 0.000000 0.000000 -0.000000 0.000000'/>
        <inertia ixx='0.010000' ixy='0.000000' ixz='0.000000' iyy='0.010000' iyz='0.000000' izz='0.001000'/>
      </inertial>
      <collision name='arm_elbow_pan_geom' laser_retro='0.000000'>
        <origin pose='0.000000 0.000000 0.100000 0.000000 -0.000000 0.000000'/>
        <geometry>
          <cylinder radius='0.050000' length='0.200000'/>
        </geometry>
        <surface>
          <friction>
            <ode mu='-1.000000' mu2='-1.000000' fdir1='0.000000 0.000000 0.000000' slip1='0.000000' slip2='0.000000'/>
          </friction>
          <bounce restitution_coefficient='0.000000' threshold='100000.000000'/>
          <contact>
            <ode soft_cfm='0.000000' soft_erp='0.200000' kp='1000000000000.000000' kd='1.000000' max_vel='100.000000' min_depth='0.000000'/>
          </contact>
        </surface>
      </collision>
      <visual name='arm_elbow_pan_geom_visual' cast_shadows='1' laser_retro='0.000000' transparency='0.000000'>
        <origin pose='0.000000 0.000000 0.100000 0.000000 -0.000000 0.000000'/>
        <geometry>
          <cylinder radius='0.050000' length='0.200000'/>
        </geometry>
        <material script='Gazebo/Red'/>
      </visual>
    </link>
    <link name='arm_elbow' gravity='1' self_collide='0' kinematic='0'>
      <origin pose='1.100000 0.000000 1.200000 0.000000 -0.000000 0.000000'/>
      <inertial mass='1.100000'>
        <origin pose='0.045455 0.000000 -0.009091 0.000000 -0.000000 0.000000'/>
        <inertia ixx='0.012000' ixy='0.000000' ixz='0.005000' iyy='0.046000' iyz='0.000000' izz='0.036000'/>
      </inertial>
      <collision name='arm_elbow_geom' laser_retro='0.000000'>
        <origin pose='0.250000 0.000000 0.050000 0.000000 -0.000000 0.000000'/>
        <geometry>
          <box size='0.500000 0.030000 0.100000'/>
        </geometry>
        <surface>
          <friction>
            <ode mu='-1.000000' mu2='-1.000000' fdir1='0.000000 0.000000 0.000000' slip1='0.000000' slip2='0.000000'/>
          </friction>
          <bounce restitution_coefficient='0.000000' threshold='100000.000000'/>
          <contact>
            <ode soft_cfm='0.000000' soft_erp='0.200000' kp='1000000000000.000000' kd='1.000000' max_vel='100.000000' min_depth='0.000000'/>
          </contact>
        </surface>
      </collision>
      <visual name='arm_elbow_geom_visual' cast_shadows='1' laser_retro='0.000000' transparency='0.000000'>
        <origin pose='0.250000 0.000000 0.050000 0.000000 -0.000000 0.000000'/>
        <geometry>
          <box size='0.500000 0.030000 0.100000'/>
        </geometry>
        <material script='Gazebo/Yellow'/>
      </visual>
      <collision name='arm_elbow_geom_arm_wrist' laser_retro='0.000000'>
        <origin pose='0.500000 0.000000 0.050000 0.000000 -0.000000 0.000000'/>
        <geometry>
          <cylinder radius='0.050000' length='0.300000'/>
        </geometry>
        <surface>
          <friction>
            <ode mu='-1.000000' mu2='-1.000000' fdir1='0.000000 0.000000 0.000000' slip1='0.000000' slip2='0.000000'/>
          </friction>
          <bounce restitution_coefficient='0.000000' threshold='100000.000000'/>
          <contact>
            <ode soft_cfm='0.000000' soft_erp='0.200000' kp='1000000000000.000000' kd='1.000000' max_vel='100.000000' min_depth='0.000000'/>
          </contact>
        </surface>
      </collision>
      <visual name='arm_elbow_geom_arm_wrist_visual' cast_shadows='1' laser_retro='0.000000' transparency='0.000000'>
        <origin pose='0.500000 0.000000 0.050000 0.000000 -0.000000 0.000000'/>
        <geometry>
          <cylinder radius='0.050000' length='0.300000'/>
        </geometry>
        <material script='Gazebo/Red'/>
      </visual>
    </link>
    <link name='arm_wrist_lift' gravity='1' self_collide='0' kinematic='0'>
      <origin pose='1.600000 0.000000 1.050000 0.000000 -0.000000 0.000000'/>
      <inertial mass='0.100000'>
        <origin pose='0.000000 0.000000 0.000000 0.000000 -0.000000 0.000000'/>
        <inertia ixx='0.010000' ixy='0.000000' ixz='0.000000' iyy='0.010000' iyz='0.000000' izz='0.001000'/>
      </inertial>
      <collision name='arm_wrist_lift_geom' laser_retro='0.000000'>
        <origin pose='0.000000 0.000000 0.150000 0.000000 -0.000000 0.000000'/>
        <geometry>
          <cylinder radius='0.030000' length='0.300000'/>
        </geometry>
        <surface>
          <friction>
            <ode mu='-1.000000' mu2='-1.000000' fdir1='0.000000 0.000000 0.000000' slip1='0.000000' slip2='0.000000'/>
          </friction>
          <bounce restitution_coefficient='0.000000' threshold='100000.000000'/>
          <contact>
            <ode soft_cfm='0.000000' soft_erp='0.200000' kp='1000000000000.000000' kd='1.000000' max_vel='100.000000' min_depth='0.000000'/>
          </contact>
        </surface>
      </collision>
      <visual name='arm_wrist_lift_geom_visual' cast_shadows='1' laser_retro='0.000000' transparency='0.000000'>
        <origin pose='0.000000 0.000000 0.150000 0.000000 -0.000000 0.000000'/>
        <geometry>
          <cylinder radius='0.030000' length='0.300000'/>
        </geometry>
        <material script='Gazebo/Yellow'/>
      </visual>
    </link>
    <link name='arm_wrist_roll' gravity='1' self_collide='0' kinematic='0'>
      <origin pose='1.600000 0.000000 1.000000 0.000000 -0.000000 0.000000'/>
      <inertial mass='0.100000'>
        <origin pose='0.000000 0.000000 0.000000 0.000000 -0.000000 0.000000'/>
        <inertia ixx='0.010000' ixy='0.000000' ixz='0.000000' iyy='0.010000' iyz='0.000000' izz='0.001000'/>
      </inertial>
      <collision name='arm_wrist_roll_geom' laser_retro='0.000000'>
        <origin pose='0.000000 0.000000 0.025000 0.000000 -0.000000 0.000000'/>
        <geometry>
          <cylinder radius='0.050000' length='0.050000'/>
        </geometry>
        <surface>
          <friction>
            <ode mu='-1.000000' mu2='-1.000000' fdir1='0.000000 0.000000 0.000000' slip1='0.000000' slip2='0.000000'/>
          </friction>
          <bounce restitution_coefficient='0.000000' threshold='100000.000000'/>
          <contact>
            <ode soft_cfm='0.000000' soft_erp='0.200000' kp='1000000000000.000000' kd='1.000000' max_vel='100.000000' min_depth='0.000000'/>
          </contact>
        </surface>
      </collision>
      <visual name='arm_wrist_roll_geom_visual' cast_shadows='1' laser_retro='0.000000' transparency='0.000000'>
        <origin pose='0.000000 0.000000 0.025000 0.000000 -0.000000 0.000000'/>
        <geometry>
          <cylinder radius='0.050000' length='0.050000'/>
        </geometry>
        <material script='Gazebo/Red'/>
      </visual>
    </link>
    <joint name='arm_base_joint' type='revolute'>
      <origin pose='0.000000 0.000000 0.000000 0.000000 -0.000000 0.000000'/>
      <parent link='world'/>
      <child link='arm_base'/>
      <axis xyz='0.000000 0.000000 1.000000'>
        <dynamics damping='0.000000' friction='0.000000'/>
        <limit lower='0.000000' upper='0.000000' effort='0.000000' velocity='0.000000'/>
      </axis>
    </joint>
    <joint name='arm_shoulder_pan_joint' type='revolute'>
      <origin pose='0.000000 0.000000 0.000000 0.000000 -0.000000 0.000000'/>
      <parent link='world'/>
      <child link='arm_shoulder_pan'/>
      <axis xyz='1.000000 0.000000 0.000000'>
        <dynamics damping='0.000000' friction='0.000000'/>
        <limit lower='-10000000000000000.000000' upper='10000000000000000.000000' effort='0.000000' velocity='0.000000'/>
      </axis>
    </joint>
    <joint name='arm_shoulder_joint' type='revolute'>
      <origin pose='0.000000 0.000000 0.000000 0.000000 -0.000000 0.000000'/>
      <parent link='arm_shoulder_pan'/>
      <child link='arm_shoulder'/>
      <axis xyz='1.000000 0.000000 0.000000'>
        <dynamics damping='0.000000' friction='0.000000'/>
        <limit lower='-10000000000000000.000000' upper='10000000000000000.000000' effort='0.000000' velocity='0.000000'/>
      </axis>
    </joint>
    <joint name='arm_elbow_pan_joint' type='revolute'>
      <origin pose='0.000000 0.000000 0.000000 0.000000 -0.000000 0.000000'/>
      <parent link='arm_shoulder'/>
      <child link='arm_elbow_pan'/>
      <axis xyz='1.000000 0.000000 0.000000'>
        <dynamics damping='0.000000' friction='0.000000'/>
        <limit lower='-10000000000000000.000000' upper='10000000000000000.000000' effort='0.000000' velocity='0.000000'/>
      </axis>
    </joint>
    <joint name='arm_elbow_joint' type='revolute'>
      <origin pose='0.000000 0.000000 0.000000 0.000000 -0.000000 0.000000'/>
      <parent link='arm_elbow_pan'/>
      <child link='arm_elbow'/>
      <axis xyz='1.000000 0.000000 0.000000'>
        <dynamics damping='0.000000' friction='0.000000'/>
        <limit lower='-10000000000000000.000000' upper='10000000000000000.000000' effort='0.000000' velocity='0.000000'/>
      </axis>
    </joint>
    <joint name='arm_wrist_lift_joint' type='prismatic'>
      <origin pose='0.000000 0.000000 0.000000 0.000000 -0.000000 0.000000'/>
      <parent link='arm_elbow'/>
      <child link='arm_wrist_lift'/>
      <axis xyz='0.000000 0.000000 1.000000'>
        <dynamics damping='0.000000' friction='0.000000'/>
        <limit lower='-0.100000' upper='0.100000' effort='0.000000' velocity='0.000000'/>
      </axis>
    </joint>
    <joint name='arm_wrist_roll_joint' type='revolute'>
      <origin pose='0.000000 0.000000 0.000000 0.000000 -0.000000 0.000000'/>
      <parent link='arm_wrist_lift'/>
      <child link='arm_wrist_roll'/>
      <axis xyz='0.000000 0.000000 1.000000'>
        <dynamics damping='0.000000' friction='0.000000'/>
        <limit lower='-2.999994' upper='2.999994' effort='0.000000' velocity='0.000000'/>
      </axis>
    </joint>
  </model>
</gazebo>
