<gazebo version='1.0'>
  <model name='youbot' static='0'>
    <origin pose='0.000000 0.000000 0.083637 0.000000 -0.000000 0.000000'/>
    <link name='base_footprint' gravity='1' self_collide='0' kinematic='0'>
      <origin pose='0.000000 0.000000 0.000000 0.000000 -0.000000 0.000000'/>
      <inertial mass='0.100000'>
        <origin pose='0.000000 0.000000 -0.050000 0.000000 -0.000000 0.000000'/>
        <inertia ixx='1.000000' ixy='0.000000' ixz='0.000000' iyy='1.000000' iyz='0.000000' izz='1.000000'/>
      </inertial>
      <collision name='base_footprint_geom' laser_retro='0.000000'>
        <origin pose='0.000000 0.000000 -0.050000 0.000000 -0.000000 0.000000'/>
        <geometry>
          <box size='0.001000 0.001000 0.001000'/>
        </geometry>
        <surface>
          <friction>
            <ode mu='0.000000' mu2='0.000000' fdir1='0.000000 0.000000 0.000000' slip1='0.000000' slip2='0.000000'/>
          </friction>
          <bounce restitution_coefficient='0.000000' threshold='0.000000'/>
          <contact>
            <ode soft_cfm='0.000000' soft_erp='0.200000' kp='10000000000000.000000' kd='100000000000.000000' max_vel='-1.000000' min_depth='0.000000'/>
          </contact>
        </surface>
      </collision>
      <visual name='base_footprint_geom_visual' cast_shadows='1' laser_retro='0.000000' transparency='0.000000'>
        <origin pose='0.000000 0.000000 0.000000 0.000000 -0.000000 0.000000'/>
        <geometry>
          <box size='0.001000 0.001000 0.001000'/>
        </geometry>
      </visual>
    </link>
    <link name='base_link' gravity='1' self_collide='0' kinematic='0'>
      <origin pose='0.000000 0.000000 0.000000 0.000000 -0.000000 0.000000'/>
      <inertial mass='22.000000'>
        <origin pose='0.000000 0.000000 0.000000 0.000000 -0.000000 0.000000'/>
        <inertia ixx='5.652230' ixy='-0.009720' ixz='1.293990' iyy='5.669470' iyz='-0.007380' izz='3.683200'/>
      </inertial>
      <collision name='base_link_geom' laser_retro='0.000000'>
        <origin pose='0.000000 0.000000 0.000000 0.000000 -0.000000 0.000000'/>
        <geometry>
          <mesh filename='youbot/base/base_convex.stl' scale='1.000000 1.000000 1.000000'/>
        </geometry>
        <surface>
          <friction>
            <ode mu='0.000000' mu2='0.000000' fdir1='0.000000 0.000000 0.000000' slip1='0.000000' slip2='0.000000'/>
          </friction>
          <bounce restitution_coefficient='0.000000' threshold='0.000000'/>
          <contact>
            <ode soft_cfm='0.000000' soft_erp='0.200000' kp='10000000000000.000000' kd='100000000000.000000' max_vel='-1.000000' min_depth='0.000000'/>
          </contact>
        </surface>
      </collision>
      <visual name='base_link_geom_visual' cast_shadows='1' laser_retro='0.000000' transparency='0.000000'>
        <origin pose='0.000000 0.000000 0.000000 0.000000 -0.000000 0.000000'/>
        <geometry>
          <mesh filename='youbot/base/base.dae' scale='1.000000 1.000000 1.000000'/>
        </geometry>
      </visual>
    </link>
    <link name='arm_link_0' gravity='1' self_collide='0' kinematic='0'>
      <origin pose='0.143000 0.000000 0.046000 0.000000 -0.000000 0.000000'/>
      <inertial mass='0.845000'>
        <origin pose='0.000000 0.000000 0.000000 0.000000 -0.000000 0.000000'/>
        <inertia ixx='0.010000' ixy='0.000000' ixz='0.000000' iyy='0.010000' iyz='0.000000' izz='0.010000'/>
      </inertial>
      <collision name='arm_link_0_geom' laser_retro='0.000000'>
        <origin pose='0.000000 0.000000 0.000000 0.000000 -0.000000 0.000000'/>
        <geometry>
          <mesh filename='youbot/arm/arm0_convex.stl' scale='1.000000 1.000000 1.000000'/>
        </geometry>
        <surface>
          <friction>
            <ode mu='0.000000' mu2='0.000000' fdir1='0.000000 0.000000 0.000000' slip1='0.000000' slip2='0.000000'/>
          </friction>
          <bounce restitution_coefficient='0.000000' threshold='0.000000'/>
          <contact>
            <ode soft_cfm='0.000000' soft_erp='0.200000' kp='10000000000000.000000' kd='100000000000.000000' max_vel='-1.000000' min_depth='0.000000'/>
          </contact>
        </surface>
      </collision>
      <visual name='arm_link_0_geom_visual' cast_shadows='1' laser_retro='0.000000' transparency='0.000000'>
        <origin pose='0.000000 0.000000 0.000000 0.000000 -0.000000 0.000000'/>
        <geometry>
          <mesh filename='youbot/arm/arm0.dae' scale='1.000000 1.000000 1.000000'/>
        </geometry>
        <material script='youbot/DarkGrey'/>
      </visual>
    </link>
    <link name='arm_link_1' gravity='1' self_collide='0' kinematic='0'>
      <origin pose='0.167000 0.000000 0.142000 0.000000 -0.000000 2.967060'/>
      <inertial mass='2.412000'>
        <origin pose='0.014890 0.002130 0.002130 0.000000 -0.000000 0.000000'/>
        <inertia ixx='0.003863' ixy='-0.000979' ixz='0.000000' iyy='0.006196' iyz='0.000000' izz='0.006369'/>
      </inertial>
      <collision name='arm_link_1_geom' laser_retro='0.000000'>
        <origin pose='0.000000 0.000000 0.000000 0.000000 -0.000000 0.000000'/>
        <geometry>
          <mesh filename='youbot/arm/arm1_convex.stl' scale='1.000000 1.000000 1.000000'/>
        </geometry>
        <surface>
          <friction>
            <ode mu='0.000000' mu2='0.000000' fdir1='0.000000 0.000000 0.000000' slip1='0.000000' slip2='0.000000'/>
          </friction>
          <bounce restitution_coefficient='0.000000' threshold='0.000000'/>
          <contact>
            <ode soft_cfm='0.000000' soft_erp='0.200000' kp='10000000000000.000000' kd='100000000000.000000' max_vel='-1.000000' min_depth='0.000000'/>
          </contact>
        </surface>
      </collision>
      <visual name='arm_link_1_geom_visual' cast_shadows='1' laser_retro='0.000000' transparency='0.000000'>
        <origin pose='0.000000 0.000000 0.000000 0.000000 -0.000000 0.000000'/>
        <geometry>
          <mesh filename='youbot/arm/arm1.dae' scale='1.000000 1.000000 1.000000'/>
        </geometry>
      </visual>
    </link>
    <link name='arm_link_2' gravity='1' self_collide='0' kinematic='0'>
      <origin pose='0.134501 0.005730 0.161000 0.000000 -1.134460 2.967060'/>
      <inertial mass='1.155000'>
        <origin pose='0.104530 0.001700 -0.002970 0.000000 -0.000000 0.000000'/>
        <inertia ixx='0.000823' ixy='0.000000' ixz='-0.000000' iyy='0.004447' iyz='0.000000' izz='0.004439'/>
      </inertial>
      <collision name='arm_link_2_geom' laser_retro='0.000000'>
        <origin pose='0.000000 -0.032000 0.078000 0.000000 -0.000000 0.000000'/>
        <geometry>
          <mesh filename='youbot/arm/arm2_convex.stl' scale='1.000000 1.000000 1.000000'/>
        </geometry>
        <surface>
          <friction>
            <ode mu='0.000000' mu2='0.000000' fdir1='0.000000 0.000000 0.000000' slip1='0.000000' slip2='0.000000'/>
          </friction>
          <bounce restitution_coefficient='0.000000' threshold='0.000000'/>
          <contact>
            <ode soft_cfm='0.000000' soft_erp='0.200000' kp='10000000000000.000000' kd='100000000000.000000' max_vel='-1.000000' min_depth='0.000000'/>
          </contact>
        </surface>
      </collision>
      <visual name='arm_link_2_geom_visual' cast_shadows='1' laser_retro='0.000000' transparency='0.000000'>
        <origin pose='0.000000 -0.032000 0.078000 0.000000 -0.000000 0.000000'/>
        <geometry>
          <mesh filename='youbot/arm/arm2.dae' scale='1.000000 1.000000 1.000000'/>
        </geometry>
      </visual>
    </link>
    <link name='arm_link_3' gravity='1' self_collide='0' kinematic='0'>
      <origin pose='0.272845 -0.018663 0.226506 -0.000000 1.413720 2.967060'/>
      <inertial mass='0.934000'>
        <origin pose='0.000100 0.096700 0.021070 0.000000 -0.000000 0.000000'/>
        <inertia ixx='0.002459' ixy='0.000000' ixz='0.000000' iyy='0.002571' iyz='-0.000000' izz='0.000535'/>
      </inertial>
      <collision name='arm_link_3_geom' laser_retro='0.000000'>
        <origin pose='0.000000 0.028000 0.079000 0.000000 -0.000000 0.000000'/>
        <geometry>
          <mesh filename='youbot/arm/arm3_convex.stl' scale='1.000000 1.000000 1.000000'/>
        </geometry>
        <surface>
          <friction>
            <ode mu='0.000000' mu2='0.000000' fdir1='0.000000 0.000000 0.000000' slip1='0.000000' slip2='0.000000'/>
          </friction>
          <bounce restitution_coefficient='0.000000' threshold='0.000000'/>
          <contact>
            <ode soft_cfm='0.000000' soft_erp='0.200000' kp='10000000000000.000000' kd='100000000000.000000' max_vel='-1.000000' min_depth='0.000000'/>
          </contact>
        </surface>
      </collision>
      <visual name='arm_link_3_geom_visual' cast_shadows='1' laser_retro='0.000000' transparency='0.000000'>
        <origin pose='0.000000 0.028000 0.079000 0.000000 -0.000000 0.000000'/>
        <geometry>
          <mesh filename='youbot/arm/arm3.dae' scale='1.000000 1.000000 1.000000'/>
        </geometry>
      </visual>
    </link>
    <link name='arm_link_4' gravity='1' self_collide='0' kinematic='0'>
      <origin pose='0.141533 0.004491 0.247624 -0.000000 -0.375246 2.967060'/>
      <inertial mass='0.877000'>
        <origin pose='0.000110 0.051030 -0.023190 0.000000 -0.000000 0.000000'/>
        <inertia ixx='0.000869' ixy='0.000000' ixz='-0.000000' iyy='0.001173' iyz='-0.000231' izz='0.001091'/>
      </inertial>
      <collision name='arm_link_4_geom' laser_retro='0.000000'>
        <origin pose='0.000000 -0.010000 0.029000 0.000000 -0.000000 0.000000'/>
        <geometry>
          <mesh filename='youbot/arm/arm4_convex.stl' scale='1.000000 1.000000 1.000000'/>
        </geometry>
        <surface>
          <friction>
            <ode mu='0.000000' mu2='0.000000' fdir1='0.000000 0.000000 0.000000' slip1='0.000000' slip2='0.000000'/>
          </friction>
          <bounce restitution_coefficient='0.000000' threshold='0.000000'/>
          <contact>
            <ode soft_cfm='0.000000' soft_erp='0.200000' kp='10000000000000.000000' kd='100000000000.000000' max_vel='-1.000000' min_depth='0.000000'/>
          </contact>
        </surface>
      </collision>
      <visual name='arm_link_4_geom_visual' cast_shadows='1' laser_retro='0.000000' transparency='0.000000'>
        <origin pose='0.000000 -0.010000 0.029000 0.000000 -0.000000 0.000000'/>
        <geometry>
          <mesh filename='youbot/arm/arm4.dae' scale='1.000000 1.000000 1.000000'/>
        </geometry>
      </visual>
    </link>
    <link name='arm_link_5' gravity='1' self_collide='0' kinematic='0'>
      <origin pose='0.190287 -0.004106 0.367846 -0.085052 0.365926 -0.408445'/>
      <inertial mass='0.251000'>
        <origin pose='0.000000 0.001150 -0.016830 0.000000 -0.000000 0.000000'/>
        <inertia ixx='0.000280' ixy='0.000000' ixz='0.000000' iyy='0.000339' iyz='0.000000' izz='0.000119'/>
      </inertial>
      <collision name='arm_link_5_geom' laser_retro='0.000000'>
        <origin pose='0.003000 0.000000 -0.034000 0.000000 -0.000000 0.000000'/>
        <geometry>
          <mesh filename='youbot/arm/arm5_convex.stl' scale='1.000000 1.000000 1.000000'/>
        </geometry>
        <surface>
          <friction>
            <ode mu='0.000000' mu2='0.000000' fdir1='0.000000 0.000000 0.000000' slip1='0.000000' slip2='0.000000'/>
          </friction>
          <bounce restitution_coefficient='0.000000' threshold='0.000000'/>
          <contact>
            <ode soft_cfm='0.000000' soft_erp='0.200000' kp='10000000000000.000000' kd='100000000000.000000' max_vel='-1.000000' min_depth='0.000000'/>
          </contact>
        </surface>
      </collision>
      <visual name='arm_link_5_geom_visual' cast_shadows='1' laser_retro='0.000000' transparency='0.000000'>
        <origin pose='0.003000 0.000000 -0.034000 0.000000 -0.000000 0.000000'/>
        <geometry>
          <mesh filename='youbot/arm/arm5.dae' scale='1.000000 1.000000 1.000000'/>
        </geometry>
      </visual>
    </link>
    <link name='gripper_palm_link' gravity='1' self_collide='1' kinematic='0'>
      <origin pose='0.190287 -0.004106 0.367846 -0.085052 0.365926 -0.408445'/>
      <inertial mass='0.100000'>
        <origin pose='0.000000 0.000000 0.000000 0.000000 -0.000000 0.000000'/>
        <inertia ixx='0.010000' ixy='0.000000' ixz='0.000000' iyy='0.010000' iyz='0.000000' izz='0.010000'/>
      </inertial>
      <collision name='gripper_palm_link_geom' laser_retro='0.000000'>
        <origin pose='0.000000 0.000000 0.000000 0.000000 -0.000000 0.000000'/>
        <geometry>
          <mesh filename='youbot/gripper/palm_convex.stl' scale='1.000000 1.000000 1.000000'/>
        </geometry>
        <surface>
          <friction>
            <ode mu='0.000000' mu2='0.000000' fdir1='0.000000 0.000000 0.000000' slip1='0.000000' slip2='0.000000'/>
          </friction>
          <bounce restitution_coefficient='0.000000' threshold='0.000000'/>
          <contact>
            <ode soft_cfm='0.000000' soft_erp='0.200000' kp='10000000000000.000000' kd='100000000000.000000' max_vel='-1.000000' min_depth='0.000000'/>
          </contact>
        </surface>
      </collision>
      <visual name='gripper_palm_link_geom_visual' cast_shadows='1' laser_retro='0.000000' transparency='0.000000'>
        <origin pose='0.000000 0.000000 0.000000 0.000000 -0.000000 0.000000'/>
        <geometry>
          <mesh filename='youbot/gripper/palm.stl' scale='1.000000 1.000000 1.000000'/>
        </geometry>
        <material script='Gazebo/Black'/>
      </visual>
    </link>
    <link name='gripper_finger_link_l' gravity='1' self_collide='0' kinematic='0'>
      <origin pose='0.213260 -0.001105 0.408579 0.085052 -0.365926 2.733150'/>
      <inertial mass='0.010000'>
        <origin pose='0.000000 -0.001000 0.000000 0.000000 -0.000000 0.000000'/>
        <inertia ixx='0.010000' ixy='0.000000' ixz='0.000000' iyy='0.010000' iyz='0.000000' izz='0.010000'/>
      </inertial>
      <collision name='gripper_finger_link_l_geom' laser_retro='0.000000'>
        <origin pose='0.000000 0.000000 0.000000 0.000000 -0.000000 0.000000'/>
        <geometry>
          <mesh filename='youbot/gripper/finger_convex.stl' scale='1.000000 1.000000 1.000000'/>
        </geometry>
        <surface>
          <friction>
            <ode mu='0.000000' mu2='0.000000' fdir1='0.000000 0.000000 0.000000' slip1='0.000000' slip2='0.000000'/>
          </friction>
          <bounce restitution_coefficient='0.000000' threshold='0.000000'/>
          <contact>
            <ode soft_cfm='0.000000' soft_erp='0.200000' kp='10000000000000.000000' kd='100000000000.000000' max_vel='-1.000000' min_depth='0.000000'/>
          </contact>
        </surface>
      </collision>
      <visual name='gripper_finger_link_l_geom_visual' cast_shadows='1' laser_retro='0.000000' transparency='0.000000'>
        <origin pose='0.000000 0.000000 0.000000 0.000000 -0.000000 0.000000'/>
        <geometry>
          <mesh filename='youbot/gripper/finger.stl' scale='1.000000 1.000000 1.000000'/>
        </geometry>
      </visual>
    </link>
    <link name='gripper_finger_link_r' gravity='1' self_collide='0' kinematic='0'>
      <origin pose='0.207375 -0.015929 0.409848 -0.085052 0.365926 -0.408445'/>
      <inertial mass='0.010000'>
        <origin pose='0.000000 -0.001000 0.000000 0.000000 -0.000000 0.000000'/>
        <inertia ixx='0.010000' ixy='0.000000' ixz='0.000000' iyy='0.010000' iyz='0.000000' izz='0.010000'/>
      </inertial>
      <collision name='gripper_finger_link_r_geom' laser_retro='0.000000'>
        <origin pose='0.000000 0.000000 0.000000 0.000000 -0.000000 0.000000'/>
        <geometry>
          <mesh filename='youbot/gripper/finger_convex.stl' scale='1.000000 1.000000 1.000000'/>
        </geometry>
        <surface>
          <friction>
            <ode mu='0.000000' mu2='0.000000' fdir1='0.000000 0.000000 0.000000' slip1='0.000000' slip2='0.000000'/>
          </friction>
          <bounce restitution_coefficient='0.000000' threshold='0.000000'/>
          <contact>
            <ode soft_cfm='0.000000' soft_erp='0.200000' kp='10000000000000.000000' kd='100000000000.000000' max_vel='-1.000000' min_depth='0.000000'/>
          </contact>
        </surface>
      </collision>
      <visual name='gripper_finger_link_r_geom_visual' cast_shadows='1' laser_retro='0.000000' transparency='0.000000'>
        <origin pose='0.000000 0.000000 0.000000 0.000000 -0.000000 0.000000'/>
        <geometry>
          <mesh filename='youbot/gripper/finger.stl' scale='1.000000 1.000000 1.000000'/>
        </geometry>
      </visual>
    </link>
    <link name='base_laser_front_link' gravity='1' self_collide='0' kinematic='0'>
      <origin pose='0.300000 0.000000 -0.030000 0.000000 -0.000000 0.000000'/>
      <inertial mass='0.160000'>
        <origin pose='0.000000 0.000000 0.000000 0.000000 -0.000000 0.000000'/>
        <inertia ixx='0.100000' ixy='0.000000' ixz='0.000000' iyy='0.100000' iyz='0.000000' izz='0.100000'/>
      </inertial>
      <collision name='base_laser_front_link_geom' laser_retro='0.000000'>
        <origin pose='0.000000 0.000000 0.000000 0.000000 -0.000000 0.000000'/>
        <geometry>
          <mesh filename='hokuyo/hokuyo_convex.stl' scale='1.000000 1.000000 1.000000'/>
        </geometry>
        <surface>
          <friction>
            <ode mu='0.000000' mu2='0.000000' fdir1='0.000000 0.000000 0.000000' slip1='0.000000' slip2='0.000000'/>
          </friction>
          <bounce restitution_coefficient='0.000000' threshold='0.000000'/>
          <contact>
            <ode soft_cfm='0.000000' soft_erp='0.200000' kp='10000000000000.000000' kd='100000000000.000000' max_vel='-1.000000' min_depth='0.000000'/>
          </contact>
        </surface>
      </collision>
      <visual name='base_laser_front_link_geom_visual' cast_shadows='1' laser_retro='0.000000' transparency='0.000000'>
        <origin pose='0.000000 0.000000 0.000000 0.000000 -0.000000 0.000000'/>
        <geometry>
          <mesh filename='hokuyo/hokuyo.dae' scale='1.000000 1.000000 1.000000'/>
        </geometry>
      </visual>
      <sensor name='base_laser_front' type='ray' always_on='0' update_rate='10.000000' visualize='0'>
        <origin pose='0.000000 0.000000 0.000000 0.000000 -0.000000 0.000000'/>
        <ray>
          <scan>
            <horizontal samples='640' resolution='1.000000' min_angle='-1.570000' max_angle='1.570000'/>
          </scan>
          <range min='0.050000' max='5.600000' resolution='0.360000'/>
        </ray>
      </sensor>
    </link>
    <link name='caster_link_bl' gravity='1' self_collide='0' kinematic='0'>
      <origin pose='-0.228000 0.158000 -0.034000 0.000000 -0.000000 0.000000'/>
      <inertial mass='0.100000'>
        <origin pose='0.000000 0.000000 0.000000 0.000000 -0.000000 0.000000'/>
        <inertia ixx='0.012412' ixy='-0.000712' ixz='0.000503' iyy='0.015218' iyz='-0.000004' izz='0.011764'/>
      </inertial>
    </link>
    <link name='wheel_link_bl' gravity='1' self_collide='0' kinematic='0'>
      <origin pose='-0.228000 0.158000 -0.034000 0.000000 -0.000000 0.000000'/>
      <inertial mass='0.400000'>
        <origin pose='0.000000 0.000000 0.000000 0.000000 -0.000000 0.000000'/>
        <inertia ixx='0.012412' ixy='-0.000712' ixz='0.000503' iyy='0.015218' iyz='-0.000004' izz='0.011764'/>
      </inertial>
      <collision name='wheel_link_bl_geom' laser_retro='0.000000'>
        <origin pose='0.000000 0.000000 0.000000 1.570800 -0.000000 0.000000'/>
        <geometry>
          <cylinder radius='0.050000' length='0.005000'/>
        </geometry>
        <surface>
          <friction>
            <ode mu='0.000000' mu2='0.000000' fdir1='0.000000 0.000000 0.000000' slip1='0.000000' slip2='0.000000'/>
          </friction>
          <bounce restitution_coefficient='0.000000' threshold='0.000000'/>
          <contact>
            <ode soft_cfm='0.000000' soft_erp='0.200000' kp='10000000000000.000000' kd='100000000000.000000' max_vel='-1.000000' min_depth='0.000000'/>
          </contact>
        </surface>
      </collision>
      <visual name='wheel_link_bl_geom_visual' cast_shadows='1' laser_retro='0.000000' transparency='0.000000'>
        <origin pose='0.000000 0.000000 0.000000 0.000000 -0.000000 0.000000'/>
        <geometry>
          <sphere radius='0.025000'/>
        </geometry>
        <material script='youbot/Orange'/>
      </visual>
    </link>
    <link name='caster_link_br' gravity='1' self_collide='0' kinematic='0'>
      <origin pose='-0.228000 -0.158000 -0.034000 0.000000 -0.000000 0.000000'/>
      <inertial mass='0.100000'>
        <origin pose='0.000000 0.000000 0.000000 0.000000 -0.000000 0.000000'/>
        <inertia ixx='0.012412' ixy='-0.000712' ixz='0.000503' iyy='0.015218' iyz='-0.000004' izz='0.011764'/>
      </inertial>
    </link>
    <link name='wheel_link_br' gravity='1' self_collide='0' kinematic='0'>
      <origin pose='-0.228000 -0.158000 -0.034000 0.000000 -0.000000 0.000000'/>
      <inertial mass='0.400000'>
        <origin pose='0.000000 0.000000 0.000000 0.000000 -0.000000 0.000000'/>
        <inertia ixx='0.012412' ixy='-0.000712' ixz='0.000503' iyy='0.015218' iyz='-0.000004' izz='0.011764'/>
      </inertial>
      <collision name='wheel_link_br_geom' laser_retro='0.000000'>
        <origin pose='0.000000 0.000000 0.000000 1.570800 -0.000000 0.000000'/>
        <geometry>
          <cylinder radius='0.050000' length='0.005000'/>
        </geometry>
        <surface>
          <friction>
            <ode mu='0.000000' mu2='0.000000' fdir1='0.000000 0.000000 0.000000' slip1='0.000000' slip2='0.000000'/>
          </friction>
          <bounce restitution_coefficient='0.000000' threshold='0.000000'/>
          <contact>
            <ode soft_cfm='0.000000' soft_erp='0.200000' kp='10000000000000.000000' kd='100000000000.000000' max_vel='-1.000000' min_depth='0.000000'/>
          </contact>
        </surface>
      </collision>
      <visual name='wheel_link_br_geom_visual' cast_shadows='1' laser_retro='0.000000' transparency='0.000000'>
        <origin pose='0.000000 0.000000 0.000000 0.000000 -0.000000 0.000000'/>
        <geometry>
          <sphere radius='0.025000'/>
        </geometry>
        <material script='youbot/Orange'/>
      </visual>
    </link>
    <link name='caster_link_fl' gravity='1' self_collide='0' kinematic='0'>
      <origin pose='0.228000 0.158000 -0.034000 0.000000 -0.000000 0.000000'/>
      <inertial mass='0.100000'>
        <origin pose='0.000000 0.000000 0.000000 0.000000 -0.000000 0.000000'/>
        <inertia ixx='0.012412' ixy='-0.000712' ixz='0.000503' iyy='0.015218' iyz='-0.000004' izz='0.011764'/>
      </inertial>
    </link>
    <link name='wheel_link_fl' gravity='1' self_collide='0' kinematic='0'>
      <origin pose='0.228000 0.158000 -0.034000 0.000000 -0.000000 0.000000'/>
      <inertial mass='0.400000'>
        <origin pose='0.000000 0.000000 0.000000 0.000000 -0.000000 0.000000'/>
        <inertia ixx='0.012412' ixy='-0.000712' ixz='0.000503' iyy='0.015218' iyz='-0.000004' izz='0.011764'/>
      </inertial>
      <collision name='wheel_link_fl_geom' laser_retro='0.000000'>
        <origin pose='0.000000 0.000000 0.000000 1.570800 -0.000000 0.000000'/>
        <geometry>
          <cylinder radius='0.050000' length='0.005000'/>
        </geometry>
        <surface>
          <friction>
            <ode mu='0.000000' mu2='0.000000' fdir1='0.000000 0.000000 0.000000' slip1='0.000000' slip2='0.000000'/>
          </friction>
          <bounce restitution_coefficient='0.000000' threshold='0.000000'/>
          <contact>
            <ode soft_cfm='0.000000' soft_erp='0.200000' kp='10000000000000.000000' kd='100000000000.000000' max_vel='-1.000000' min_depth='0.000000'/>
          </contact>
        </surface>
      </collision>
      <visual name='wheel_link_fl_geom_visual' cast_shadows='1' laser_retro='0.000000' transparency='0.000000'>
        <origin pose='0.000000 0.000000 0.000000 0.000000 -0.000000 0.000000'/>
        <geometry>
          <sphere radius='0.025000'/>
        </geometry>
        <material script='youbot/Orange'/>
      </visual>
    </link>
    <link name='caster_link_fr' gravity='1' self_collide='0' kinematic='0'>
      <origin pose='0.228000 -0.158000 -0.034000 0.000000 -0.000000 0.000000'/>
      <inertial mass='0.100000'>
        <origin pose='0.000000 0.000000 0.000000 0.000000 -0.000000 0.000000'/>
        <inertia ixx='0.012412' ixy='-0.000712' ixz='0.000503' iyy='0.015218' iyz='-0.000004' izz='0.011764'/>
      </inertial>
    </link>
    <link name='wheel_link_fr' gravity='1' self_collide='0' kinematic='0'>
      <origin pose='0.228000 -0.158000 -0.034000 0.000000 -0.000000 0.000000'/>
      <inertial mass='0.400000'>
        <origin pose='0.000000 0.000000 0.000000 0.000000 -0.000000 0.000000'/>
        <inertia ixx='0.012412' ixy='-0.000712' ixz='0.000503' iyy='0.015218' iyz='-0.000004' izz='0.011764'/>
      </inertial>
      <collision name='wheel_link_fr_geom' laser_retro='0.000000'>
        <origin pose='0.000000 0.000000 0.000000 1.570800 -0.000000 0.000000'/>
        <geometry>
          <cylinder radius='0.050000' length='0.005000'/>
        </geometry>
        <surface>
          <friction>
            <ode mu='0.000000' mu2='0.000000' fdir1='0.000000 0.000000 0.000000' slip1='0.000000' slip2='0.000000'/>
          </friction>
          <bounce restitution_coefficient='0.000000' threshold='0.000000'/>
          <contact>
            <ode soft_cfm='0.000000' soft_erp='0.200000' kp='10000000000000.000000' kd='100000000000.000000' max_vel='-1.000000' min_depth='0.000000'/>
          </contact>
        </surface>
      </collision>
      <visual name='wheel_link_fr_geom_visual' cast_shadows='1' laser_retro='0.000000' transparency='0.000000'>
        <origin pose='0.000000 0.000000 0.000000 0.000000 -0.000000 0.000000'/>
        <geometry>
          <sphere radius='0.025000'/>
        </geometry>
        <material script='youbot/Orange'/>
      </visual>
    </link>
    <link name='plate_link' gravity='1' self_collide='0' kinematic='0'>
      <origin pose='-0.159000 0.000000 0.046000 0.000000 -0.000000 0.000000'/>
      <inertial mass='1.000000'>
        <origin pose='0.000000 0.000000 0.000000 0.000000 -0.000000 0.000000'/>
        <inertia ixx='0.010000' ixy='0.000000' ixz='0.000000' iyy='0.010000' iyz='0.000000' izz='0.010000'/>
      </inertial>
      <collision name='plate_link_geom' laser_retro='0.000000'>
        <origin pose='0.000000 0.000000 0.000000 0.000000 -0.000000 0.000000'/>
        <geometry>
          <mesh filename='youbot/plate/plate_convex.stl' scale='1.000000 1.000000 1.000000'/>
        </geometry>
        <surface>
          <friction>
            <ode mu='0.000000' mu2='0.000000' fdir1='0.000000 0.000000 0.000000' slip1='0.000000' slip2='0.000000'/>
          </friction>
          <bounce restitution_coefficient='0.000000' threshold='0.000000'/>
          <contact>
            <ode soft_cfm='0.000000' soft_erp='0.200000' kp='10000000000000.000000' kd='100000000000.000000' max_vel='-1.000000' min_depth='0.000000'/>
          </contact>
        </surface>
      </collision>
      <visual name='plate_link_geom_visual' cast_shadows='1' laser_retro='0.000000' transparency='0.000000'>
        <origin pose='0.000000 0.000000 0.000000 0.000000 -0.000000 0.000000'/>
        <geometry>
          <mesh filename='youbot/plate/plate.dae' scale='1.000000 1.000000 1.000000'/>
        </geometry>
      </visual>
    </link>
    <joint name='base_footprint_joint' type='revolute'>
      <origin pose='0.000000 0.000000 0.000000 0.000000 -0.000000 0.000000'/>
      <parent link='base_footprint'/>
      <child link='base_link'/>
      <axis xyz='0.000000 0.000000 1.000000'>
        <dynamics damping='0.000000' friction='0.000000'/>
        <limit lower='0.000000' upper='0.000000' effort='0.000000' velocity='0.000000'/>
      </axis>
    </joint>
    <joint name='arm_joint_0' type='revolute'>
      <origin pose='0.000000 0.000000 0.000000 0.000000 -0.000000 0.000000'/>
      <parent link='base_link'/>
      <child link='arm_link_0'/>
      <axis xyz='0.000000 0.000000 1.000000'>
        <dynamics damping='0.000000' friction='0.000000'/>
        <limit lower='0.000000' upper='0.000000' effort='0.000000' velocity='0.000000'/>
      </axis>
    </joint>
    <joint name='arm_joint_1' type='revolute'>
      <origin pose='0.000000 0.000000 0.000000 0.000000 -0.000000 0.000000'/>
      <parent link='arm_link_0'/>
      <child link='arm_link_1'/>
      <axis xyz='0.000000 0.000000 -1.000000'>
        <dynamics damping='1.000000' friction='0.000000'/>
        <limit lower='0.000000' upper='5.899213' effort='0.000000' velocity='0.000000'/>
      </axis>
    </joint>
    <joint name='arm_joint_2' type='revolute'>
      <origin pose='0.000000 0.000000 0.000000 0.000000 -0.000000 0.000000'/>
      <parent link='arm_link_1'/>
      <child link='arm_link_2'/>
      <axis xyz='-0.173648 -0.984808 0.000000'>
        <dynamics damping='1.000000' friction='0.000000'/>
        <limit lower='0.000000' upper='2.705260' effort='0.000000' velocity='0.000000'/>
      </axis>
    </joint>
    <joint name='arm_joint_3' type='revolute'>
      <origin pose='0.000000 0.000000 0.000000 0.000000 -0.000000 0.000000'/>
      <parent link='arm_link_2'/>
      <child link='arm_link_3'/>
      <axis xyz='-0.173648 -0.984808 0.000000'>
        <dynamics damping='1.000000' friction='0.000000'/>
        <limit lower='-5.183628' upper='0.000000' effort='0.000000' velocity='0.000000'/>
      </axis>
    </joint>
    <joint name='arm_joint_4' type='revolute'>
      <origin pose='0.000000 0.000000 0.000000 0.000000 -0.000000 0.000000'/>
      <parent link='arm_link_3'/>
      <child link='arm_link_4'/>
      <axis xyz='-0.173648 -0.984808 0.000000'>
        <dynamics damping='1.000000' friction='0.000000'/>
        <limit lower='0.000000' upper='3.577925' effort='0.000000' velocity='0.000000'/>
      </axis>
    </joint>
    <joint name='arm_joint_5' type='revolute'>
      <origin pose='0.000000 0.000000 0.000000 0.000000 -0.000000 0.000000'/>
      <parent link='arm_link_4'/>
      <child link='arm_link_5'/>
      <axis xyz='-0.360933 0.063642 -0.930418'>
        <dynamics damping='1.000000' friction='0.000000'/>
        <limit lower='0.000000' upper='5.846853' effort='0.000000' velocity='0.000000'/>
      </axis>
    </joint>
    <joint name='gripper_palm_joint' type='revolute'>
      <origin pose='0.000000 0.000000 0.000000 0.000000 -0.000000 0.000000'/>
      <parent link='arm_link_5'/>
      <child link='gripper_palm_link'/>
      <axis xyz='0.000000 0.000000 1.000000'>
        <dynamics damping='0.000000' friction='0.000000'/>
        <limit lower='0.000000' upper='0.000000' effort='0.000000' velocity='0.000000'/>
      </axis>
    </joint>
    <joint name='gripper_finger_joint_l' type='prismatic'>
      <origin pose='0.000000 0.000000 0.000000 0.000000 -0.000000 0.000000'/>
      <parent link='gripper_palm_link'/>
      <child link='gripper_finger_link_l'/>
      <axis xyz='0.367852 0.926495 -0.079325'>
        <dynamics damping='1.000000' friction='0.000000'/>
        <limit lower='0.000000' upper='0.011500' effort='0.000000' velocity='0.000000'/>
      </axis>
    </joint>
    <joint name='gripper_finger_joint_r' type='prismatic'>
      <origin pose='0.000000 0.000000 0.000000 0.000000 -0.000000 0.000000'/>
      <parent link='gripper_palm_link'/>
      <child link='gripper_finger_link_r'/>
      <axis xyz='-0.367852 -0.926495 0.079325'>
        <dynamics damping='1.000000' friction='0.000000'/>
        <limit lower='0.000000' upper='0.011500' effort='0.000000' velocity='0.000000'/>
      </axis>
    </joint>
    <joint name='base_laser_front_hokuyo_urg04_laser_joint' type='revolute'>
      <origin pose='0.000000 0.000000 0.000000 0.000000 -0.000000 0.000000'/>
      <parent link='base_link'/>
      <child link='base_laser_front_link'/>
      <axis xyz='0.000000 0.000000 1.000000'>
        <dynamics damping='0.000000' friction='0.000000'/>
        <limit lower='0.000000' upper='0.000000' effort='0.000000' velocity='0.000000'/>
      </axis>
    </joint>
    <joint name='caster_joint_bl' type='revolute'>
      <origin pose='0.000000 0.000000 0.000000 0.000000 -0.000000 0.000000'/>
      <parent link='base_link'/>
      <child link='caster_link_bl'/>
      <axis xyz='0.000000 0.000000 1.000000'>
        <dynamics damping='1.000000' friction='0.000000'/>
        <limit lower='-10000000000000000.000000' upper='10000000000000000.000000' effort='0.000000' velocity='0.000000'/>
      </axis>
    </joint>
    <joint name='wheel_joint_bl' type='revolute'>
      <origin pose='0.000000 0.000000 0.000000 0.000000 -0.000000 0.000000'/>
      <parent link='caster_link_bl'/>
      <child link='wheel_link_bl'/>
      <axis xyz='0.000000 1.000000 0.000000'>
        <dynamics damping='1.000000' friction='0.000000'/>
        <limit lower='-10000000000000000.000000' upper='10000000000000000.000000' effort='0.000000' velocity='0.000000'/>
      </axis>
    </joint>
    <joint name='caster_joint_br' type='revolute'>
      <origin pose='0.000000 0.000000 0.000000 0.000000 -0.000000 0.000000'/>
      <parent link='base_link'/>
      <child link='caster_link_br'/>
      <axis xyz='0.000000 0.000000 1.000000'>
        <dynamics damping='1.000000' friction='0.000000'/>
        <limit lower='-10000000000000000.000000' upper='10000000000000000.000000' effort='0.000000' velocity='0.000000'/>
      </axis>
    </joint>
    <joint name='wheel_joint_br' type='revolute'>
      <origin pose='0.000000 0.000000 0.000000 0.000000 -0.000000 0.000000'/>
      <parent link='caster_link_br'/>
      <child link='wheel_link_br'/>
      <axis xyz='0.000000 1.000000 0.000000'>
        <dynamics damping='1.000000' friction='0.000000'/>
        <limit lower='-10000000000000000.000000' upper='10000000000000000.000000' effort='0.000000' velocity='0.000000'/>
      </axis>
    </joint>
    <joint name='caster_joint_fl' type='revolute'>
      <origin pose='0.000000 0.000000 0.000000 0.000000 -0.000000 0.000000'/>
      <parent link='base_link'/>
      <child link='caster_link_fl'/>
      <axis xyz='0.000000 0.000000 1.000000'>
        <dynamics damping='1.000000' friction='0.000000'/>
        <limit lower='-10000000000000000.000000' upper='10000000000000000.000000' effort='0.000000' velocity='0.000000'/>
      </axis>
    </joint>
    <joint name='wheel_joint_fl' type='revolute'>
      <origin pose='0.000000 0.000000 0.000000 0.000000 -0.000000 0.000000'/>
      <parent link='caster_link_fl'/>
      <child link='wheel_link_fl'/>
      <axis xyz='0.000000 1.000000 0.000000'>
        <dynamics damping='1.000000' friction='0.000000'/>
        <limit lower='-10000000000000000.000000' upper='10000000000000000.000000' effort='0.000000' velocity='0.000000'/>
      </axis>
    </joint>
    <joint name='caster_joint_fr' type='revolute'>
      <origin pose='0.000000 0.000000 0.000000 0.000000 -0.000000 0.000000'/>
      <parent link='base_link'/>
      <child link='caster_link_fr'/>
      <axis xyz='0.000000 0.000000 1.000000'>
        <dynamics damping='1.000000' friction='0.000000'/>
        <limit lower='-10000000000000000.000000' upper='10000000000000000.000000' effort='0.000000' velocity='0.000000'/>
      </axis>
    </joint>
    <joint name='wheel_joint_fr' type='revolute'>
      <origin pose='0.000000 0.000000 0.000000 0.000000 -0.000000 0.000000'/>
      <parent link='caster_link_fr'/>
      <child link='wheel_link_fr'/>
      <axis xyz='0.000000 1.000000 0.000000'>
        <dynamics damping='1.000000' friction='0.000000'/>
        <limit lower='-10000000000000000.000000' upper='10000000000000000.000000' effort='0.000000' velocity='0.000000'/>
      </axis>
    </joint>
    <joint name='plate_joint' type='revolute'>
      <origin pose='0.000000 0.000000 0.000000 0.000000 -0.000000 0.000000'/>
      <parent link='base_link'/>
      <child link='plate_link'/>
      <axis xyz='0.000000 0.000000 1.000000'>
        <dynamics damping='0.000000' friction='0.000000'/>
        <limit lower='0.000000' upper='0.000000' effort='0.000000' velocity='0.000000'/>
      </axis>
    </joint>
  </model>
</gazebo>
