<?xml version="1.0" ?>
<sdf version="1.4">
    <world name="default">
        <include>
            <uri>model://sun</uri>
        </include>
        <physics type="dart">
            <gravity>0 -9.81 0</gravity>
        </physics>
        <!--include><uri>model://ground_plane</uri></include-->
        <!-- 25.3kg total mass -->
        <model name="test_model">
            <pose>0 0 0 0 0 0</pose>
            <link name="link1">
                <pose>1 2 3 0.1 0 0</pose>
                <inertial>
                    <inertia>
                        <ixx>1</ixx>
                        <ixy>0</ixy>
                        <ixz>0</ixz>
                        <iyy>2</iyy>
                        <iyz>0</iyz>
                        <izz>3</izz>
                    </inertia>
                    <mass>5.0</mass>
                </inertial>
                <visual name="visual">
                    <pose>0 0 0 0 0 0</pose>
                    <geometry>
                        <box>
                            <size>0.2 0.4 0.6</size>
                        </box>
                    </geometry>
                    <material>
                        <script>Gazebo/WoodPallet</script>
                    </material>
                </visual>
            </link>
            <joint name="joint01" type="ball">
                <pose>0 0 0 -0.1 0 0</pose>
                <parent>
                    <link_name>world</link_name>
                </parent>
                <child>
                    <link_name>link1</link_name>
                </child>
            </joint>
        </model>
    </world>
</sdf>
