<?xml version="1.0" ?>
<sdf version="1.6">
  <world name="default">
    <include>
      <uri>model://ground_plane</uri>
    </include>
    <include>
      <uri>model://sun</uri>
    </include>

    <model name="box">
      <allow_auto_disable>0</allow_auto_disable>
      <pose>0 0 1.5 0 0 0</pose>
      <link name="link">
        <inertial>
          <mass>0.2</mass>
          <inertia>
            <ixx>0.0333333</ixx>
            <ixy>0</ixy>
            <ixz>0</ixz>
            <iyy>0.0333333</iyy>
            <iyz>0</iyz>
            <izz>0.0333333</izz>
          </inertia>
        </inertial>
        <collision name="collision">
          <geometry>
            <box>
              <size>1 1 1</size>
            </box>
          </geometry>
        </collision>
        <visual name="visual">
          <geometry>
            <box>
              <size>1 1 1</size>
            </box>
          </geometry>
        </visual>
      </link>

      <plugin filename="libHarnessPlugin.so" name="harness">
        <!-- This plugin creates a special link, with the name specified in
             <harness_link_name>, that is fixed to the world. Use this name
             when creating a joint in this world. See below for an example.
        -->
        <harness_link_name>harness_link</harness_link_name>

        <!-- Pose of the harness link, in this model's frame -->
        <harness_link_pose>0 0 2 0 0 0</harness_link_pose>

        <joint name="joint1" type="prismatic">
          <pose>0 0 0 0 0 0</pose>
          <!-- This name matches <harness_link_name> above. -->
          <parent>harness_link</parent>
          <child>link</child>
          <axis>
            <xyz>0 0 1</xyz>
            <dynamics>
              <damping>10</damping>
            </dynamics>
            <limit>
              <lower>-0.5</lower>
              <upper>0</upper>
              <effort>10000</effort>
              <velocity>-1</velocity>
              <stiffness>0</stiffness>
              <dissipation>0</dissipation>
            </limit>
          </axis>
          <physics>
            <ode>
              <implicit_spring_damper>1</implicit_spring_damper>
              <limit>
                <cfm>0.0</cfm>
                <erp>0.0</erp>
              </limit>
            </ode>
          </physics>
        </joint>

        <!-- The joint that raises or lowers the harness -->
        <winch>
          <!-- This must be a joint specified within
               the body of this plugin. -->
          <joint>joint1</joint>

          <!-- PID value for velocity control of the winch. These values
               are tuned to work with this box model. -->
          <pid>
            <p>400</p>
            <i>0</i>
            <d>0</d>
          </pid>
        </winch>

        <!-- Joint to detach. Once the joint is detached, it cannot be
             reattached. This must be a joint specified within the
             body of this plugin. -->
        <detach>joint1</detach>
      </plugin>
    </model>

  </world>
</sdf>
