<?xml version="1.0" ?>
<sdf version="1.6">
  <world name="default">
    <include>
      <uri>model://ground_plane</uri>
    </include>
    <include>
      <uri>model://sun</uri>
    </include>

    <model name="box">
      <pose>0 0 1.5 0 0 0</pose>
      <link name="link">
        <collision name="collision">
          <geometry>
            <box>
              <size>1 1 1</size>
            </box>
          </geometry>
        </collision>
        <visual name="visual">
          <geometry>
            <box>
              <size>1 1 1</size>
            </box>
          </geometry>
        </visual>
      </link>

      <plugin filename="libHarnessPlugin.so" name="harness">
        <!-- This plugin creates a special link, with the name specified in
             <harness_link_name>, that is fixed to the world. Use this name
             when creating a joint in this world. See below for an example.
        -->
        <harness_link_name>harness_link</harness_link_name>

        <joint name="joint1" type="prismatic">
          <pose>0 0 0 0 0 0</pose>
          <!-- This name matches <harness_link_name> above. -->
          <parent>harness_link</parent>
          <child>link</child>
          <axis>
            <xyz>0 0 1</xyz>
            <dynamics>
              <damping>0</damping>
            </dynamics>
            <limit>
              <lower>-0.5</lower>
              <upper>0</upper>
              <effort>0</effort>
              <velocity>0</velocity>
              <stiffness>0</stiffness>
              <dissipation>0</dissipation>
            </limit>
          </axis>
        </joint>

        <!-- The joint that raises or lowers the harness -->
        <winch>
          <!-- This must be a joint specified within
               the body of this plugin. -->
          <joint>joint1</joint>

          <!-- PID value for velocity control of the winch -->
          <pid>
            <p>10000</p>
            <i>0</i>
            <d>10</d>
          </pid>
        </winch>

        <!-- Joint to detach. Once the joint is detached, it cannot be
             reattached. This must be a joint specified within the
             body of this plugin. -->
        <detach>joint1</detach>
      </plugin>
    </model>

  </world>
</sdf>
