<?xml version="1.0" ?>

<sdf version="1.5">
  <world name="default">
    <include>
      <uri>model://ground_plane</uri>
    </include>
    <include>
      <uri>model://sun</uri>
    </include>


    <model name="peg1">
      <static>true</static>
      <link name="link">
        <pose> 0 0.6 0.3 0 0 0</pose>
        <self_collide>0</self_collide>
        <visual name="vis_peg">
          <pose>0 0 0 0 0 0</pose>
          <geometry>
            <cylinder>
              <radius>0.03</radius>
              <length>0.6</length>
            </cylinder>
          </geometry>
          <material>
            <script>
              <uri>file://media/materials/scripts/gazebo.material</uri>
              <name>Gazebo/Wood</name>
           </script>
          </material>
        </visual>
        <collision name="col_peg">
          <pose>0 0 0 0 0 0</pose>
          <geometry>
            <cylinder>
              <radius>0.03</radius>
              <length>0.6</length>
            </cylinder>
          </geometry>
          <surface>
            <contact>
              <ode>
                <min_depth>0.001</min_depth>
                <max_vel>0.1</max_vel>
                <kp>1e8</kp>
                <kd>1</kd>
              </ode>
            </contact>
          </surface>
        </collision>
      </link>
    </model>

    <model name="peg2">
      <static>true</static>
      <link name="link">
        <pose>0 0.3 0.6 1.5707963267948966 0 0</pose>
        <self_collide>0</self_collide>
        <visual name="vis_peg2">
          <pose>0 0 0 0 0 0</pose>
          <geometry>
            <cylinder>
              <radius>0.03</radius>
              <length>0.6</length>
            </cylinder>
          </geometry>
          <material>
            <script>
              <uri>file://media/materials/scripts/gazebo.material</uri>
              <name>Gazebo/Wood</name>
           </script>
          </material>
        </visual>
        <collision name="col_peg2">
          <pose>0.0 0.0 0.0 0 0 0</pose>
          <geometry>
            <cylinder>
              <radius>0.03</radius>
              <length>0.6</length>
            </cylinder>
          </geometry>
          <surface>
            <contact>
              <ode>
                <min_depth>0.001</min_depth>
                <max_vel>0.1</max_vel>
                <kp>1e8</kp>
                <kd>1</kd>
              </ode>
            </contact>
          </surface>
        </collision>
      </link>
    </model>

    <model name="barlayer_0">

      <link name="link_0">
        <pose>0 0 0.53 1.5707963267948966 0 0</pose>
        <inertial>
          <mass>0.10602875205865551</mass>
          <inertia>
            <ixx>0.0022095950142556895</ixx>
            <iyy>0.0022095950142556895</iyy>
            <izz>1.325359400733194e-06</izz>
            <ixy>0.0</ixy>
            <ixz>0.0</ixz>
            <iyz>0.0</iyz>
          </inertia>
        </inertial>
        <collision name="collision">
          <geometry>
            <cylinder>
              <radius>0.005</radius>
              <length>0.5</length>
            </cylinder>
          </geometry>
          <surface>
            <contact>
              <ode>
                <min_depth>0.001</min_depth>
                <max_vel>0.1</max_vel>
                <kp>1e8</kp>
                <kd>1</kd>
              </ode>
            </contact>
          </surface>
        </collision>
        <visual name="visual">
          <geometry>
            <cylinder>
              <radius>0.005</radius>
              <length>0.5</length>
            </cylinder>
          </geometry>
          <material>
            <script>
              <uri>file://media/materials/scripts/gazebo.material</uri>
              <name>Gazebo/Red</name>
            </script>
          </material>
        </visual>
      </link>
      <link name="linkvert_0">
        <pose>0 0 0.555  0 0 0 </pose>
        <inertial>
          <mass>0.010602875205865553</mass>
          <inertia>
            <ixx>2.275200304591984e-06</ixx>
            <iyy>2.275200304591984e-06</iyy>
            <izz>1.3253594007331942e-07</izz>
            <ixy>0.0</ixy>
            <ixz>0.0</ixz>
            <iyz>0.0</iyz>
          </inertia>
        </inertial>
        <collision name="collision">
          <geometry>
            <cylinder>
              <radius>0.005</radius>
              <length>0.05</length>
            </cylinder>
          </geometry>
          <surface>
            <contact>
              <ode>
                <min_depth>0.001</min_depth>
                <max_vel>0.1</max_vel>
                <kp>1e8</kp>
                <kd>1</kd>
              </ode>
            </contact>
          </surface>
        </collision>
        <visual name="visual">
          <geometry>
            <cylinder>
              <radius>0.005</radius>
              <length>0.05</length>
            </cylinder>
          </geometry>
          <material>
            <script>
              <uri>file://media/materials/scripts/gazebo.material</uri>
              <name>Gazebo/Yellow</name>
            </script>
          </material>
        </visual>
      </link>

        <joint name="vertChild_0" type="ball">
          <pose>0 0 0.53 0 0 0</pose>
          <parent>linkvert_0</parent>
          <child>link_0</child>
          <thread_pitch>-0.1</thread_pitch>
          <axis>
            <xyz>0 0 1</xyz>
            <limit>
              <upper>1.7</upper>
              <lower>-1.7</lower>
              <stiffness>1e6</stiffness>
              <dissipation>1.0</dissipation>
            </limit>
            <dynamics>
              <damping>0.1</damping>
           </dynamics>
          </axis>
          <physics>
            <ode>
              <cfm_damping>1</cfm_damping>
            </ode>
          </physics>
        </joint>
        <joint name="vertParent_0" type="revolute">
          <pose>0 0 0.5800000000000001 0 0 0 </pose>
          <parent>peg2</parent>
          <child>linkvert_0</child>
          <axis>
            <xyz>0 0 1</xyz>
            <limit>
              <upper>0</upper>
              <lower>0</lower>
            </limit>
          </axis>
        </joint>

    </model>

    <model name="barlayer_1">

      <link name="link_1">
        <pose>0 0.25 0.48000000000000004 0 1.5707963267948966 0</pose>
        <inertial>
          <mass>0.06361725123519331</mass>
          <inertia>
            <ixx>0.0004775269920841698</ixx>
            <iyy>0.0004775269920841698</iyy>
            <izz>7.952156404399164e-07</izz>
            <ixy>0.0</ixy>
            <ixz>0.0</ixz>
            <iyz>0.0</iyz>
          </inertia>
        </inertial>
        <collision name="collision">
          <geometry>
            <cylinder>
              <radius>0.005</radius>
              <length>0.3</length>
            </cylinder>
          </geometry>
          <surface>
            <contact>
              <ode>
                <min_depth>0.001</min_depth>
                <max_vel>0.1</max_vel>
                <kp>1e8</kp>
                <kd>1</kd>
              </ode>
            </contact>
          </surface>
        </collision>
        <visual name="visual">
          <geometry>
            <cylinder>
              <radius>0.005</radius>
              <length>0.3</length>
            </cylinder>
          </geometry>
          <material>
            <script>
              <uri>file://media/materials/scripts/gazebo.material</uri>
              <name>Gazebo/Green</name>
            </script>
          </material>
        </visual>
      </link>
      <link name="linkvert_1">
        <pose>0 0.25 0.505  0 0 0 </pose>
        <inertial>
          <mass>0.010602875205865553</mass>
          <inertia>
            <ixx>2.275200304591984e-06</ixx>
            <iyy>2.275200304591984e-06</iyy>
            <izz>1.3253594007331942e-07</izz>
            <ixy>0.0</ixy>
            <ixz>0.0</ixz>
            <iyz>0.0</iyz>
          </inertia>
        </inertial>
        <collision name="collision">
          <geometry>
            <cylinder>
              <radius>0.005</radius>
              <length>0.05</length>
            </cylinder>
          </geometry>
          <surface>
            <contact>
              <ode>
                <min_depth>0.001</min_depth>
                <max_vel>0.1</max_vel>
                <kp>1e8</kp>
                <kd>1</kd>
              </ode>
            </contact>
          </surface>
        </collision>
        <visual name="visual">
          <geometry>
            <cylinder>
              <radius>0.005</radius>
              <length>0.05</length>
            </cylinder>
          </geometry>
          <material>
            <script>
              <uri>file://media/materials/scripts/gazebo.material</uri>
              <name>Gazebo/Yellow</name>
            </script>
          </material>
        </visual>
      </link>

        <joint name="vertChild_1" type="ball">
          <pose>0 0.25 0.48000000000000004 0 0 0</pose>
          <parent>linkvert_1</parent>
          <child>link_1</child>
          <thread_pitch>-0.1</thread_pitch>
          <axis>
            <xyz>0 0 1</xyz>
            <limit>
              <upper>1.7</upper>
              <lower>-1.7</lower>
              <stiffness>1e6</stiffness>
              <dissipation>1.0</dissipation>
            </limit>
            <dynamics>
              <damping>0.1</damping>
           </dynamics>
          </axis>
          <physics>
            <ode>
              <cfm_damping>1</cfm_damping>
            </ode>
          </physics>
        </joint>
        <joint name="vertParent_1" type="revolute">
          <pose>0 0.25 0.53 0 0 0 </pose>
          <parent>link_0</parent>
          <child>linkvert_1</child>
          <axis>
            <xyz>1 0 0</xyz>
            <limit>
              <upper>0</upper>
              <lower>0</lower>
            </limit>
          </axis>
        </joint>

      <link name="link_2">
        <pose>0 -0.25 0.48000000000000004 0 1.5707963267948966 0</pose>
        <inertial>
          <mass>0.06361725123519331</mass>
          <inertia>
            <ixx>0.0004775269920841698</ixx>
            <iyy>0.0004775269920841698</iyy>
            <izz>7.952156404399164e-07</izz>
            <ixy>0.0</ixy>
            <ixz>0.0</ixz>
            <iyz>0.0</iyz>
          </inertia>
        </inertial>
        <collision name="collision">
          <geometry>
            <cylinder>
              <radius>0.005</radius>
              <length>0.3</length>
            </cylinder>
          </geometry>
          <surface>
            <contact>
              <ode>
                <min_depth>0.001</min_depth>
                <max_vel>0.1</max_vel>
                <kp>1e8</kp>
                <kd>1</kd>
              </ode>
            </contact>
          </surface>
        </collision>
        <visual name="visual">
          <geometry>
            <cylinder>
              <radius>0.005</radius>
              <length>0.3</length>
            </cylinder>
          </geometry>
          <material>
            <script>
              <uri>file://media/materials/scripts/gazebo.material</uri>
              <name>Gazebo/Green</name>
            </script>
          </material>
        </visual>
      </link>
      <link name="linkvert_2">
        <pose>0 -0.25 0.505  0 0 0 </pose>
        <inertial>
          <mass>0.010602875205865553</mass>
          <inertia>
            <ixx>2.275200304591984e-06</ixx>
            <iyy>2.275200304591984e-06</iyy>
            <izz>1.3253594007331942e-07</izz>
            <ixy>0.0</ixy>
            <ixz>0.0</ixz>
            <iyz>0.0</iyz>
          </inertia>
        </inertial>
        <collision name="collision">
          <geometry>
            <cylinder>
              <radius>0.005</radius>
              <length>0.05</length>
            </cylinder>
          </geometry>
          <surface>
            <contact>
              <ode>
                <min_depth>0.001</min_depth>
                <max_vel>0.1</max_vel>
                <kp>1e8</kp>
                <kd>1</kd>
              </ode>
            </contact>
          </surface>
        </collision>
        <visual name="visual">
          <geometry>
            <cylinder>
              <radius>0.005</radius>
              <length>0.05</length>
            </cylinder>
          </geometry>
          <material>
            <script>
              <uri>file://media/materials/scripts/gazebo.material</uri>
              <name>Gazebo/Yellow</name>
            </script>
          </material>
        </visual>
      </link>

        <joint name="vertChild_2" type="ball">
          <pose>0 -0.25 0.48000000000000004 0 0 0</pose>
          <parent>linkvert_2</parent>
          <child>link_2</child>
          <thread_pitch>-0.1</thread_pitch>
          <axis>
            <xyz>0 0 1</xyz>
            <limit>
              <upper>1.7</upper>
              <lower>-1.7</lower>
              <stiffness>1e6</stiffness>
              <dissipation>1.0</dissipation>
            </limit>
            <dynamics>
              <damping>0.1</damping>
           </dynamics>
          </axis>
          <physics>
            <ode>
              <cfm_damping>1</cfm_damping>
            </ode>
          </physics>
        </joint>
        <joint name="vertParent_2" type="revolute">
          <pose>0 -0.25 0.53 0 0 0 </pose>
          <parent>link_0</parent>
          <child>linkvert_2</child>
          <axis>
            <xyz>1 0 0</xyz>
            <limit>
              <upper>0</upper>
              <lower>0</lower>
            </limit>
          </axis>
        </joint>

    </model>

    <model name="barlayer_2">

      <link name="link_3">
        <pose>0.15 0.25 0.43000000000000005 1.5707963267948966 0 0</pose>
        <inertial>
          <mass>0.03817035074111599</mass>
          <inertia>
            <ixx>0.00010329851169314512</ixx>
            <iyy>0.00010329851169314512</iyy>
            <izz>4.771293842639499e-07</izz>
            <ixy>0.0</ixy>
            <ixz>0.0</ixz>
            <iyz>0.0</iyz>
          </inertia>
        </inertial>
        <collision name="collision">
          <geometry>
            <cylinder>
              <radius>0.005</radius>
              <length>0.18</length>
            </cylinder>
          </geometry>
          <surface>
            <contact>
              <ode>
                <min_depth>0.001</min_depth>
                <max_vel>0.1</max_vel>
                <kp>1e8</kp>
                <kd>1</kd>
              </ode>
            </contact>
          </surface>
        </collision>
        <visual name="visual">
          <geometry>
            <cylinder>
              <radius>0.005</radius>
              <length>0.18</length>
            </cylinder>
          </geometry>
          <material>
            <script>
              <uri>file://media/materials/scripts/gazebo.material</uri>
              <name>Gazebo/Blue</name>
            </script>
          </material>
        </visual>
      </link>
      <link name="linkvert_3">
        <pose>0.15 0.25 0.45500000000000007  0 0 0 </pose>
        <inertial>
          <mass>0.010602875205865553</mass>
          <inertia>
            <ixx>2.275200304591984e-06</ixx>
            <iyy>2.275200304591984e-06</iyy>
            <izz>1.3253594007331942e-07</izz>
            <ixy>0.0</ixy>
            <ixz>0.0</ixz>
            <iyz>0.0</iyz>
          </inertia>
        </inertial>
        <collision name="collision">
          <geometry>
            <cylinder>
              <radius>0.005</radius>
              <length>0.05</length>
            </cylinder>
          </geometry>
          <surface>
            <contact>
              <ode>
                <min_depth>0.001</min_depth>
                <max_vel>0.1</max_vel>
                <kp>1e8</kp>
                <kd>1</kd>
              </ode>
            </contact>
          </surface>
        </collision>
        <visual name="visual">
          <geometry>
            <cylinder>
              <radius>0.005</radius>
              <length>0.05</length>
            </cylinder>
          </geometry>
          <material>
            <script>
              <uri>file://media/materials/scripts/gazebo.material</uri>
              <name>Gazebo/Yellow</name>
            </script>
          </material>
        </visual>
      </link>

        <joint name="vertChild_3" type="ball">
          <pose>0.15 0.25 0.43000000000000005 0 0 0</pose>
          <parent>linkvert_3</parent>
          <child>link_3</child>
          <thread_pitch>-0.1</thread_pitch>
          <axis>
            <xyz>0 0 1</xyz>
            <limit>
              <upper>1.7</upper>
              <lower>-1.7</lower>
              <stiffness>1e6</stiffness>
              <dissipation>1.0</dissipation>
            </limit>
            <dynamics>
              <damping>0.1</damping>
           </dynamics>
          </axis>
          <physics>
            <ode>
              <cfm_damping>1</cfm_damping>
            </ode>
          </physics>
        </joint>
        <joint name="vertParent_3" type="revolute">
          <pose>0.15 0.25 0.48000000000000004 0 0 0 </pose>
          <parent>link_1</parent>
          <child>linkvert_3</child>
          <axis>
            <xyz>1 0 0</xyz>
            <limit>
              <upper>0</upper>
              <lower>0</lower>
            </limit>
          </axis>
        </joint>

      <link name="link_4">
        <pose>-0.15 0.25 0.43000000000000005 1.5707963267948966 0 0</pose>
        <inertial>
          <mass>0.03817035074111599</mass>
          <inertia>
            <ixx>0.00010329851169314512</ixx>
            <iyy>0.00010329851169314512</iyy>
            <izz>4.771293842639499e-07</izz>
            <ixy>0.0</ixy>
            <ixz>0.0</ixz>
            <iyz>0.0</iyz>
          </inertia>
        </inertial>
        <collision name="collision">
          <geometry>
            <cylinder>
              <radius>0.005</radius>
              <length>0.18</length>
            </cylinder>
          </geometry>
          <surface>
            <contact>
              <ode>
                <min_depth>0.001</min_depth>
                <max_vel>0.1</max_vel>
                <kp>1e8</kp>
                <kd>1</kd>
              </ode>
            </contact>
          </surface>
        </collision>
        <visual name="visual">
          <geometry>
            <cylinder>
              <radius>0.005</radius>
              <length>0.18</length>
            </cylinder>
          </geometry>
          <material>
            <script>
              <uri>file://media/materials/scripts/gazebo.material</uri>
              <name>Gazebo/Blue</name>
            </script>
          </material>
        </visual>
      </link>
      <link name="linkvert_4">
        <pose>-0.15 0.25 0.45500000000000007  0 0 0 </pose>
        <inertial>
          <mass>0.010602875205865553</mass>
          <inertia>
            <ixx>2.275200304591984e-06</ixx>
            <iyy>2.275200304591984e-06</iyy>
            <izz>1.3253594007331942e-07</izz>
            <ixy>0.0</ixy>
            <ixz>0.0</ixz>
            <iyz>0.0</iyz>
          </inertia>
        </inertial>
        <collision name="collision">
          <geometry>
            <cylinder>
              <radius>0.005</radius>
              <length>0.05</length>
            </cylinder>
          </geometry>
          <surface>
            <contact>
              <ode>
                <min_depth>0.001</min_depth>
                <max_vel>0.1</max_vel>
                <kp>1e8</kp>
                <kd>1</kd>
              </ode>
            </contact>
          </surface>
        </collision>
        <visual name="visual">
          <geometry>
            <cylinder>
              <radius>0.005</radius>
              <length>0.05</length>
            </cylinder>
          </geometry>
          <material>
            <script>
              <uri>file://media/materials/scripts/gazebo.material</uri>
              <name>Gazebo/Yellow</name>
            </script>
          </material>
        </visual>
      </link>

        <joint name="vertChild_4" type="ball">
          <pose>-0.15 0.25 0.43000000000000005 0 0 0</pose>
          <parent>linkvert_4</parent>
          <child>link_4</child>
          <thread_pitch>-0.1</thread_pitch>
          <axis>
            <xyz>0 0 1</xyz>
            <limit>
              <upper>1.7</upper>
              <lower>-1.7</lower>
              <stiffness>1e6</stiffness>
              <dissipation>1.0</dissipation>
            </limit>
            <dynamics>
              <damping>0.1</damping>
           </dynamics>
          </axis>
          <physics>
            <ode>
              <cfm_damping>1</cfm_damping>
            </ode>
          </physics>
        </joint>
        <joint name="vertParent_4" type="revolute">
          <pose>-0.15 0.25 0.48000000000000004 0 0 0 </pose>
          <parent>link_1</parent>
          <child>linkvert_4</child>
          <axis>
            <xyz>1 0 0</xyz>
            <limit>
              <upper>0</upper>
              <lower>0</lower>
            </limit>
          </axis>
        </joint>

      <link name="link_5">
        <pose>0.15 -0.25 0.43000000000000005 1.5707963267948966 0 0</pose>
        <inertial>
          <mass>0.03817035074111599</mass>
          <inertia>
            <ixx>0.00010329851169314512</ixx>
            <iyy>0.00010329851169314512</iyy>
            <izz>4.771293842639499e-07</izz>
            <ixy>0.0</ixy>
            <ixz>0.0</ixz>
            <iyz>0.0</iyz>
          </inertia>
        </inertial>
        <collision name="collision">
          <geometry>
            <cylinder>
              <radius>0.005</radius>
              <length>0.18</length>
            </cylinder>
          </geometry>
          <surface>
            <contact>
              <ode>
                <min_depth>0.001</min_depth>
                <max_vel>0.1</max_vel>
                <kp>1e8</kp>
                <kd>1</kd>
              </ode>
            </contact>
          </surface>
        </collision>
        <visual name="visual">
          <geometry>
            <cylinder>
              <radius>0.005</radius>
              <length>0.18</length>
            </cylinder>
          </geometry>
          <material>
            <script>
              <uri>file://media/materials/scripts/gazebo.material</uri>
              <name>Gazebo/Blue</name>
            </script>
          </material>
        </visual>
      </link>
      <link name="linkvert_5">
        <pose>0.15 -0.25 0.45500000000000007  0 0 0 </pose>
        <inertial>
          <mass>0.010602875205865553</mass>
          <inertia>
            <ixx>2.275200304591984e-06</ixx>
            <iyy>2.275200304591984e-06</iyy>
            <izz>1.3253594007331942e-07</izz>
            <ixy>0.0</ixy>
            <ixz>0.0</ixz>
            <iyz>0.0</iyz>
          </inertia>
        </inertial>
        <collision name="collision">
          <geometry>
            <cylinder>
              <radius>0.005</radius>
              <length>0.05</length>
            </cylinder>
          </geometry>
          <surface>
            <contact>
              <ode>
                <min_depth>0.001</min_depth>
                <max_vel>0.1</max_vel>
                <kp>1e8</kp>
                <kd>1</kd>
              </ode>
            </contact>
          </surface>
        </collision>
        <visual name="visual">
          <geometry>
            <cylinder>
              <radius>0.005</radius>
              <length>0.05</length>
            </cylinder>
          </geometry>
          <material>
            <script>
              <uri>file://media/materials/scripts/gazebo.material</uri>
              <name>Gazebo/Yellow</name>
            </script>
          </material>
        </visual>
      </link>

        <joint name="vertChild_5" type="ball">
          <pose>0.15 -0.25 0.43000000000000005 0 0 0</pose>
          <parent>linkvert_5</parent>
          <child>link_5</child>
          <thread_pitch>-0.1</thread_pitch>
          <axis>
            <xyz>0 0 1</xyz>
            <limit>
              <upper>1.7</upper>
              <lower>-1.7</lower>
              <stiffness>1e6</stiffness>
              <dissipation>1.0</dissipation>
            </limit>
            <dynamics>
              <damping>0.1</damping>
           </dynamics>
          </axis>
          <physics>
            <ode>
              <cfm_damping>1</cfm_damping>
            </ode>
          </physics>
        </joint>
        <joint name="vertParent_5" type="revolute">
          <pose>0.15 -0.25 0.48000000000000004 0 0 0 </pose>
          <parent>link_2</parent>
          <child>linkvert_5</child>
          <axis>
            <xyz>1 0 0</xyz>
            <limit>
              <upper>0</upper>
              <lower>0</lower>
            </limit>
          </axis>
        </joint>

      <link name="link_6">
        <pose>-0.15 -0.25 0.43000000000000005 1.5707963267948966 0 0</pose>
        <inertial>
          <mass>0.03817035074111599</mass>
          <inertia>
            <ixx>0.00010329851169314512</ixx>
            <iyy>0.00010329851169314512</iyy>
            <izz>4.771293842639499e-07</izz>
            <ixy>0.0</ixy>
            <ixz>0.0</ixz>
            <iyz>0.0</iyz>
          </inertia>
        </inertial>
        <collision name="collision">
          <geometry>
            <cylinder>
              <radius>0.005</radius>
              <length>0.18</length>
            </cylinder>
          </geometry>
          <surface>
            <contact>
              <ode>
                <min_depth>0.001</min_depth>
                <max_vel>0.1</max_vel>
                <kp>1e8</kp>
                <kd>1</kd>
              </ode>
            </contact>
          </surface>
        </collision>
        <visual name="visual">
          <geometry>
            <cylinder>
              <radius>0.005</radius>
              <length>0.18</length>
            </cylinder>
          </geometry>
          <material>
            <script>
              <uri>file://media/materials/scripts/gazebo.material</uri>
              <name>Gazebo/Blue</name>
            </script>
          </material>
        </visual>
      </link>
      <link name="linkvert_6">
        <pose>-0.15 -0.25 0.45500000000000007  0 0 0 </pose>
        <inertial>
          <mass>0.010602875205865553</mass>
          <inertia>
            <ixx>2.275200304591984e-06</ixx>
            <iyy>2.275200304591984e-06</iyy>
            <izz>1.3253594007331942e-07</izz>
            <ixy>0.0</ixy>
            <ixz>0.0</ixz>
            <iyz>0.0</iyz>
          </inertia>
        </inertial>
        <collision name="collision">
          <geometry>
            <cylinder>
              <radius>0.005</radius>
              <length>0.05</length>
            </cylinder>
          </geometry>
          <surface>
            <contact>
              <ode>
                <min_depth>0.001</min_depth>
                <max_vel>0.1</max_vel>
                <kp>1e8</kp>
                <kd>1</kd>
              </ode>
            </contact>
          </surface>
        </collision>
        <visual name="visual">
          <geometry>
            <cylinder>
              <radius>0.005</radius>
              <length>0.05</length>
            </cylinder>
          </geometry>
          <material>
            <script>
              <uri>file://media/materials/scripts/gazebo.material</uri>
              <name>Gazebo/Yellow</name>
            </script>
          </material>
        </visual>
      </link>

        <joint name="vertChild_6" type="ball">
          <pose>-0.15 -0.25 0.43000000000000005 0 0 0</pose>
          <parent>linkvert_6</parent>
          <child>link_6</child>
          <thread_pitch>-0.1</thread_pitch>
          <axis>
            <xyz>0 0 1</xyz>
            <limit>
              <upper>1.7</upper>
              <lower>-1.7</lower>
              <stiffness>1e6</stiffness>
              <dissipation>1.0</dissipation>
            </limit>
            <dynamics>
              <damping>0.1</damping>
           </dynamics>
          </axis>
          <physics>
            <ode>
              <cfm_damping>1</cfm_damping>
            </ode>
          </physics>
        </joint>
        <joint name="vertParent_6" type="revolute">
          <pose>-0.15 -0.25 0.48000000000000004 0 0 0 </pose>
          <parent>link_2</parent>
          <child>linkvert_6</child>
          <axis>
            <xyz>1 0 0</xyz>
            <limit>
              <upper>0</upper>
              <lower>0</lower>
            </limit>
          </axis>
        </joint>

    </model>

  </world>
</sdf>
