<?xml version="1.0" ?>
<%
  # Pendulum axes test
  # Pendulums with different link frame orientations
  require "matrix"

  # Inertial parameters
  # Aluminum 2700 kg/m^3
  density = 2700.0

  # Largest pendulum box dimension
  dd = 0.1

  # Initial angle of revolute joints
  theta = 0.1* Math::PI

  pendula = {
    "x_axis" => {:pos => [0, 0, -dd/2], :rpy => [theta, 0, 0], :size => [dd/10, dd/10, dd], :axis => [1, 0, 0]},
    "y_axis" => {:pos => [0, 0, -dd/2], :rpy => [0, theta, 0], :size => [dd/10, dd/10, dd], :axis => [0, 1, 0]},
  }

  revolute_friction = [0.0, 0.1, 1.0, 10.0]
%>
<sdf version="1.5">
  <world name="default">
    <include>
      <uri>model://sun</uri>
    </include>
    <%  # Revolute joints
        i = 0
        pendula.keys.each do |p|
          i = i + 1
          name = 'pendulum_' + p
          size = Vector.elements(pendula[p][:size])
          dx = size[0]
          dy = size[1]
          dz = size[2]
          mass = density * dx * dy * dz 
          ixx = 1.0 / 12 * mass * (dy*dy + dz*dz)
          iyy = 1.0 / 12 * mass * (dz*dz + dx*dx)
          izz = 1.0 / 12 * mass * (dx*dx + dy*dy)
          pos = Vector.elements(pendula[p][:pos])
          rpy = Vector.elements(pendula[p][:rpy])
          axis = Vector.elements(pendula[p][:axis])
    %>
    <%= "<model name='#{name}'>" %>
      <pose><%= dd*2.1*i %> 0 <%= dd*1.8 %>  <%= rpy.to_a.join(" ") %></pose>
      <link name="link">
        <pose><%= pos.to_a.join(" ") %>  0 0 0</pose>
        <inertial>
          <mass><%= mass %></mass>
          <inertia>
            <ixx><%= ixx %></ixx>
            <iyy><%= iyy %></iyy>
            <izz><%= izz %></izz>
            <ixy>0.0</ixy>
            <ixz>0.0</ixz>
            <iyz>0.0</iyz>
          </inertia>
        </inertial>
        <collision name="collision">
          <geometry>
            <box>
              <size><%= size.to_a.join(" ") %></size>
            </box>
          </geometry>
        </collision>
        <visual name="visual">
          <geometry>
            <box>
              <size><%= dx %> <%= dy %> <%= dz %></size>
            </box>
          </geometry>
        </visual>
      </link>
      <joint name="joint" type="revolute">
        <pose><%= (-1 * pos).to_a.join(" ") %>  0 0 0</pose>
        <parent>world</parent>
        <child>link</child>
        <axis>
          <xyz><%= axis.to_a.join(" ") %></xyz>
        </axis>
      </joint>
    </model>
    <% end %>
  </world>
</sdf>
