<?xml version="1.0" ?>
<sdf version="1.5">
  <world name="default">
    <!-- A global light source -->
    <include>
      <uri>model://sun</uri>
    </include>
    <!-- A ground plane -->
    <include>
      <uri>model://ground_plane</uri>
    </include>

    <physics type='ode'>
      <gravity> 0 0 0 </gravity>
    </physics>

    <model name='Simple_Quadruped'>
      <pose>0 0 1 0 0 0</pose>
      <link name='Body'>
        <pose>0.177336 0 0.303594 0 -0 0</pose>
        <inertial>
          <mass>0.789429</mass>
          <inertia>
            <ixx>0.125804</ixx>
            <ixy>0</ixy>
            <ixz>0</ixz>
            <iyy>0.501238</iyy>
            <iyz>0</iyz>
            <izz>0.621249</izz>
          </inertia>
        </inertial>
        <visual name='visual'>
          <geometry>
            <box>
              <size>2.75231 1.36686 0.209842</size>
            </box>
          </geometry>
          <material>
            <script>
              <uri>file://media/materials/scripts/gazebo.material</uri>
              <name>Gazebo/Grey</name>
            </script>
          </material>
        </visual>
        <collision name='collision'>
          <geometry>
            <box>
              <size>2.75231 1.36686 0.209842</size>
            </box>
          </geometry>
        </collision>
      </link>
      <link name='BackRightLeg'>
        <pose>-0.822065 -0.717181 -0.075896 0 0.582844 0</pose>
        <inertial>
          <mass>0.0164264</mass>
          <inertia>
            <ixx>0.00137511</ixx>
            <ixy>0</ixy>
            <ixz>0</ixz>
            <iyy>0.00144991</iyy>
            <iyz>0</iyz>
            <izz>8.72781e-05</izz>
          </inertia>
        </inertial>
        <visual name='visual'>
          <geometry>
            <box>
              <size>0.243314 0.067511 1</size>
            </box>
          </geometry>
          <material>
            <script>
              <uri>file://media/materials/scripts/gazebo.material</uri>
              <name>Gazebo/Grey</name>
            </script>
          </material>
        </visual>
        <collision name='collision'>
          <geometry>
            <box>
              <size>0.243314 0.067511 1</size>
            </box>
          </geometry>
        </collision>
      </link>
      <link name='FrontRightLeg'>
        <pose>0.733397 -0.717182 -0.075896 0 0.582844 0</pose>
        <inertial>
          <mass>0.0164264</mass>
          <inertia>
            <ixx>0.00137511</ixx>
            <ixy>0</ixy>
            <ixz>0</ixz>
            <iyy>0.00144991</iyy>
            <iyz>0</iyz>
            <izz>8.72781e-05</izz>
          </inertia>
          <pose>0 0 0 0 -0 0</pose>
        </inertial>
        <visual name='ModelPreview_1::FrontRightLeg::visual'>
          <pose>0 0 0 0 -0 0</pose>
          <geometry>
            <box>
              <size>0.243314 0.067511 1</size>
            </box>
          </geometry>
          <material>
            <script>
              <uri>file://media/materials/scripts/gazebo.material</uri>
              <name>Gazebo/Grey</name>
            </script>
          </material>
        </visual>
        <collision name='collision'>
          <geometry>
            <box>
              <size>0.243314 0.067511 1</size>
            </box>
          </geometry>
        </collision>
      </link>
      <link name='BackLeftLeg'>
        <pose>-0.822065 0.71718 -0.075896 0 0.582844 0</pose>
        <inertial>
          <mass>0.0164264</mass>
          <inertia>
            <ixx>0.00137511</ixx>
            <ixy>0</ixy>
            <ixz>0</ixz>
            <iyy>0.00144991</iyy>
            <iyz>0</iyz>
            <izz>8.72781e-05</izz>
          </inertia>
        </inertial>
        <visual name='ModelPreview_1::BackLeftLeg::visual'>
          <pose>0 0 0 0 -0 0</pose>
          <geometry>
            <box>
              <size>0.243314 0.067511 1</size>
            </box>
          </geometry>
          <material>
            <script>
              <uri>file://media/materials/scripts/gazebo.material</uri>
              <name>Gazebo/Grey</name>
            </script>
          </material>
        </visual>
        <collision name='collision'>
          <geometry>
            <box>
              <size>0.243314 0.067511 1</size>
            </box>
          </geometry>
        </collision>
      </link>
      <link name='FrontLeftLeg'>
        <pose>0.733396 0.717181 -0.075896 0 0.582844 0</pose>
        <inertial>
          <mass>0.0164264</mass>
          <inertia>
            <ixx>0.00137511</ixx>
            <ixy>0</ixy>
            <ixz>0</ixz>
            <iyy>0.00144991</iyy>
            <iyz>0</iyz>
            <izz>8.72781e-05</izz>
          </inertia>
          <pose>0 0 0 0 -0 0</pose>
        </inertial>
        <visual name='ModelPreview_1::FrontLeftLeg::visual'>
          <pose>0 0 0 0 -0 0</pose>
          <geometry>
            <box>
              <size>0.243314 0.067511 1</size>
            </box>
          </geometry>
          <material>
            <script>
              <uri>file://media/materials/scripts/gazebo.material</uri>
              <name>Gazebo/Grey</name>
            </script>
          </material>
        </visual>
        <collision name='collision'>
          <laser_retro>0</laser_retro>
          <max_contacts>10</max_contacts>
          <pose>0 0 0 0 -0 0</pose>
          <geometry>
            <box>
              <size>0.243314 0.067511 1</size>
            </box>
          </geometry>
        </collision>
      </link>
      <joint name='BackLeftJoint' type='revolute'>
        <parent>Body</parent>
        <child>BackLeftLeg</child>
        <pose>0 0 0.5 0 -0 0</pose>
        <axis>
          <xyz>0 1 0</xyz>
        </axis>
      </joint>
      <joint name='FrontRightJoint' type='revolute'>
        <parent>Body</parent>
        <child>FrontRightLeg</child>
        <pose>0 0 0.5 0 -0 0</pose>
        <axis>
          <xyz>0 1 0</xyz>
        </axis>
      </joint>
      <joint name='FrontLeftJoint' type='revolute'>
        <parent>Body</parent>
        <child>FrontLeftLeg</child>
        <pose>0 0 0.5 0 -0 0</pose>
        <axis>
          <xyz>0 1 0</xyz>
        </axis>
      </joint>
      <joint name='BackRightJoint' type='revolute'>
        <parent>Body</parent>
        <child>BackRightLeg</child>
        <pose>0 0 0.5 0 -0 0</pose>
        <axis>
          <xyz>0 1 0</xyz>
        </axis>
      </joint>

      <plugin name="SinusoidalForce" filename="libSinusoidalForcePlugin.so">
        <joint name="FrontLeftJoint">
          <min>-0.5</min>
          <max>0.5</max>
          <period>1</period>
        </joint>
        <joint name="FrontRightJoint">
          <min>-1</min>
          <max>1</max>
          <period>2</period>
        </joint>
        <joint name="BackLeftJoint">
          <min>-3</min>
          <max>3</max>
          <period>0.5</period>
        </joint>
        <joint name="BackRightJoint">
          <min>-2</min>
          <max>0</max>
          <period>0.1</period>
        </joint>
      </plugin>
    </model>


  </world>
</sdf>
