<?xml version="1.0"?> 
<gazebo version="1.2">
  <world name="default">

    <include filename="ground_plane.model"/>
    <include filename="sun.light"/>
    
    <model name="revolute_model">
      <origin pose="0 0 0.5 0 0 0"/>
      <link name="body1">
        <inertial mass="1.0">
          <inertia ixx="1" ixy="0" ixz="0" iyy="1" iyz="0" izz="1"/>
        </inertial>

        <collision name="geom">
          <geometry>
            <box size="1 1 1"/>
          </geometry>
        </collision>

        <visual name="visual">
          <geometry>
            <box size="1 1 1"/>
          </geometry>
          <material script="Gazebo/WoodPallet"/>
        </visual>
      </link>

      <link name="body2">
        <origin pose="0 0.5 2.0 0 0 0"/>
        <inertial mass="1.0">
          <inertia ixx="1" ixy="0" ixz="0" iyy="1" iyz="0" izz="1"/>
        </inertial>

        <collision name="geom">
          <geometry>
            <box size="1 1 1"/>
          </geometry>
        </collision>

        <visual name="visual">
          <geometry>
            <box size="1 1 1"/>
          </geometry>
          <material script="Gazebo/WoodPallet"/>
        </visual>
      </link>

      <joint type="revolute" name="revolute_joint">
        <origin pose="0 0 1 0 0 0"/>
        <parent link="body2"/>
        <child link="body1"/>
        <axis xyz="0 0 1"/>
      </joint>
    </model>

  </world>
</gazebo>
