<gazebo version="1.2">
  <world name="default">

    <scene>
      <ambient>0.5 0.5 0.5 1</ambient>
      <background>0.5 0.5 0.5 1</background>
      <shadows>false</shadows>
    </scene>

    <include filename="sun.light"/>

    <physics type="ode">
      <gravity xyz="0.0 0.0 -9.81"/>
      <ode>
        <solver type="quick" dt="0.001" iters="1000" sor="1.0"/>
        <constraints cfm="0" erp="1.0" contact_max_correcting_vel="0.0" contact_surface_layer="0.0"/>
      </ode>
    </physics>

    <model name="model_1" static="false">

      <origin>0.0 0.0 10.1 1.57079633 0.0 0.0</origin>

      <link name="link_1" self_collide="true" gravity="true" kinematic="false">

        <origin>0.0 0.0 0.0 0.0 0.0 0.0</origin>

        <inertial mass="5.0">
          <origin>0.0 0.0 -10.0 0.0 0.0 0.0</origin>
          <inertia ixx="0.0" ixy="0.0" ixz="0.0"
                   iyy="0.0" iyz="0.0"
                   izz="0.0"/>
        </inertial>

        <damping>
          <linear>0.0</linear>
          <angular>0.0</angular>
        </damping>

        <visual name="visual_cylinder">
          <origin>0.0 0.0 -5.0 0.0 0.0 0.0</origin>
          <geometry>
            <cylinder radius="0.05" length="10.0"/>
          </geometry>
          <material script="Gazebo/Green"/>
        </visual>

        <collision name="collision_cylinder">
          <origin>0.0 0.0 -5.0 0.0 0.0 0.0</origin>
          <max_contacts>250</max_contacts>
          <geometry>
            <cylinder radius="0.05" length="10.0"/>
          </geometry>
        </collision>

      </link>

      <joint name="joint_0" type="revolute">
        <parent link="world"/>
        <child link="link_1"/>
        <origin>0.0 0.0 0.0 0.0 0.0 0.0</origin>
        <axis xyz="1.0 0.0 0.0"/>
      </joint>

      <link name="link_2" self_collide="true" gravity="true" kinematic="false">

        <origin>0.0 0.0 -10.0 0.0 0.0 0.0</origin>

        <inertial mass="5.0">
          <origin>0.0 0.0 0.0 0.0 0.0 0.0</origin>
          <inertia ixx="0.0" ixy="0.0" ixz="0.0"
                   iyy="0.0" iyz="0.0"
                   izz="0.0"/>
        </inertial>

        <damping>
          <linear>0.0</linear>
          <angular>0.0</angular>
        </damping>

        <visual name="visual_sphere">
          <origin>0.0 0.0 0.0 0.0 0.0 0.0</origin>
          <geometry>
            <sphere radius="0.1"/>
          </geometry>
          <material script="Gazebo/Red"/>
        </visual>

        <collision name="collision_sphere">
          <origin>0.0 0.0 0.0 0.0 0.0 0.0</origin>
          <max_contacts>250</max_contacts>
          <geometry>
            <sphere radius="0.1"/>
          </geometry>
        </collision>

      </link>
      <joint name="joint_1" type="revolute">
        <parent link="link_1"/>
        <child link="link_2"/>
        <origin>0.0 0.0 0.0 0.0 0.0 0.0</origin>
        <axis xyz="0 0 1">
          <limit lower='0' upper='0' effort='0' velocity='0'/>
        </axis>
      </joint>

    </model>



    <model name="model_2" static="false">

      <origin>1.0 0.0 10.1 1.57079633 0.0 0.0</origin>

      <link name="link_1" self_collide="true" gravity="true" kinematic="false">

        <origin>0.0 0.0 0.0 0.0 0.0 0.0</origin>

        <inertial mass="10.0">
          <origin>0.0 0.0 -10.0 0.0 0.0 0.0</origin>
          <inertia ixx="0.0" ixy="0.0" ixz="0.0"
                   iyy="0.0" iyz="0.0"
                   izz="0.0"/>
        </inertial>

        <damping>
          <linear>0.0</linear>
          <angular>0.0</angular>
        </damping>

        <visual name="visual_cylinder">
          <origin>0.0 0.0 -5.0 0.0 0.0 0.0</origin>
          <geometry>
            <cylinder radius="0.1" length="10.0"/>
          </geometry>
          <material script="Gazebo/Green"/>
        </visual>

        <collision name="collision_cylinder">
          <origin>0.0 0.0 -5.0 0.0 0.0 0.0</origin>
          <max_contacts>250</max_contacts>
          <geometry>
            <cylinder radius="0.1" length="10.0"/>
          </geometry>
        </collision>

      </link>

      <joint name="joint_0" type="revolute">
        <parent link="world"/>
        <child link="link_1"/>
        <origin>0.0 0.0 0.0 0.0 0.0 0.0</origin>
        <axis xyz="1.0 0.0 0.0"/>
      </joint>

    </model>

    <model name="model_3" static="false">

      <origin>0.0 -10.5 10.1 0.0 1.57079633 0.0</origin>

      <link name="link_1" self_collide="true" gravity="true" kinematic="false">

        <origin>0.0 0.0 0.0 0.0 0.0 0.0</origin>

        <inertial mass="10.0">
          <origin>0.0 0.0 -10.0 0.0 0.0 0.0</origin>
          <inertia ixx="0.0" ixy="0.0" ixz="0.0"
                   iyy="0.0" iyz="0.0"
                   izz="0.0"/>
        </inertial>

        <damping>
          <linear>0.0</linear>
          <angular>0.0</angular>
        </damping>

        <visual name="visual_cylinder">
          <origin>0.0 0.0 -5.0 0.0 0.0 0.0</origin>
          <geometry>
            <cylinder radius="0.1" length="10.0"/>
          </geometry>
          <material script="Gazebo/Green"/>
        </visual>

        <collision name="collision_cylinder">
          <origin>0.0 0.0 -5.0 0.0 0.0 0.0</origin>
          <max_contacts>250</max_contacts>
          <geometry>
            <cylinder radius="0.1" length="10.0"/>
          </geometry>
        </collision>

      </link>

      <joint name="joint_0" type="revolute">
        <parent link="world"/>
        <child link="link_1"/>
        <origin>0.0 0.0 0.0 0.0 0.0 0.0</origin>
        <axis xyz="0.0 1.0 0.0"/>
      </joint>

    </model>
  </world>
</gazebo>
